Workbook

Sheet Lote 1
A2: Muestra | B2: Tiempo [min] | C2: Pellets/g | H2: m | I2: s | J2: Diametro [mm] Microscopio | M2: m | N2: s | O2: Espesor [mm] Microscopio | R2: m | S2: s | T2: Densidad 00 [g/ml] | W2: Densidad 0 [g/ml] | Z2: m | AA2: s
C3: 1 | D3: 2 | E3: 3 | F3: 4 | G3: 5 | J3: 1 | K3: 2 | L3: 3 | O3: 1 | P3: 2 | Q3: 3 | T3: 1 | U3: 2 | V3: 3 | W3: 1 | X3: 2 | Y3: 3
A4: 0 | B4: 0 | C4: 1594 | D4: 1615 | E4: 1610 | F4: 1585 | G4: 1601 | H4: =ROUNDDOWN(AVERAGE(C4:G4),0) -> 1601 | I4: =_xlfn.STDEV.S(C4:G4) -> 12.062338 | K4: 0.9845 | M4: =AVERAGE(J4:L4) -> 0.9845 | N4: =_xlfn.STDEV.S(J4:L4) -> #DIV/0! | O4: 0 | P4: 0 | Q4: 0 | R4: =AVERAGE(O4:Q4) -> 0 | S4: =_xlfn.STDEV.S(O4:Q4) -> 0 | T4: 0.90769231 | U4: 0.91626374 | V4: 0.9121978 | W4: 0.86823529 | X4: 0.88 | Y4: 0.88279412 | Z4: =AVERAGE(T4:Y4) -> 0.89453054 | AA4: =_xlfn.STDEV.S(T4:Y4) -> 0.019990079
A5: 1 | B5: 20 | H5: =ROUNDDOWN(AVERAGE(C5:G5),0) -> #DIV/0! | I5: =_xlfn.STDEV.S(C5:G5) -> #DIV/0! | M5: =AVERAGE(J5:L5) -> #DIV/0! | N5: =_xlfn.STDEV.S(J5:L5) -> #DIV/0! | R5: =AVERAGE(O5:Q5) -> #DIV/0! | S5: =_xlfn.STDEV.S(O5:Q5) -> #DIV/0! | Z5: =AVERAGE(T5:Y5) -> #DIV/0! | AA5: =_xlfn.STDEV.S(T5:Y5) -> #DIV/0!
A6: 2 | B6: 40 | H6: =ROUNDDOWN(AVERAGE(C6:G6),0) -> #DIV/0! | I6: =_xlfn.STDEV.S(C6:G6) -> #DIV/0! | M6: =AVERAGE(J6:L6) -> #DIV/0! | N6: =_xlfn.STDEV.S(J6:L6) -> #DIV/0! | R6: =AVERAGE(O6:Q6) -> #DIV/0! | S6: =_xlfn.STDEV.S(O6:Q6) -> #DIV/0! | Z6: =AVERAGE(T6:Y6) -> #DIV/0! | AA6: =_xlfn.STDEV.S(T6:Y6) -> #DIV/0!
A7: 3 | B7: 60 | H7: =ROUNDDOWN(AVERAGE(C7:G7),0) -> #DIV/0! | I7: =_xlfn.STDEV.S(C7:G7) -> #DIV/0! | M7: =AVERAGE(J7:L7) -> #DIV/0! | N7: =_xlfn.STDEV.S(J7:L7) -> #DIV/0! | R7: =AVERAGE(O7:Q7) -> #DIV/0! | S7: =_xlfn.STDEV.S(O7:Q7) -> #DIV/0! | Z7: =AVERAGE(T7:Y7) -> #DIV/0! | AA7: =_xlfn.STDEV.S(T7:Y7) -> #DIV/0!
A8: 4 | B8: 80 | H8: =ROUNDDOWN(AVERAGE(C8:G8),0) -> #DIV/0! | I8: =_xlfn.STDEV.S(C8:G8) -> #DIV/0! | M8: =AVERAGE(J8:L8) -> #DIV/0! | N8: =_xlfn.STDEV.S(J8:L8) -> #DIV/0! | R8: =AVERAGE(O8:Q8) -> #DIV/0! | S8: =_xlfn.STDEV.S(O8:Q8) -> #DIV/0! | Z8: =AVERAGE(T8:Y8) -> #DIV/0! | AA8: =_xlfn.STDEV.S(T8:Y8) -> #DIV/0!
A9: 5 | B9: 100 | H9: =ROUNDDOWN(AVERAGE(C9:G9),0) -> #DIV/0! | I9: =_xlfn.STDEV.S(C9:G9) -> #DIV/0! | M9: =AVERAGE(J9:L9) -> #DIV/0! | N9: =_xlfn.STDEV.S(J9:L9) -> #DIV/0! | R9: =AVERAGE(O9:Q9) -> #DIV/0! | S9: =_xlfn.STDEV.S(O9:Q9) -> #DIV/0! | Z9: =AVERAGE(T9:Y9) -> #DIV/0! | AA9: =_xlfn.STDEV.S(T9:Y9) -> #DIV/0!
A10: 6 | B10: 120 | H10: =ROUNDDOWN(AVERAGE(C10:G10),0) -> #DIV/0! | I10: =_xlfn.STDEV.S(C10:G10) -> #DIV/0! | M10: =AVERAGE(J10:L10) -> #DIV/0! | N10: =_xlfn.STDEV.S(J10:L10) -> #DIV/0! | R10: =AVERAGE(O10:Q10) -> #DIV/0! | S10: =_xlfn.STDEV.S(O10:Q10) -> #DIV/0! | Z10: =AVERAGE(T10:Y10) -> #DIV/0! | AA10: =_xlfn.STDEV.S(T10:Y10) -> #DIV/0!
A11: 7 | B11: 140 | H11: =ROUNDDOWN(AVERAGE(C11:G11),0) -> #DIV/0! | I11: =_xlfn.STDEV.S(C11:G11) -> #DIV/0! | M11: =AVERAGE(J11:L11) -> #DIV/0! | N11: =_xlfn.STDEV.S(J11:L11) -> #DIV/0! | R11: =AVERAGE(O11:Q11) -> #DIV/0! | S11: =_xlfn.STDEV.S(O11:Q11) -> #DIV/0! | Z11: =AVERAGE(T11:Y11) -> #DIV/0! | AA11: =_xlfn.STDEV.S(T11:Y11) -> #DIV/0!
A12: 8 | B12: 160 | H12: =ROUNDDOWN(AVERAGE(C12:G12),0) -> #DIV/0! | I12: =_xlfn.STDEV.S(C12:G12) -> #DIV/0! | M12: =AVERAGE(J12:L12) -> #DIV/0! | N12: =_xlfn.STDEV.S(J12:L12) -> #DIV/0! | R12: =AVERAGE(O12:Q12) -> #DIV/0! | S12: =_xlfn.STDEV.S(O12:Q12) -> #DIV/0! | Z12: =AVERAGE(T12:Y12) -> #DIV/0! | AA12: =_xlfn.STDEV.S(T12:Y12) -> #DIV/0!
A13: 9 | B13: 180 | H13: =ROUNDDOWN(AVERAGE(C13:G13),0) -> #DIV/0! | I13: =_xlfn.STDEV.S(C13:G13) -> #DIV/0! | M13: =AVERAGE(J13:L13) -> #DIV/0! | N13: =_xlfn.STDEV.S(J13:L13) -> #DIV/0! | R13: =AVERAGE(O13:Q13) -> #DIV/0! | S13: =_xlfn.STDEV.S(O13:Q13) -> #DIV/0! | Z13: =AVERAGE(T13:Y13) -> #DIV/0! | AA13: =_xlfn.STDEV.S(T13:Y13) -> #DIV/0!
A14: Final | B14: 200 | C14: 1308 | D14: 1312 | E14: 1303 | F14: 1296 | G14: 1297 | H14: =ROUNDDOWN(AVERAGE(C14:G14),0) -> 1303 | I14: =_xlfn.STDEV.S(C14:G14) -> 6.9065187 | K14: 0.9361 | M14: =AVERAGE(J14:L14) -> 0.9361 | N14: =_xlfn.STDEV.S(J14:L14) -> #DIV/0! | P14: 0.0501 | R14: =AVERAGE(O14:Q14) -> 0.0501 | S14: =_xlfn.STDEV.S(O14:Q14) -> #DIV/0! | T14: 0.99956044 | U14: 0.98054945 | V14: 0.98296703 | W14: 0.97897059 | X14: 0.96132353 | Y14: 0.96588235 | Z14: =AVERAGE(T14:Y14) -> 0.9782089 | AA14: =_xlfn.STDEV.S(T14:Y14) -> 0.013576788

Sheet Lote 2
A2: Muestra | B2: Tiempo [min] | C2: Pellets/g | H2: m | I2: s | J2: Diametro [mm] Microscopio | M2: m | N2: s | O2: Espesor [mm] Microscopio | R2: m | S2: s | T2: Densidad 00 [g/ml] | W2: Densidad 0 [g/ml] | Z2: m | AA2: s
C3: 1 | D3: 2 | E3: 3 | F3: 4 | G3: 5 | J3: 1 | K3: 2 | L3: 3 | O3: 1 | P3: 2 | Q3: 3 | T3: 1 | U3: 2 | V3: 3 | W3: 1 | X3: 2 | Y3: 3
A4: 0 | B4: 0 | C4: 1536 | D4: 1581 | E4: 1556 | F4: 1557 | G4: 1560 | H4: =ROUNDDOWN(AVERAGE(C4:G4),0) -> 1558 | I4: =_xlfn.STDEV.S(C4:G4) -> 15.984367 | K4: 0.9521 | M4: =AVERAGE(J4:L4) -> 0.9521 | N4: =_xlfn.STDEV.S(J4:L4) -> #DIV/0! | O4: 0 | P4: 0 | Q4: 0 | R4: =AVERAGE(O4:Q4) -> 0 | S4: =_xlfn.STDEV.S(O4:Q4) -> 0 | T4: 0.91835165 | U4: 0.91406593 | V4: 0.91373626 | W4: 0.87867647 | X4: 0.88205882 | Y4: 0.89397059 | Z4: =AVERAGE(T4:Y4) -> 0.90014329 | AA4: =_xlfn.STDEV.S(T4:Y4) -> 0.017527851
A5: 1 | B5: 20 | H5: =ROUNDDOWN(AVERAGE(C5:G5),0) -> #DIV/0! | I5: =_xlfn.STDEV.S(C5:G5) -> #DIV/0! | M5: =AVERAGE(J5:L5) -> #DIV/0! | N5: =_xlfn.STDEV.S(J5:L5) -> #DIV/0! | R5: =AVERAGE(O5:Q5) -> #DIV/0! | S5: =_xlfn.STDEV.S(O5:Q5) -> #DIV/0! | Z5: =AVERAGE(T5:Y5) -> #DIV/0! | AA5: =_xlfn.STDEV.S(T5:Y5) -> #DIV/0!
A6: 2 | B6: 40 | H6: =ROUNDDOWN(AVERAGE(C6:G6),0) -> #DIV/0! | I6: =_xlfn.STDEV.S(C6:G6) -> #DIV/0! | M6: =AVERAGE(J6:L6) -> #DIV/0! | N6: =_xlfn.STDEV.S(J6:L6) -> #DIV/0! | R6: =AVERAGE(O6:Q6) -> #DIV/0! | S6: =_xlfn.STDEV.S(O6:Q6) -> #DIV/0! | Z6: =AVERAGE(T6:Y6) -> #DIV/0! | AA6: =_xlfn.STDEV.S(T6:Y6) -> #DIV/0!
A7: 3 | B7: 60 | H7: =ROUNDDOWN(AVERAGE(C7:G7),0) -> #DIV/0! | I7: =_xlfn.STDEV.S(C7:G7) -> #DIV/0! | M7: =AVERAGE(J7:L7) -> #DIV/0! | N7: =_xlfn.STDEV.S(J7:L7) -> #DIV/0! | R7: =AVERAGE(O7:Q7) -> #DIV/0! | S7: =_xlfn.STDEV.S(O7:Q7) -> #DIV/0! | Z7: =AVERAGE(T7:Y7) -> #DIV/0! | AA7: =_xlfn.STDEV.S(T7:Y7) -> #DIV/0!
A8: 4 | B8: 80 | H8: =ROUNDDOWN(AVERAGE(C8:G8),0) -> #DIV/0! | I8: =_xlfn.STDEV.S(C8:G8) -> #DIV/0! | M8: =AVERAGE(J8:L8) -> #DIV/0! | N8: =_xlfn.STDEV.S(J8:L8) -> #DIV/0! | R8: =AVERAGE(O8:Q8) -> #DIV/0! | S8: =_xlfn.STDEV.S(O8:Q8) -> #DIV/0! | Z8: =AVERAGE(T8:Y8) -> #DIV/0! | AA8: =_xlfn.STDEV.S(T8:Y8) -> #DIV/0!
A9: 5 | B9: 100 | H9: =ROUNDDOWN(AVERAGE(C9:G9),0) -> #DIV/0! | I9: =_xlfn.STDEV.S(C9:G9) -> #DIV/0! | M9: =AVERAGE(J9:L9) -> #DIV/0! | N9: =_xlfn.STDEV.S(J9:L9) -> #DIV/0! | R9: =AVERAGE(O9:Q9) -> #DIV/0! | S9: =_xlfn.STDEV.S(O9:Q9) -> #DIV/0! | Z9: =AVERAGE(T9:Y9) -> #DIV/0! | AA9: =_xlfn.STDEV.S(T9:Y9) -> #DIV/0!
A10: 6 | B10: 120 | H10: =ROUNDDOWN(AVERAGE(C10:G10),0) -> #DIV/0! | I10: =_xlfn.STDEV.S(C10:G10) -> #DIV/0! | M10: =AVERAGE(J10:L10) -> #DIV/0! | N10: =_xlfn.STDEV.S(J10:L10) -> #DIV/0! | R10: =AVERAGE(O10:Q10) -> #DIV/0! | S10: =_xlfn.STDEV.S(O10:Q10) -> #DIV/0! | Z10: =AVERAGE(T10:Y10) -> #DIV/0! | AA10: =_xlfn.STDEV.S(T10:Y10) -> #DIV/0!
A11: 7 | B11: 140 | H11: =ROUNDDOWN(AVERAGE(C11:G11),0) -> #DIV/0! | I11: =_xlfn.STDEV.S(C11:G11) -> #DIV/0! | M11: =AVERAGE(J11:L11) -> #DIV/0! | N11: =_xlfn.STDEV.S(J11:L11) -> #DIV/0! | R11: =AVERAGE(O11:Q11) -> #DIV/0! | S11: =_xlfn.STDEV.S(O11:Q11) -> #DIV/0! | Z11: =AVERAGE(T11:Y11) -> #DIV/0! | AA11: =_xlfn.STDEV.S(T11:Y11) -> #DIV/0!
A12: 8 | B12: 160 | H12: =ROUNDDOWN(AVERAGE(C12:G12),0) -> #DIV/0! | I12: =_xlfn.STDEV.S(C12:G12) -> #DIV/0! | M12: =AVERAGE(J12:L12) -> #DIV/0! | N12: =_xlfn.STDEV.S(J12:L12) -> #DIV/0! | R12: =AVERAGE(O12:Q12) -> #DIV/0! | S12: =_xlfn.STDEV.S(O12:Q12) -> #DIV/0! | Z12: =AVERAGE(T12:Y12) -> #DIV/0! | AA12: =_xlfn.STDEV.S(T12:Y12) -> #DIV/0!
A13: 9 | B13: 180 | H13: =ROUNDDOWN(AVERAGE(C13:G13),0) -> #DIV/0! | I13: =_xlfn.STDEV.S(C13:G13) -> #DIV/0! | M13: =AVERAGE(J13:L13) -> #DIV/0! | N13: =_xlfn.STDEV.S(J13:L13) -> #DIV/0! | R13: =AVERAGE(O13:Q13) -> #DIV/0! | S13: =_xlfn.STDEV.S(O13:Q13) -> #DIV/0! | Z13: =AVERAGE(T13:Y13) -> #DIV/0! | AA13: =_xlfn.STDEV.S(T13:Y13) -> #DIV/0!
A14: Final | B14: 200 | C14: 1306 | D14: 1301 | E14: 1306 | F14: 1293 | G14: 1318 | H14: =ROUNDDOWN(AVERAGE(C14:G14),0) -> 1304 | I14: =_xlfn.STDEV.S(C14:G14) -> 9.093954 | K14: 0.9892 | M14: =AVERAGE(J14:L14) -> 0.9892 | N14: =_xlfn.STDEV.S(J14:L14) -> #DIV/0! | P14: 0.0508 | R14: =AVERAGE(O14:Q14) -> 0.0508 | S14: =_xlfn.STDEV.S(O14:Q14) -> #DIV/0! | T14: 1.0024176 | U14: 1.0012088 | V14: 0.99021978 | W14: 0.93794118 | X14: 0.93529412 | Y14: 0.93485294 | Z14: =AVERAGE(T14:Y14) -> 0.96698906 | AA14: =_xlfn.STDEV.S(T14:Y14) -> 0.034196244

Sheet Lote 3
A2: Muestra | B2: Tiempo [min] | C2: Pellets/g | H2: m | I2: s | J2: Diametro [mm] Microscopio | M2: m | N2: s | O2: Espesor [mm] Microscopio | R2: m | S2: s | T2: Densidad 00 [g/ml] | W2: Densidad 0 [g/ml] | Z2: m | AA2: s
C3: 1 | D3: 2 | E3: 3 | F3: 4 | G3: 5 | J3: 1 | K3: 2 | L3: 3 | O3: 1 | P3: 2 | Q3: 3 | T3: 1 | U3: 2 | V3: 3 | W3: 1 | X3: 2 | Y3: 3
A4: 0 | B4: 0 | C4: 1570 | D4: 1586 | E4: 1576 | F4: 1563 | G4: 1554 | H4: =ROUNDDOWN(AVERAGE(C4:G4),0) -> 1569 | I4: =_xlfn.STDEV.S(C4:G4) -> 12.214745 | K4: 0.9273 | M4: =AVERAGE(J4:L4) -> 0.9273 | N4: =_xlfn.STDEV.S(J4:L4) -> #DIV/0! | O4: 0 | P4: 0 | Q4: 0 | R4: =AVERAGE(O4:Q4) -> 0 | S4: =_xlfn.STDEV.S(O4:Q4) -> 0 | T4: 0.91120879 | U4: 0.91054945 | V4: 0.91835165 | W4: 0.87617647 | X4: 0.87441176 | Y4: 0.87735294 | Z4: =AVERAGE(T4:Y4) -> 0.89467518 | AA4: =_xlfn.STDEV.S(T4:Y4) -> 0.020682341
A5: 1 | B5: 20 | H5: =ROUNDDOWN(AVERAGE(C5:G5),0) -> #DIV/0! | I5: =_xlfn.STDEV.S(C5:G5) -> #DIV/0! | M5: =AVERAGE(J5:L5) -> #DIV/0! | N5: =_xlfn.STDEV.S(J5:L5) -> #DIV/0! | R5: =AVERAGE(O5:Q5) -> #DIV/0! | S5: =_xlfn.STDEV.S(O5:Q5) -> #DIV/0! | Z5: =AVERAGE(T5:Y5) -> #DIV/0! | AA5: =_xlfn.STDEV.S(T5:Y5) -> #DIV/0!
A6: 2 | B6: 40 | H6: =ROUNDDOWN(AVERAGE(C6:G6),0) -> #DIV/0! | I6: =_xlfn.STDEV.S(C6:G6) -> #DIV/0! | M6: =AVERAGE(J6:L6) -> #DIV/0! | N6: =_xlfn.STDEV.S(J6:L6) -> #DIV/0! | R6: =AVERAGE(O6:Q6) -> #DIV/0! | S6: =_xlfn.STDEV.S(O6:Q6) -> #DIV/0! | Z6: =AVERAGE(T6:Y6) -> #DIV/0! | AA6: =_xlfn.STDEV.S(T6:Y6) -> #DIV/0!
A7: 3 | B7: 60 | H7: =ROUNDDOWN(AVERAGE(C7:G7),0) -> #DIV/0! | I7: =_xlfn.STDEV.S(C7:G7) -> #DIV/0! | M7: =AVERAGE(J7:L7) -> #DIV/0! | N7: =_xlfn.STDEV.S(J7:L7) -> #DIV/0! | R7: =AVERAGE(O7:Q7) -> #DIV/0! | S7: =_xlfn.STDEV.S(O7:Q7) -> #DIV/0! | Z7: =AVERAGE(T7:Y7) -> #DIV/0! | AA7: =_xlfn.STDEV.S(T7:Y7) -> #DIV/0!
A8: 4 | B8: 80 | H8: =ROUNDDOWN(AVERAGE(C8:G8),0) -> #DIV/0! | I8: =_xlfn.STDEV.S(C8:G8) -> #DIV/0! | M8: =AVERAGE(J8:L8) -> #DIV/0! | N8: =_xlfn.STDEV.S(J8:L8) -> #DIV/0! | R8: =AVERAGE(O8:Q8) -> #DIV/0! | S8: =_xlfn.STDEV.S(O8:Q8) -> #DIV/0! | Z8: =AVERAGE(T8:Y8) -> #DIV/0! | AA8: =_xlfn.STDEV.S(T8:Y8) -> #DIV/0!
A9: 5 | B9: 100 | H9: =ROUNDDOWN(AVERAGE(C9:G9),0) -> #DIV/0! | I9: =_xlfn.STDEV.S(C9:G9) -> #DIV/0! | M9: =AVERAGE(J9:L9) -> #DIV/0! | N9: =_xlfn.STDEV.S(J9:L9) -> #DIV/0! | R9: =AVERAGE(O9:Q9) -> #DIV/0! | S9: =_xlfn.STDEV.S(O9:Q9) -> #DIV/0! | Z9: =AVERAGE(T9:Y9) -> #DIV/0! | AA9: =_xlfn.STDEV.S(T9:Y9) -> #DIV/0!
A10: 6 | B10: 120 | H10: =ROUNDDOWN(AVERAGE(C10:G10),0) -> #DIV/0! | I10: =_xlfn.STDEV.S(C10:G10) -> #DIV/0! | M10: =AVERAGE(J10:L10) -> #DIV/0! | N10: =_xlfn.STDEV.S(J10:L10) -> #DIV/0! | R10: =AVERAGE(O10:Q10) -> #DIV/0! | S10: =_xlfn.STDEV.S(O10:Q10) -> #DIV/0! | Z10: =AVERAGE(T10:Y10) -> #DIV/0! | AA10: =_xlfn.STDEV.S(T10:Y10) -> #DIV/0!
A11: 7 | B11: 140 | H11: =ROUNDDOWN(AVERAGE(C11:G11),0) -> #DIV/0! | I11: =_xlfn.STDEV.S(C11:G11) -> #DIV/0! | M11: =AVERAGE(J11:L11) -> #DIV/0! | N11: =_xlfn.STDEV.S(J11:L11) -> #DIV/0! | R11: =AVERAGE(O11:Q11) -> #DIV/0! | S11: =_xlfn.STDEV.S(O11:Q11) -> #DIV/0! | Z11: =AVERAGE(T11:Y11) -> #DIV/0! | AA11: =_xlfn.STDEV.S(T11:Y11) -> #DIV/0!
A12: 8 | B12: 160 | H12: =ROUNDDOWN(AVERAGE(C12:G12),0) -> #DIV/0! | I12: =_xlfn.STDEV.S(C12:G12) -> #DIV/0! | M12: =AVERAGE(J12:L12) -> #DIV/0! | N12: =_xlfn.STDEV.S(J12:L12) -> #DIV/0! | R12: =AVERAGE(O12:Q12) -> #DIV/0! | S12: =_xlfn.STDEV.S(O12:Q12) -> #DIV/0! | Z12: =AVERAGE(T12:Y12) -> #DIV/0! | AA12: =_xlfn.STDEV.S(T12:Y12) -> #DIV/0!
A13: 9 | B13: 180 | H13: =ROUNDDOWN(AVERAGE(C13:G13),0) -> #DIV/0! | I13: =_xlfn.STDEV.S(C13:G13) -> #DIV/0! | M13: =AVERAGE(J13:L13) -> #DIV/0! | N13: =_xlfn.STDEV.S(J13:L13) -> #DIV/0! | R13: =AVERAGE(O13:Q13) -> #DIV/0! | S13: =_xlfn.STDEV.S(O13:Q13) -> #DIV/0! | Z13: =AVERAGE(T13:Y13) -> #DIV/0! | AA13: =_xlfn.STDEV.S(T13:Y13) -> #DIV/0!
A14: Final | B14: 200 | C14: 1304 | D14: 1307 | E14: 1325 | F14: 1309 | G14: 1307 | H14: =ROUNDDOWN(AVERAGE(C14:G14),0) -> 1310 | I14: =_xlfn.STDEV.S(C14:G14) -> 8.3546394 | K14: 0.9892 | M14: =AVERAGE(J14:L14) -> 0.9892 | N14: =_xlfn.STDEV.S(J14:L14) -> #DIV/0! | P14: 0.0505 | R14: =AVERAGE(O14:Q14) -> 0.0505 | S14: =_xlfn.STDEV.S(O14:Q14) -> #DIV/0! | T14: 1.0085714 | U14: 0.99021978 | V14: 0.99120879 | W14: 0.96514706 | X14: 0.95838235 | Y14: 0.96382353 | Z14: =AVERAGE(T14:Y14) -> 0.97955882 | AA14: =_xlfn.STDEV.S(T14:Y14) -> 0.019974235

Sheet %Ganancia
A1: Lote 1
A2: Conteo de pellet/g | K2: Ganancia en peso [g] | S2: % de Ganancia
A3: Muestra | B3: Tiempo | C3: 1 | D3: 2 | E3: 3 | F3: 4 | G3: 5 | H3: m | I3: s | K3: Tiempo | L3: 1 | M3: 2 | N3: 3 | O3: 4 | P3: 5 | Q3: m | S3: Tiempo | T3: 1 | U3: 2 | V3: 3 | W3: 4 | X3: 5 | Y3: m
A4: Desnudo | B4: 0 | C4: ='Lote 1'!C4 -> 1594 | D4: ='Lote 1'!D4 -> 1615 | E4: ='Lote 1'!E4 -> 1610 | F4: ='Lote 1'!F4 -> 1585 | G4: ='Lote 1'!G4 -> 1601 | H4: =ROUND(AVERAGE(C4:G4),0) -> 1601 | I4: =_xlfn.STDEV.S(C4:G4) -> 12.062338 | K4: 0 | L4: =1/C4 -> 0.00062735257 | M4: =1/D4 -> 0.00061919505 | N4: =1/E4 -> 0.00062111801 | O4: =1/F4 -> 0.00063091483 | P4: =1/G4 -> 0.00062460962 | Q4: =AVERAGE(L4:P4) -> 0.00062463802 | S4: 0 | T4: 0 | U4: 0 | V4: 0 | W4: 0 | X4: 0 | Y4: 0
A5: 1 | B5: 20 | C5: ='Lote 1'!C5 -> 0 | D5: ='Lote 1'!D5 -> 0 | E5: ='Lote 1'!E5 -> 0 | F5: ='Lote 1'!F5 -> 0 | G5: ='Lote 1'!G5 -> 0 | H5: =ROUND(AVERAGE(C5:G5),0) -> 0 | I5: =_xlfn.STDEV.S(C5:G5) -> 0 | K5: 20 | L5: =1/C5 -> #DIV/0! | M5: =1/D5 -> #DIV/0! | N5: =1/E5 -> #DIV/0! | O5: =1/F5 -> #DIV/0! | P5: =1/G5 -> #DIV/0! | Q5: =AVERAGE(L5:P5) -> #DIV/0! | S5: 20 | T5: =(L5-$M$46)/$M$46 -> #DIV/0! | U5: =(M5-$M$46)/$M$46 -> #DIV/0! | V5: =(N5-$M$46)/$M$46 -> #DIV/0! | W5: =(O5-$M$46)/$M$46 -> #DIV/0! | X5: =(P5-$M$46)/$M$46 -> #DIV/0! | Y5: =AVERAGE(T5:X5) -> #DIV/0!
A6: 2 | B6: 40 | C6: ='Lote 1'!C6 -> 0 | D6: ='Lote 1'!D6 -> 0 | E6: ='Lote 1'!E6 -> 0 | F6: ='Lote 1'!F6 -> 0 | G6: ='Lote 1'!G6 -> 0 | H6: =ROUND(AVERAGE(C6:G6),0) -> 0 | I6: =_xlfn.STDEV.S(C6:G6) -> 0 | K6: 40 | L6: =1/C6 -> #DIV/0! | M6: =1/D6 -> #DIV/0! | N6: =1/E6 -> #DIV/0! | O6: =1/F6 -> #DIV/0! | P6: =1/G6 -> #DIV/0! | Q6: =AVERAGE(L6:P6) -> #DIV/0! | S6: 40 | T6: =(L6-$M$46)/$M$46 -> #DIV/0! | U6: =(M6-$M$46)/$M$46 -> #DIV/0! | V6: =(N6-$M$46)/$M$46 -> #DIV/0! | W6: =(O6-$M$46)/$M$46 -> #DIV/0! | X6: =(P6-$M$46)/$M$46 -> #DIV/0! | Y6: =AVERAGE(T6:X6) -> #DIV/0!
A7: 3 | B7: 60 | C7: ='Lote 1'!C7 -> 0 | D7: ='Lote 1'!D7 -> 0 | E7: ='Lote 1'!E7 -> 0 | F7: ='Lote 1'!F7 -> 0 | G7: ='Lote 1'!G7 -> 0 | H7: =ROUND(AVERAGE(C7:G7),0) -> 0 | I7: =_xlfn.STDEV.S(C7:G7) -> 0 | K7: 60 | L7: =1/C7 -> #DIV/0! | M7: =1/D7 -> #DIV/0! | N7: =1/E7 -> #DIV/0! | O7: =1/F7 -> #DIV/0! | P7: =1/G7 -> #DIV/0! | Q7: =AVERAGE(L7:P7) -> #DIV/0! | S7: 60 | T7: =(L7-$M$46)/$M$46 -> #DIV/0! | U7: =(M7-$M$46)/$M$46 -> #DIV/0! | V7: =(N7-$M$46)/$M$46 -> #DIV/0! | W7: =(O7-$M$46)/$M$46 -> #DIV/0! | X7: =(P7-$M$46)/$M$46 -> #DIV/0! | Y7: =AVERAGE(T7:X7) -> #DIV/0!
A8: 4 | B8: 80 | C8: ='Lote 1'!C8 -> 0 | D8: ='Lote 1'!D8 -> 0 | E8: ='Lote 1'!E8 -> 0 | F8: ='Lote 1'!F8 -> 0 | G8: ='Lote 1'!G8 -> 0 | H8: =ROUND(AVERAGE(C8:G8),0) -> 0 | I8: =_xlfn.STDEV.S(C8:G8) -> 0 | K8: 80 | L8: =1/C8 -> #DIV/0! | M8: =1/D8 -> #DIV/0! | N8: =1/E8 -> #DIV/0! | O8: =1/F8 -> #DIV/0! | P8: =1/G8 -> #DIV/0! | Q8: =AVERAGE(L8:P8) -> #DIV/0! | S8: 80 | T8: =(L8-$M$46)/$M$46 -> #DIV/0! | U8: =(M8-$M$46)/$M$46 -> #DIV/0! | V8: =(N8-$M$46)/$M$46 -> #DIV/0! | W8: =(O8-$M$46)/$M$46 -> #DIV/0! | X8: =(P8-$M$46)/$M$46 -> #DIV/0! | Y8: =AVERAGE(T8:X8) -> #DIV/0!
A9: 5 | B9: 100 | C9: ='Lote 1'!C9 -> 0 | D9: ='Lote 1'!D9 -> 0 | E9: ='Lote 1'!E9 -> 0 | F9: ='Lote 1'!F9 -> 0 | G9: ='Lote 1'!G9 -> 0 | H9: =ROUND(AVERAGE(C9:G9),0) -> 0 | I9: =_xlfn.STDEV.S(C9:G9) -> 0 | K9: 100 | L9: =1/C9 -> #DIV/0! | M9: =1/D9 -> #DIV/0! | N9: =1/E9 -> #DIV/0! | O9: =1/F9 -> #DIV/0! | P9: =1/G9 -> #DIV/0! | Q9: =AVERAGE(L9:P9) -> #DIV/0! | S9: 100 | T9: =(L9-$M$46)/$M$46 -> #DIV/0! | U9: =(M9-$M$46)/$M$46 -> #DIV/0! | V9: =(N9-$M$46)/$M$46 -> #DIV/0! | W9: =(O9-$M$46)/$M$46 -> #DIV/0! | X9: =(P9-$M$46)/$M$46 -> #DIV/0! | Y9: =AVERAGE(T9:X9) -> #DIV/0!
A10: 6 | B10: 120 | C10: ='Lote 1'!C10 -> 0 | D10: ='Lote 1'!D10 -> 0 | E10: ='Lote 1'!E10 -> 0 | F10: ='Lote 1'!F10 -> 0 | G10: ='Lote 1'!G10 -> 0 | H10: =ROUND(AVERAGE(C10:G10),0) -> 0 | I10: =_xlfn.STDEV.S(C10:G10) -> 0 | K10: 120 | L10: =1/C10 -> #DIV/0! | M10: =1/D10 -> #DIV/0! | N10: =1/E10 -> #DIV/0! | O10: =1/F10 -> #DIV/0! | P10: =1/G10 -> #DIV/0! | Q10: =AVERAGE(L10:P10) -> #DIV/0! | S10: 120 | T10: =(L10-$M$46)/$M$46 -> #DIV/0! | U10: =(M10-$M$46)/$M$46 -> #DIV/0! | V10: =(N10-$M$46)/$M$46 -> #DIV/0! | W10: =(O10-$M$46)/$M$46 -> #DIV/0! | X10: =(P10-$M$46)/$M$46 -> #DIV/0! | Y10: =AVERAGE(T10:X10) -> #DIV/0!
A11: 7 | B11: 140 | C11: ='Lote 1'!C11 -> 0 | D11: ='Lote 1'!D11 -> 0 | E11: ='Lote 1'!E11 -> 0 | F11: ='Lote 1'!F11 -> 0 | G11: ='Lote 1'!G11 -> 0 | H11: =ROUND(AVERAGE(C11:G11),0) -> 0 | I11: =_xlfn.STDEV.S(C11:G11) -> 0 | K11: 140 | L11: =1/C11 -> #DIV/0! | M11: =1/D11 -> #DIV/0! | N11: =1/E11 -> #DIV/0! | O11: =1/F11 -> #DIV/0! | P11: =1/G11 -> #DIV/0! | Q11: =AVERAGE(L11:P11) -> #DIV/0! | S11: 140 | T11: =(L11-$M$46)/$M$46 -> #DIV/0! | U11: =(M11-$M$46)/$M$46 -> #DIV/0! | V11: =(N11-$M$46)/$M$46 -> #DIV/0! | W11: =(O11-$M$46)/$M$46 -> #DIV/0! | X11: =(P11-$M$46)/$M$46 -> #DIV/0! | Y11: =AVERAGE(T11:X11) -> #DIV/0!
A12: 8 | B12: 160 | C12: ='Lote 1'!C12 -> 0 | D12: ='Lote 1'!D12 -> 0 | E12: ='Lote 1'!E12 -> 0 | F12: ='Lote 1'!F12 -> 0 | G12: ='Lote 1'!G12 -> 0 | H12: =ROUND(AVERAGE(C12:G12),0) -> 0 | I12: =_xlfn.STDEV.S(C12:G12) -> 0 | K12: 160 | L12: =1/C12 -> #DIV/0! | M12: =1/D12 -> #DIV/0! | N12: =1/E12 -> #DIV/0! | O12: =1/F12 -> #DIV/0! | P12: =1/G12 -> #DIV/0! | Q12: =AVERAGE(L12:P12) -> #DIV/0! | S12: 160 | T12: =(L12-$M$46)/$M$46 -> #DIV/0! | U12: =(M12-$M$46)/$M$46 -> #DIV/0! | V12: =(N12-$M$46)/$M$46 -> #DIV/0! | W12: =(O12-$M$46)/$M$46 -> #DIV/0! | X12: =(P12-$M$46)/$M$46 -> #DIV/0! | Y12: =AVERAGE(T12:X12) -> #DIV/0!
A13: 9 | B13: 180 | C13: ='Lote 1'!C13 -> 0 | D13: ='Lote 1'!D13 -> 0 | E13: ='Lote 1'!E13 -> 0 | F13: ='Lote 1'!F13 -> 0 | G13: ='Lote 1'!G13 -> 0 | H13: =ROUND(AVERAGE(C13:G13),0) -> 0 | I13: =_xlfn.STDEV.S(C12:G12) -> 0 | K13: 180 | L13: =1/C13 -> #DIV/0! | M13: =1/D13 -> #DIV/0! | N13: =1/E13 -> #DIV/0! | O13: =1/F13 -> #DIV/0! | P13: =1/G13 -> #DIV/0! | Q13: =AVERAGE(L13:P13) -> #DIV/0! | S13: 180 | T13: =(L13-$M$46)/$M$46 -> #DIV/0! | U13: =(M13-$M$46)/$M$46 -> #DIV/0! | V13: =(N13-$M$46)/$M$46 -> #DIV/0! | W13: =(O13-$M$46)/$M$46 -> #DIV/0! | X13: =(P13-$M$46)/$M$46 -> #DIV/0! | Y13: =AVERAGE(T13:X13) -> #DIV/0!
A14: Final | B14: 200 | C14: ='Lote 1'!C14 -> 1308 | D14: ='Lote 1'!D14 -> 1312 | E14: ='Lote 1'!E14 -> 1303 | F14: ='Lote 1'!F14 -> 1296 | G14: ='Lote 1'!G14 -> 1297 | H14: =ROUND(AVERAGE(C14:G14),0) -> 1303 | I14: =_xlfn.STDEV.S(C14:G14) -> 6.9065187 | K14: 200 | L14: =1/C14 -> 0.00076452599 | M14: =1/D14 -> 0.00076219512 | N14: =1/E14 -> 0.00076745971 | O14: =1/F14 -> 0.00077160494 | P14: =1/G14 -> 0.00077101002 | Q14: =AVERAGE(L14:P14) -> 0.00076735916 | S14: 200 | T14: =(L14-$M$46)/$M$46 -> 0.17558614 | U14: =(M14-$M$46)/$M$46 -> 0.17200203 | V14: =(N14-$M$46)/$M$46 -> 0.18009721 | W14: =(O14-$M$46)/$M$46 -> 0.18647119 | X14: =(P14-$M$46)/$M$46 -> 0.18555641 | Y14: =AVERAGE(T14:X14) -> 0.1799426
A16: Lote 2
A17: Conteo de pellet/g | K17: Ganancia en peso [g] | S17: % de Ganancia
A18: Muestra | B18: Tiempo | C18: 1 | D18: 2 | E18: 3 | F18: 4 | G18: 5 | H18: m | I18: s | K18: Tiempo | L18: 1 | M18: 2 | N18: 3 | O18: 4 | P18: 5 | Q18: m | S18: Tiempo | T18: 1 | U18: 2 | V18: 3 | W18: 4 | X18: 5 | Y18: m
A19: Desnudo | B19: 0 | C19: ='Lote 2'!C4 -> 1536 | D19: ='Lote 2'!D4 -> 1581 | E19: ='Lote 2'!E4 -> 1556 | F19: ='Lote 2'!F4 -> 1557 | G19: ='Lote 2'!G4 -> 1560 | H19: =ROUND(AVERAGE(C19:G19),0) -> 1558 | I19: =_xlfn.STDEV.S(C19:G19) -> 15.984367 | K19: 0 | L19: =1/C19 -> 0.00065104167 | M19: =1/D19 -> 0.00063251107 | N19: =1/E19 -> 0.00064267352 | O19: =1/F19 -> 0.00064226076 | P19: =1/G19 -> 0.00064102564 | Q19: =AVERAGE(L19:P19) -> 0.00064190253 | S19: 0 | T19: 0 | U19: 0 | V19: 0 | W19: 0 | X19: 0 | Y19: 0
A20: 1 | B20: 20 | C20: ='Lote 2'!C5 -> 0 | D20: ='Lote 2'!D5 -> 0 | E20: ='Lote 2'!E5 -> 0 | F20: ='Lote 2'!F5 -> 0 | G20: ='Lote 2'!G5 -> 0 | H20: =ROUND(AVERAGE(C20:G20),0) -> 0 | I20: =_xlfn.STDEV.S(C20:G20) -> 0 | K20: 20 | L20: =1/C20 -> #DIV/0! | M20: =1/D20 -> #DIV/0! | N20: =1/E20 -> #DIV/0! | O20: =1/F20 -> #DIV/0! | P20: =1/G20 -> #DIV/0! | Q20: =AVERAGE(L20:P20) -> #DIV/0! | S20: 20 | T20: =ABS((L20-$M$46)/$M$46) -> #DIV/0! | U20: =ABS((M20-$M$46)/$M$46) -> #DIV/0! | V20: =ABS((N20-$M$46)/$M$46) -> #DIV/0! | W20: =ABS((O20-$M$46)/$M$46) -> #DIV/0! | X20: =ABS((P20-$M$46)/$M$46) -> #DIV/0! | Y20: =AVERAGE(T20:X20) -> #DIV/0!
A21: 2 | B21: 40 | C21: ='Lote 2'!C6 -> 0 | D21: ='Lote 2'!D6 -> 0 | E21: ='Lote 2'!E6 -> 0 | F21: ='Lote 2'!F6 -> 0 | G21: ='Lote 2'!G6 -> 0 | H21: =ROUND(AVERAGE(C21:G21),0) -> 0 | I21: =_xlfn.STDEV.S(C21:G21) -> 0 | K21: 40 | L21: =1/C21 -> #DIV/0! | M21: =1/D21 -> #DIV/0! | N21: =1/E21 -> #DIV/0! | O21: =1/F21 -> #DIV/0! | P21: =1/G21 -> #DIV/0! | Q21: =AVERAGE(L21:P21) -> #DIV/0! | S21: 40 | T21: =ABS((L21-$M$46)/$M$46) -> #DIV/0! | U21: =ABS((M21-$M$46)/$M$46) -> #DIV/0! | V21: =ABS((N21-$M$46)/$M$46) -> #DIV/0! | W21: =ABS((O21-$M$46)/$M$46) -> #DIV/0! | X21: =ABS((P21-$M$46)/$M$46) -> #DIV/0! | Y21: =AVERAGE(T21:X21) -> #DIV/0!
A22: 3 | B22: 60 | C22: ='Lote 2'!C7 -> 0 | D22: ='Lote 2'!D7 -> 0 | E22: ='Lote 2'!E7 -> 0 | F22: ='Lote 2'!F7 -> 0 | G22: ='Lote 2'!G7 -> 0 | H22: =ROUND(AVERAGE(C22:G22),0) -> 0 | I22: =_xlfn.STDEV.S(C22:G22) -> 0 | K22: 60 | L22: =1/C22 -> #DIV/0! | M22: =1/D22 -> #DIV/0! | N22: =1/E22 -> #DIV/0! | O22: =1/F22 -> #DIV/0! | P22: =1/G22 -> #DIV/0! | Q22: =AVERAGE(L22:P22) -> #DIV/0! | S22: 60 | T22: =ABS((L22-$M$46)/$M$46) -> #DIV/0! | U22: =ABS((M22-$M$46)/$M$46) -> #DIV/0! | V22: =ABS((N22-$M$46)/$M$46) -> #DIV/0! | W22: =ABS((O22-$M$46)/$M$46) -> #DIV/0! | X22: =ABS((P22-$M$46)/$M$46) -> #DIV/0! | Y22: =AVERAGE(T22:X22) -> #DIV/0!
A23: 4 | B23: 80 | C23: ='Lote 2'!C8 -> 0 | D23: ='Lote 2'!D8 -> 0 | E23: ='Lote 2'!E8 -> 0 | F23: ='Lote 2'!F8 -> 0 | G23: ='Lote 2'!G8 -> 0 | H23: =ROUND(AVERAGE(C23:G23),0) -> 0 | I23: =_xlfn.STDEV.S(C23:G23) -> 0 | K23: 80 | L23: =1/C23 -> #DIV/0! | M23: =1/D23 -> #DIV/0! | N23: =1/E23 -> #DIV/0! | O23: =1/F23 -> #DIV/0! | P23: =1/G23 -> #DIV/0! | Q23: =AVERAGE(L23:P23) -> #DIV/0! | S23: 80 | T23: =ABS((L23-$M$46)/$M$46) -> #DIV/0! | U23: =ABS((M23-$M$46)/$M$46) -> #DIV/0! | V23: =ABS((N23-$M$46)/$M$46) -> #DIV/0! | W23: =ABS((O23-$M$46)/$M$46) -> #DIV/0! | X23: =ABS((P23-$M$46)/$M$46) -> #DIV/0! | Y23: =AVERAGE(T23:X23) -> #DIV/0!
A24: 5 | B24: 100 | C24: ='Lote 2'!C9 -> 0 | D24: ='Lote 2'!D9 -> 0 | E24: ='Lote 2'!E9 -> 0 | F24: ='Lote 2'!F9 -> 0 | G24: ='Lote 2'!G9 -> 0 | H24: =ROUND(AVERAGE(C24:G24),0) -> 0 | I24: =_xlfn.STDEV.S(C24:G24) -> 0 | K24: 100 | L24: =1/C24 -> #DIV/0! | M24: =1/D24 -> #DIV/0! | N24: =1/E24 -> #DIV/0! | O24: =1/F24 -> #DIV/0! | P24: =1/G24 -> #DIV/0! | Q24: =AVERAGE(L24:P24) -> #DIV/0! | S24: 100 | T24: =ABS((L24-$M$46)/$M$46) -> #DIV/0! | U24: =ABS((M24-$M$46)/$M$46) -> #DIV/0! | V24: =ABS((N24-$M$46)/$M$46) -> #DIV/0! | W24: =ABS((O24-$M$46)/$M$46) -> #DIV/0! | X24: =ABS((P24-$M$46)/$M$46) -> #DIV/0! | Y24: =AVERAGE(T24:X24) -> #DIV/0!
A25: 6 | B25: 120 | C25: ='Lote 2'!C10 -> 0 | D25: ='Lote 2'!D10 -> 0 | E25: ='Lote 2'!E10 -> 0 | F25: ='Lote 2'!F10 -> 0 | G25: ='Lote 2'!G10 -> 0 | H25: =ROUND(AVERAGE(C25:G25),0) -> 0 | I25: =_xlfn.STDEV.S(C25:G25) -> 0 | K25: 120 | L25: =1/C25 -> #DIV/0! | M25: =1/D25 -> #DIV/0! | N25: =1/E25 -> #DIV/0! | O25: =1/F25 -> #DIV/0! | P25: =1/G25 -> #DIV/0! | Q25: =AVERAGE(L25:P25) -> #DIV/0! | S25: 120 | T25: =ABS((L25-$M$46)/$M$46) -> #DIV/0! | U25: =ABS((M25-$M$46)/$M$46) -> #DIV/0! | V25: =ABS((N25-$M$46)/$M$46) -> #DIV/0! | W25: =ABS((O25-$M$46)/$M$46) -> #DIV/0! | X25: =ABS((P25-$M$46)/$M$46) -> #DIV/0! | Y25: =AVERAGE(T25:X25) -> #DIV/0!
A26: 7 | B26: 140 | C26: ='Lote 2'!C11 -> 0 | D26: ='Lote 2'!D11 -> 0 | E26: ='Lote 2'!E11 -> 0 | F26: ='Lote 2'!F11 -> 0 | G26: ='Lote 2'!G11 -> 0 | H26: =ROUND(AVERAGE(C26:G26),0) -> 0 | I26: =_xlfn.STDEV.S(C26:G26) -> 0 | K26: 140 | L26: =1/C26 -> #DIV/0! | M26: =1/D26 -> #DIV/0! | N26: =1/E26 -> #DIV/0! | O26: =1/F26 -> #DIV/0! | P26: =1/G26 -> #DIV/0! | Q26: =AVERAGE(L26:P26) -> #DIV/0! | S26: 140 | T26: =ABS((L26-$M$46)/$M$46) -> #DIV/0! | U26: =ABS((M26-$M$46)/$M$46) -> #DIV/0! | V26: =ABS((N26-$M$46)/$M$46) -> #DIV/0! | W26: =ABS((O26-$M$46)/$M$46) -> #DIV/0! | X26: =ABS((P26-$M$46)/$M$46) -> #DIV/0! | Y26: =AVERAGE(T26:X26) -> #DIV/0!
A27: 8 | B27: 160 | C27: ='Lote 2'!C12 -> 0 | D27: ='Lote 2'!D12 -> 0 | E27: ='Lote 2'!E12 -> 0 | F27: ='Lote 2'!F12 -> 0 | G27: ='Lote 2'!G12 -> 0 | H27: =ROUND(AVERAGE(C27:G27),0) -> 0 | I27: =_xlfn.STDEV.S(C27:G27) -> 0 | K27: 160 | L27: =1/C27 -> #DIV/0! | M27: =1/D27 -> #DIV/0! | N27: =1/E27 -> #DIV/0! | O27: =1/F27 -> #DIV/0! | P27: =1/G27 -> #DIV/0! | Q27: =AVERAGE(L27:P27) -> #DIV/0! | S27: 160 | T27: =ABS((L27-$M$46)/$M$46) -> #DIV/0! | U27: =ABS((M27-$M$46)/$M$46) -> #DIV/0! | V27: =ABS((N27-$M$46)/$M$46) -> #DIV/0! | W27: =ABS((O27-$M$46)/$M$46) -> #DIV/0! | X27: =ABS((P27-$M$46)/$M$46) -> #DIV/0! | Y27: =AVERAGE(T27:X27) -> #DIV/0!
A28: 9 | B28: 180 | C28: ='Lote 2'!C13 -> 0 | D28: ='Lote 2'!D13 -> 0 | E28: ='Lote 2'!E13 -> 0 | F28: ='Lote 2'!F13 -> 0 | G28: ='Lote 2'!G13 -> 0 | H28: =ROUND(AVERAGE(C28:G28),0) -> 0 | I28: =_xlfn.STDEV.S(C28:G28) -> 0 | K28: 180 | L28: =1/C28 -> #DIV/0! | M28: =1/D28 -> #DIV/0! | N28: =1/E28 -> #DIV/0! | O28: =1/F28 -> #DIV/0! | P28: =1/G28 -> #DIV/0! | Q28: =AVERAGE(L28:P28) -> #DIV/0! | S28: 180 | T28: =ABS((L28-$M$46)/$M$46) -> #DIV/0! | U28: =ABS((M28-$M$46)/$M$46) -> #DIV/0! | V28: =ABS((N28-$M$46)/$M$46) -> #DIV/0! | W28: =ABS((O28-$M$46)/$M$46) -> #DIV/0! | X28: =ABS((P28-$M$46)/$M$46) -> #DIV/0! | Y28: =AVERAGE(T28:X28) -> #DIV/0!
A29: Final | B29: 200 | C29: ='Lote 2'!C14 -> 1306 | D29: ='Lote 2'!D14 -> 1301 | E29: ='Lote 2'!E14 -> 1306 | F29: ='Lote 2'!F14 -> 1293 | G29: ='Lote 2'!G14 -> 1318 | H29: =ROUND(AVERAGE(C29:G29),0) -> 1305 | I29: =_xlfn.STDEV.S(C29:G29) -> 9.093954 | K29: 200 | L29: =1/C29 -> 0.00076569678 | M29: =1/D29 -> 0.00076863951 | N29: =1/E29 -> 0.00076569678 | O29: =1/F29 -> 0.0007733952 | P29: =1/G29 -> 0.00075872534 | Q29: =AVERAGE(L29:P29) -> 0.00076643072 | S29: 200 | T29: =ABS((L29-$M$46)/$M$46) -> 0.17738642 | U29: =ABS((M29-$M$46)/$M$46) -> 0.18191135 | V29: =ABS((N29-$M$46)/$M$46) -> 0.17738642 | W29: =ABS((O29-$M$46)/$M$46) -> 0.18922403 | X29: =ABS((P29-$M$46)/$M$46) -> 0.16666667 | Y29: =AVERAGE(T29:X29) -> 0.17851498
A31: Lote 3
A32: Conteo de pellet/g | K32: Ganancia en peso [g] | S32: % de Ganancia
A33: Muestra | B33: Tiempo | C33: 1 | D33: 2 | E33: 3 | F33: 4 | G33: 5 | H33: m | I33: s | K33: Tiempo | L33: 1 | M33: 2 | N33: 3 | O33: 4 | P33: 5 | Q33: m | S33: Tiempo | T33: 1 | U33: 2 | V33: 3 | W33: 4 | X33: 5 | Y33: m
A34: Desnudo | B34: 0 | C34: ='Lote 3'!C4 -> 1570 | D34: ='Lote 3'!D4 -> 1586 | E34: ='Lote 3'!E4 -> 1576 | F34: ='Lote 3'!F4 -> 1563 | G34: ='Lote 3'!G4 -> 1554 | H34: =ROUND(AVERAGE(C34:G34),0) -> 1570 | I34: =_xlfn.STDEV.S(C34:G34) -> 12.214745 | K34: 0 | L34: =1/C34 -> 0.00063694268 | M34: =1/D34 -> 0.00063051702 | N34: =1/E34 -> 0.00063451777 | O34: =1/F34 -> 0.00063979527 | P34: =1/G34 -> 0.00064350064 | Q34: =AVERAGE(L34:P34) -> 0.00063705467 | S34: 0 | T34: 0 | U34: 0 | V34: 0 | W34: 0 | X34: 0 | Y34: 0
A35: 1 | B35: 20 | C35: ='Lote 3'!C5 -> 0 | D35: ='Lote 3'!D5 -> 0 | E35: ='Lote 3'!E5 -> 0 | F35: ='Lote 3'!F5 -> 0 | G35: ='Lote 3'!G5 -> 0 | H35: =ROUND(AVERAGE(C35:G35),0) -> 0 | I35: =_xlfn.STDEV.S(C35:G35) -> 0 | K35: 20 | L35: =1/C35 -> #DIV/0! | M35: =1/D35 -> #DIV/0! | N35: =1/E35 -> #DIV/0! | O35: =1/F35 -> #DIV/0! | P35: =1/G35 -> #DIV/0! | Q35: =AVERAGE(L35:P35) -> #DIV/0! | S35: 20 | T35: =(L35-$M$46)/$M$46 -> #DIV/0! | U35: =(M35-$M$46)/$M$46 -> #DIV/0! | V35: =(N35-$M$46)/$M$46 -> #DIV/0! | W35: =(O35-$M$46)/$M$46 -> #DIV/0! | X35: =(P35-$M$46)/$M$46 -> #DIV/0! | Y35: =AVERAGE(T35:X35) -> #DIV/0!
A36: 2 | B36: 40 | C36: ='Lote 3'!C6 -> 0 | D36: ='Lote 3'!D6 -> 0 | E36: ='Lote 3'!E6 -> 0 | F36: ='Lote 3'!F6 -> 0 | G36: ='Lote 3'!G6 -> 0 | H36: =ROUND(AVERAGE(C36:G36),0) -> 0 | I36: =_xlfn.STDEV.S(C36:G36) -> 0 | K36: 40 | L36: =1/C36 -> #DIV/0! | M36: =1/D36 -> #DIV/0! | N36: =1/E36 -> #DIV/0! | O36: =1/F36 -> #DIV/0! | P36: =1/G36 -> #DIV/0! | Q36: =AVERAGE(L36:P36) -> #DIV/0! | S36: 40 | T36: =(L36-$M$46)/$M$46 -> #DIV/0! | U36: =(M36-$M$46)/$M$46 -> #DIV/0! | V36: =(N36-$M$46)/$M$46 -> #DIV/0! | W36: =(O36-$M$46)/$M$46 -> #DIV/0! | X36: =(P36-$M$46)/$M$46 -> #DIV/0! | Y36: =AVERAGE(T36:X36) -> #DIV/0!
A37: 3 | B37: 60 | C37: ='Lote 3'!C7 -> 0 | D37: ='Lote 3'!D7 -> 0 | E37: ='Lote 3'!E7 -> 0 | F37: ='Lote 3'!F7 -> 0 | G37: ='Lote 3'!G7 -> 0 | H37: =ROUND(AVERAGE(C37:G37),0) -> 0 | I37: =_xlfn.STDEV.S(C37:G37) -> 0 | K37: 60 | L37: =1/C37 -> #DIV/0! | M37: =1/D37 -> #DIV/0! | N37: =1/E37 -> #DIV/0! | O37: =1/F37 -> #DIV/0! | P37: =1/G37 -> #DIV/0! | Q37: =AVERAGE(L37:P37) -> #DIV/0! | S37: 60 | T37: =(L37-$M$46)/$M$46 -> #DIV/0! | U37: =(M37-$M$46)/$M$46 -> #DIV/0! | V37: =(N37-$M$46)/$M$46 -> #DIV/0! | W37: =(O37-$M$46)/$M$46 -> #DIV/0! | X37: =(P37-$M$46)/$M$46 -> #DIV/0! | Y37: =AVERAGE(T37:X37) -> #DIV/0!
A38: 4 | B38: 80 | C38: ='Lote 3'!C8 -> 0 | D38: ='Lote 3'!D8 -> 0 | E38: ='Lote 3'!E8 -> 0 | F38: ='Lote 3'!F8 -> 0 | G38: ='Lote 3'!G8 -> 0 | H38: =ROUND(AVERAGE(C38:G38),0) -> 0 | I38: =_xlfn.STDEV.S(C38:G38) -> 0 | K38: 80 | L38: =1/C38 -> #DIV/0! | M38: =1/D38 -> #DIV/0! | N38: =1/E38 -> #DIV/0! | O38: =1/F38 -> #DIV/0! | P38: =1/G38 -> #DIV/0! | Q38: =AVERAGE(L38:P38) -> #DIV/0! | S38: 80 | T38: =(L38-$M$46)/$M$46 -> #DIV/0! | U38: =(M38-$M$46)/$M$46 -> #DIV/0! | V38: =(N38-$M$46)/$M$46 -> #DIV/0! | W38: =(O38-$M$46)/$M$46 -> #DIV/0! | X38: =(P38-$M$46)/$M$46 -> #DIV/0! | Y38: =AVERAGE(T38:X38) -> #DIV/0!
A39: 5 | B39: 100 | C39: ='Lote 3'!C9 -> 0 | D39: ='Lote 3'!D9 -> 0 | E39: ='Lote 3'!E9 -> 0 | F39: ='Lote 3'!F9 -> 0 | G39: ='Lote 3'!G9 -> 0 | H39: =ROUND(AVERAGE(C39:G39),0) -> 0 | I39: =_xlfn.STDEV.S(C39:G39) -> 0 | K39: 100 | L39: =1/C39 -> #DIV/0! | M39: =1/D39 -> #DIV/0! | N39: =1/E39 -> #DIV/0! | O39: =1/F39 -> #DIV/0! | P39: =1/G39 -> #DIV/0! | Q39: =AVERAGE(L39:P39) -> #DIV/0! | S39: 100 | T39: =(L39-$M$46)/$M$46 -> #DIV/0! | U39: =(M39-$M$46)/$M$46 -> #DIV/0! | V39: =(N39-$M$46)/$M$46 -> #DIV/0! | W39: =(O39-$M$46)/$M$46 -> #DIV/0! | X39: =(P39-$M$46)/$M$46 -> #DIV/0! | Y39: =AVERAGE(T39:X39) -> #DIV/0!
A40: 6 | B40: 120 | C40: ='Lote 3'!C10 -> 0 | D40: ='Lote 3'!D10 -> 0 | E40: ='Lote 3'!E10 -> 0 | F40: ='Lote 3'!F10 -> 0 | G40: ='Lote 3'!G10 -> 0 | H40: =ROUND(AVERAGE(C40:G40),0) -> 0 | I40: =_xlfn.STDEV.S(C40:G40) -> 0 | K40: 120 | L40: =1/C40 -> #DIV/0! | M40: =1/D40 -> #DIV/0! | N40: =1/E40 -> #DIV/0! | O40: =1/F40 -> #DIV/0! | P40: =1/G40 -> #DIV/0! | Q40: =AVERAGE(L40:P40) -> #DIV/0! | S40: 120 | T40: =(L40-$M$46)/$M$46 -> #DIV/0! | U40: =(M40-$M$46)/$M$46 -> #DIV/0! | V40: =(N40-$M$46)/$M$46 -> #DIV/0! | W40: =(O40-$M$46)/$M$46 -> #DIV/0! | X40: =(P40-$M$46)/$M$46 -> #DIV/0! | Y40: =AVERAGE(T40:X40) -> #DIV/0!
A41: 7 | B41: 140 | C41: ='Lote 3'!C11 -> 0 | D41: ='Lote 3'!D11 -> 0 | E41: ='Lote 3'!E11 -> 0 | F41: ='Lote 3'!F11 -> 0 | G41: ='Lote 3'!G11 -> 0 | H41: =ROUND(AVERAGE(C41:G41),0) -> 0 | I41: =_xlfn.STDEV.S(C41:G41) -> 0 | K41: 140 | L41: =1/C41 -> #DIV/0! | M41: =1/D41 -> #DIV/0! | N41: =1/E41 -> #DIV/0! | O41: =1/F41 -> #DIV/0! | P41: =1/G41 -> #DIV/0! | Q41: =AVERAGE(L41:P41) -> #DIV/0! | S41: 140 | T41: =(L41-$M$46)/$M$46 -> #DIV/0! | U41: =(M41-$M$46)/$M$46 -> #DIV/0! | V41: =(N41-$M$46)/$M$46 -> #DIV/0! | W41: =(O41-$M$46)/$M$46 -> #DIV/0! | X41: =(P41-$M$46)/$M$46 -> #DIV/0! | Y41: =AVERAGE(T41:X41) -> #DIV/0!
A42: 8 | B42: 160 | C42: ='Lote 3'!C12 -> 0 | D42: ='Lote 3'!D12 -> 0 | E42: ='Lote 3'!E12 -> 0 | F42: ='Lote 3'!F12 -> 0 | G42: ='Lote 3'!G12 -> 0 | H42: =ROUND(AVERAGE(C42:G42),0) -> 0 | I42: =_xlfn.STDEV.S(C42:G42) -> 0 | K42: 160 | L42: =1/C42 -> #DIV/0! | M42: =1/D42 -> #DIV/0! | N42: =1/E42 -> #DIV/0! | O42: =1/F42 -> #DIV/0! | P42: =1/G42 -> #DIV/0! | Q42: =AVERAGE(L42:P42) -> #DIV/0! | S42: 160 | T42: =(L42-$M$46)/$M$46 -> #DIV/0! | U42: =(M42-$M$46)/$M$46 -> #DIV/0! | V42: =(N42-$M$46)/$M$46 -> #DIV/0! | W42: =(O42-$M$46)/$M$46 -> #DIV/0! | X42: =(P42-$M$46)/$M$46 -> #DIV/0! | Y42: =AVERAGE(T42:X42) -> #DIV/0!
...

Sheet Resumen
A1: Muestra | B1: Tiempo [min] | C1: Lote 1 | H1: Lote 2 | M1: Lote 3 | S1: Muestra | T1: Tiempo [min] | U1: Lote 1 | Z1: Lote 2 | AE1: Lote 3
C2: Pellets/g | D2: %Ganancia | E2: Diametro [mm] | F2: e [mm] | G2: r [g/ml] | H2: Pellets/g | I2: %Ganancia | J2: Diametro [mm] | K2: e [mm] | L2: r [g/ml] | M2: Pellets/g | N2: %Ganancia | O2: Diametro [mm] | P2: e [mm] | Q2: r [g/ml] | U2: Pellets/g | V2: %Ganancia | W2: Diametro [mm] | X2: e [mm] | Y2: r [g/ml] | Z2: Pellets/g | AA2: %Ganancia | AB2: Diametro [mm] | AC2: e [mm] | AD2: r [g/ml] | AE2: Pellets/g | AF2: %Ganancia | AG2: Diametro [mm] | AH2: e [mm] | AI2: r [g/ml]
A3: 0 | B3: 0 | C3: ='Lote 1'!H4 -> 1601 | D3: ='%Ganancia'!Y4 -> 0 | E3: ='Lote 1'!M4 -> 0.9845 | F3: ='Lote 1'!R4 -> 0 | G3: ='Lote 1'!Z4 -> 0.89453054 | H3: ='Lote 2'!H4 -> 1558 | I3: ='%Ganancia'!Y19 -> 0 | J3: ='Lote 2'!M4 -> 0.9521 | K3: ='Lote 2'!R4 -> 0 | L3: ='Lote 2'!Z4 -> 0.90014329 | M3: ='Lote 3'!H4 -> 1569 | N3: ='%Ganancia'!Y34 -> 0 | O3: ='Lote 3'!M4 -> 0.9273 | P3: ='Lote 3'!R4 -> 0 | Q3: ='Lote 3'!Z4 -> 0.89467518 | S3: 0 | T3: 0 | U3: 1601 | V3: ='%Ganancia'!AQ4 -> 0 | W3: 0.9845 | X3: ='Lote 1'!AJ4 -> 0 | Y3: 0.8945 | Z3: 1558 | AA3: ='%Ganancia'!AQ19 -> 0 | AB3: 0.9521 | AC3: ='Lote 2'!AJ4 -> 0 | AD3: 0.9001 | AE3: 1569 | AF3: ='%Ganancia'!AQ34 -> 0 | AG3: 0.9273 | AH3: ='Lote 3'!AJ4 -> 0 | AI3: 0.8947
A4: 1 | B4: 20 | C4: ='Lote 1'!H5 -> #DIV/0! | D4: ='%Ganancia'!Y5 -> #DIV/0! | E4: ='Lote 1'!M5 -> #DIV/0! | F4: ='Lote 1'!R5 -> #DIV/0! | G4: ='Lote 1'!Z5 -> #DIV/0! | H4: ='Lote 2'!H5 -> #DIV/0! | I4: ='%Ganancia'!Y20 -> #DIV/0! | J4: ='Lote 2'!M5 -> #DIV/0! | K4: ='Lote 2'!R5 -> #DIV/0! | L4: ='Lote 2'!Z5 -> #DIV/0! | M4: ='Lote 3'!H5 -> #DIV/0! | N4: ='%Ganancia'!Y35 -> #DIV/0! | O4: ='Lote 3'!M5 -> #DIV/0! | P4: ='Lote 3'!R5 -> #DIV/0! | Q4: ='Lote 3'!Z5 -> #DIV/0! | S4: Final | T4: 200 | U4: 1303 | V4: 0.1799426 | W4: 0.9361 | X4: 0.0501 | Y4: 0.9782089 | Z4: 1304 | AA4: 0.17851498 | AB4: 0.9892 | AC4: 0.0508 | AD4: 0.96698906 | AE4: 1310 | AF4: 0.17347092 | AG4: 0.9892 | AH4: 0.0505 | AI4: 0.97955882
A5: 2 | B5: 40 | C5: ='Lote 1'!H6 -> #DIV/0! | D5: ='%Ganancia'!Y6 -> #DIV/0! | E5: ='Lote 1'!M6 -> #DIV/0! | F5: ='Lote 1'!R6 -> #DIV/0! | G5: ='Lote 1'!Z6 -> #DIV/0! | H5: ='Lote 2'!H6 -> #DIV/0! | I5: ='%Ganancia'!Y21 -> #DIV/0! | J5: ='Lote 2'!M6 -> #DIV/0! | K5: ='Lote 2'!R6 -> #DIV/0! | L5: ='Lote 2'!Z6 -> #DIV/0! | M5: ='Lote 3'!H6 -> #DIV/0! | N5: ='%Ganancia'!Y36 -> #DIV/0! | O5: ='Lote 3'!M6 -> #DIV/0! | P5: ='Lote 3'!R6 -> #DIV/0! | Q5: ='Lote 3'!Z6 -> #DIV/0!
A6: 3 | B6: 60 | C6: ='Lote 1'!H7 -> #DIV/0! | D6: ='%Ganancia'!Y7 -> #DIV/0! | E6: ='Lote 1'!M7 -> #DIV/0! | F6: ='Lote 1'!R7 -> #DIV/0! | G6: ='Lote 1'!Z7 -> #DIV/0! | H6: ='Lote 2'!H7 -> #DIV/0! | I6: ='%Ganancia'!Y22 -> #DIV/0! | J6: ='Lote 2'!M7 -> #DIV/0! | K6: ='Lote 2'!R7 -> #DIV/0! | L6: ='Lote 2'!Z7 -> #DIV/0! | M6: ='Lote 3'!H7 -> #DIV/0! | N6: ='%Ganancia'!Y37 -> #DIV/0! | O6: ='Lote 3'!M7 -> #DIV/0! | P6: ='Lote 3'!R7 -> #DIV/0! | Q6: ='Lote 3'!Z7 -> #DIV/0!
A7: 4 | B7: 80 | C7: ='Lote 1'!H8 -> #DIV/0! | D7: ='%Ganancia'!Y8 -> #DIV/0! | E7: ='Lote 1'!M8 -> #DIV/0! | F7: ='Lote 1'!R8 -> #DIV/0! | G7: ='Lote 1'!Z8 -> #DIV/0! | H7: ='Lote 2'!H8 -> #DIV/0! | I7: ='%Ganancia'!Y23 -> #DIV/0! | J7: ='Lote 2'!M8 -> #DIV/0! | K7: ='Lote 2'!R8 -> #DIV/0! | L7: ='Lote 2'!Z8 -> #DIV/0! | M7: ='Lote 3'!H8 -> #DIV/0! | N7: ='%Ganancia'!Y38 -> #DIV/0! | O7: ='Lote 3'!M8 -> #DIV/0! | P7: ='Lote 3'!R8 -> #DIV/0! | Q7: ='Lote 3'!Z8 -> #DIV/0!
A8: 5 | B8: 100 | C8: ='Lote 1'!H9 -> #DIV/0! | D8: ='%Ganancia'!Y9 -> #DIV/0! | E8: ='Lote 1'!M9 -> #DIV/0! | F8: ='Lote 1'!R9 -> #DIV/0! | G8: ='Lote 1'!Z9 -> #DIV/0! | H8: ='Lote 2'!H9 -> #DIV/0! | I8: ='%Ganancia'!Y24 -> #DIV/0! | J8: ='Lote 2'!M9 -> #DIV/0! | K8: ='Lote 2'!R9 -> #DIV/0! | L8: ='Lote 2'!Z9 -> #DIV/0! | M8: ='Lote 3'!H9 -> #DIV/0! | N8: ='%Ganancia'!Y39 -> #DIV/0! | O8: ='Lote 3'!M9 -> #DIV/0! | P8: ='Lote 3'!R9 -> #DIV/0! | Q8: ='Lote 3'!Z9 -> #DIV/0!
A9: 6 | B9: 120 | C9: ='Lote 1'!H10 -> #DIV/0! | D9: ='%Ganancia'!Y10 -> #DIV/0! | E9: ='Lote 1'!M10 -> #DIV/0! | F9: ='Lote 1'!R10 -> #DIV/0! | G9: ='Lote 1'!Z10 -> #DIV/0! | H9: ='Lote 2'!H10 -> #DIV/0! | I9: ='%Ganancia'!Y25 -> #DIV/0! | J9: ='Lote 2'!M10 -> #DIV/0! | K9: ='Lote 2'!R10 -> #DIV/0! | L9: ='Lote 2'!Z10 -> #DIV/0! | M9: ='Lote 3'!H10 -> #DIV/0! | N9: ='%Ganancia'!Y40 -> #DIV/0! | O9: ='Lote 3'!M10 -> #DIV/0! | P9: ='Lote 3'!R10 -> #DIV/0! | Q9: ='Lote 3'!Z10 -> #DIV/0!
A10: 7 | B10: 140 | C10: ='Lote 1'!H11 -> #DIV/0! | D10: ='%Ganancia'!Y11 -> #DIV/0! | E10: ='Lote 1'!M11 -> #DIV/0! | F10: ='Lote 1'!R11 -> #DIV/0! | G10: ='Lote 1'!Z11 -> #DIV/0! | H10: ='Lote 2'!H11 -> #DIV/0! | I10: ='%Ganancia'!Y26 -> #DIV/0! | J10: ='Lote 2'!M11 -> #DIV/0! | K10: ='Lote 2'!R11 -> #DIV/0! | L10: ='Lote 2'!Z11 -> #DIV/0! | M10: ='Lote 3'!H11 -> #DIV/0! | N10: ='%Ganancia'!Y41 -> #DIV/0! | O10: ='Lote 3'!M11 -> #DIV/0! | P10: ='Lote 3'!R11 -> #DIV/0! | Q10: ='Lote 3'!Z11 -> #DIV/0!
A11: 8 | B11: 160 | C11: ='Lote 1'!H12 -> #DIV/0! | D11: ='%Ganancia'!Y12 -> #DIV/0! | E11: ='Lote 1'!M12 -> #DIV/0! | F11: ='Lote 1'!R12 -> #DIV/0! | G11: ='Lote 1'!Z12 -> #DIV/0! | H11: ='Lote 2'!H12 -> #DIV/0! | I11: ='%Ganancia'!Y27 -> #DIV/0! | J11: ='Lote 2'!M12 -> #DIV/0! | K11: ='Lote 2'!R12 -> #DIV/0! | L11: ='Lote 2'!Z12 -> #DIV/0! | M11: ='Lote 3'!H12 -> #DIV/0! | N11: ='%Ganancia'!Y42 -> #DIV/0! | O11: ='Lote 3'!M12 -> #DIV/0! | P11: ='Lote 3'!R12 -> #DIV/0! | Q11: ='Lote 3'!Z12 -> #DIV/0!
A12: 9 | B12: 180 | C12: ='Lote 1'!H13 -> #DIV/0! | D12: ='%Ganancia'!Y13 -> #DIV/0! | E12: ='Lote 1'!M13 -> #DIV/0! | F12: ='Lote 1'!R13 -> #DIV/0! | G12: ='Lote 1'!Z13 -> #DIV/0! | H12: ='Lote 2'!H13 -> #DIV/0! | I12: ='%Ganancia'!Y28 -> #DIV/0! | J12: ='Lote 2'!M13 -> #DIV/0! | K12: ='Lote 2'!R13 -> #DIV/0! | L12: ='Lote 2'!Z13 -> #DIV/0! | M12: ='Lote 3'!H13 -> #DIV/0! | N12: ='%Ganancia'!Y43 -> #DIV/0! | O12: ='Lote 3'!M13 -> #DIV/0! | P12: ='Lote 3'!R13 -> #DIV/0! | Q12: ='Lote 3'!Z13 -> #DIV/0!
A13: Final | B13: 200 | C13: ='Lote 1'!H14 -> 1303 | D13: ='%Ganancia'!Y14 -> 0.1799426 | E13: ='Lote 1'!M14 -> 0.9361 | F13: ='Lote 1'!R14 -> 0.0501 | G13: ='Lote 1'!Z14 -> 0.9782089 | H13: ='Lote 2'!H14 -> 1304 | I13: ='%Ganancia'!Y29 -> 0.17851498 | J13: ='Lote 2'!M14 -> 0.9892 | K13: ='Lote 2'!R14 -> 0.0508 | L13: ='Lote 2'!Z14 -> 0.96698906 | M13: ='Lote 3'!H14 -> 1310 | N13: ='%Ganancia'!Y44 -> 0.17347092 | O13: ='Lote 3'!M14 -> 0.9892 | P13: ='Lote 3'!R14 -> 0.0505 | Q13: ='Lote 3'!Z14 -> 0.97955882
K15: r_s [g/mm3] | M15: 0.000559 | P15: r_p [g/mm3] | R15: =G13 -> 0.9782089
P16: r_d [g/mm3] | R16: 0.9023
M17: 1 | R17: 1
K18: Do [mm] | M18: 0.932 | P18: Do [mm] | R18: 0.932
K19: e [mm] | M19: 0.0533 | P19: e [mm] | R19: 0.0533
K21: mc_teo [g] | M21: =((PI()/6)*((3*(M18^2)*M19)+(3*M18*(M19^2))+(M19^3)))*M15 -> 4.3022031e-05 | P21: mc_teo [g] | R21: =(PI()/6)*(R15-R16)*((3*(R18^2)*R19)+(3*R18*(R19^2))+(R19^3)) -> 0.0058421378
K22: mc_exp [g] | M22: ='%Ganancia'!Q14-'%Ganancia'!M46 -> 0.00011702315 | P22: mc_exp [g] | R22: =M22 -> 0.00011702315
K23: %ERROR | M23: =ABS(M21-M22)/M22 -> 0.63236308 | P23: %ERROR | R23: =ABS(R21-R22)/R21 -> 0.97996912
Q25: r | R25: =R15-R16 -> 0.075908899
Q26: V | R26: =((3*(R18^2)*R19)+(3*R18*(R19^2))+(R19^3))*(PI()/6) -> 0.076962488

Sheet Analisis Cp
A1: Lote | B1: Medición | G1: m | H1: Max | I1: Min | J1: Rango
B2: 1 | C2: 2 | D2: 3 | E2: 4 | F2: 5
A3: 1 | B3: ='Lote 1'!C14 -> 1308 | C3: ='Lote 1'!D14 -> 1312 | D3: ='Lote 1'!E14 -> 1303 | E3: ='Lote 1'!F14 -> 1296 | F3: ='Lote 1'!G14 -> 1297 | G3: =ROUNDDOWN(AVERAGE(B3:F3),0) -> 1303 | H3: =MAX(B3:F3) -> 1312 | I3: =MIN(B3:F3) -> 1296 | J3: =H3-I3 -> 16
A4: 2 | B4: ='Lote 2'!C14 -> 1306 | C4: ='Lote 2'!D14 -> 1301 | D4: ='Lote 2'!E14 -> 1306 | E4: ='Lote 2'!F14 -> 1293 | F4: ='Lote 2'!G14 -> 1318 | G4: =ROUNDDOWN(AVERAGE(B4:F4),0) -> 1304 | H4: =MAX(B4:F4) -> 1318 | I4: =MIN(B4:F4) -> 1293 | J4: =H4-I4 -> 25
A5: 3 | B5: ='Lote 3'!C14 -> 1304 | C5: ='Lote 3'!D14 -> 1307 | D5: ='Lote 3'!E14 -> 1325 | E5: ='Lote 3'!F14 -> 1309 | F5: ='Lote 3'!G14 -> 1307 | G5: =ROUNDDOWN(AVERAGE(B5:F5),0) -> 1310 | H5: =MAX(B5:F5) -> 1325 | I5: =MIN(B5:F5) -> 1304 | J5: =H5-I5 -> 21
F7: Media de medias | G7: =ROUNDDOWN(AVERAGE(G3:G5),0) -> 1305 | I7: Rango promedio | J7: =ROUNDDOWN(AVERAGE(J3:J5),0) -> 20
A9: ES | B9: =ROUNDDOWN(B10*1.03,0) -> 1344 | E9: Cpi | F9: =(G7-B11)/(3*B14) -> 1.5506667
A10: Nomilanl | B10: 1305 | E10: Cps | F10: =(B9-G7)/(3*B14) -> 1.5119
A11: EI | B11: =ROUNDDOWN(B10*0.97,0) -> 1265 | E11: Cpk | F11: =MIN(F9:F10) -> 1.5119
A13: d2 | B13: 2.326 | E13: Ppi | F13: =(G7-B11)/(3*B15) -> 1.6239704
A14: Desv. Corto | B14: =J7/B13 -> 8.5984523 | E14: Pps | F14: =(B9-G7)/(3*B15) -> 1.5833711
A15: Desv. Largo | B15: =_xlfn.STDEV.S(B3:F5) -> 8.2103303 | E15: Ppk | F15: =MIN(F13:F14) -> 1.5833711
A17: Cp | B17: =(B9-B11)/(6*B14) -> 1.5312833
A18: Pp | B18: =(B9-B11)/(6*B15) -> 1.6036708

Sheet Balance de masa
A1: Humedad
D3: 1 | E3: 2 | F3: 3 | G3: 4 | H3: Promedio
A4: Lote 1 | B4: Núcleos de azúcar | D4: 0.005 | E4: 0.002 | F4: 0.004 | G4: 0.004 | H4: =AVERAGE(D4:G4) -> 0.00375
B5: Pellets recubiertos | D5: 0.006 | E5: 0.003 | F5: 0.0038 | G5: 0.002 | H5: =AVERAGE(D5:G5) -> 0.0037
B6: 1 día después | D6: 0.0039 | E6: 0.004 | F6: 0.002 | G6: 0.005 | H6: =AVERAGE(D6:G6) -> 0.003725
A7: Lote 2 | B7: Núcleos de azúcar | D7: 0.0049 | E7: 0.003 | F7: 0.003 | G7: 0.004 | H7: =AVERAGE(D7:G7) -> 0.003725
B8: Pellets recubiertos | D8: 0 | E8: 0.0049 | F8: 0.005 | G8: 0.0046 | H8: =AVERAGE(D8:G8) -> 0.003625
B9: 1 día después | D9: 0.004 | E9: 0.0056 | F9: 0.004 | G9: 0.001 | H9: =AVERAGE(D9:G9) -> 0.00365
A10: Lote 3 | B10: Núcleos de azúcar | D10: 0.003 | E10: 0.005 | F10: 0.004 | G10: 0.002 | H10: =AVERAGE(D10:G10) -> 0.0035
B11: Pellets recubiertos | H11: =AVERAGE(D11:G11) -> #DIV/0!
B12: 1 día después | H12: =AVERAGE(D12:G12) -> #DIV/0!
A15: Balance de masa
C16: Lote 1 | D16: Lote 2 | E16: Lote 3
B17: N [g] | C17: 1600 | D17: 1600 | E17: 1600
B18: S [g] | C18: 320 | D18: 320 | E18: 320
B19: A [g] | C19: 1242 | D19: 1242 | E19: 1242
B20: P_Conformes [g] | C20: 1729 | D20: 1705 | E20: 1733
B21: P_No Conformes [g] | C21: 0.0373 | D21: 0.862 | E21: 0.2949
B22: Cr [g] | C22: 1 | D22: 1 | E22: 3
B23: M [g] | C23: 98.8208 | D23: 88.6263 | E23: 88.9986
B24: Merma [g] | C24: 92.1419 | D24: 124.512 | E24: 94.7065
B25: %No conformes | C25: 1e-05 | D25: 0.0002 | E25: 0.0001
B26: %Merma | C26: 0.0227 | D26: 0.0307 | E26: 0.0233
B27: ACPM consumido [gal] | C27: 3.6 | D27: 3.933 | E27: 4.0662 | F27: =AVERAGE(C27:E27) -> 3.8664
F28: =F27*10.15 -> 39.24396
F29: =F28/180 -> 0.218022

Sheet Espesor
B2: Tiempo [min] | C2: Lote 1 | D2: Lote 2 | E2: Lote 3
B3: 0 | C3: #VALUE! | D3: #VALUE! | E3: #VALUE!
B4: 20
B5: 40
B6: 60
B7: 80
B8: 100
B9: 120
B10: 140
B11: 160
B12: 180
B13: 200 | C13: #VALUE! | D13: #VALUE! | E13: #VALUE!

Sheet Parámetros proc.
B1: Lote 1 | F1: Lote 2 | J1: Lote 3
A2: Tiempo [min] | B2: P atomiz [bar ] | C2: P. aire comp [bar] | D2: T. producto [°C ] | E2: Velocidad Aire [m/s ] | F2: P atomiz [bar ] | G2: P. aire comp [bar] | H2: T. producto [°C ] | I2: Velocidad Aire [m/s ] | J2: P atomiz [bar ] | K2: P. aire comp [bar] | L2: T. producto [°C ] | M2: Velocidad Aire [m/s ]
A3: 1 | B3: 0 | C3: 6.3 | D3: 17.4 | E3: 0.5 | F3: 3.5 | G3: 6 | H3: 50.7 | I3: 7.7 | J3: 3 | K3: 6.5 | L3: 24.5 | M3: 2.7
A4: 2 | B4: 0 | C4: 6.3 | D4: 17.4 | E4: 0.5 | F4: 3.5 | G4: 5.9 | H4: 51.4 | I4: 7.6 | J4: 3.5 | K4: 6.4 | L4: 41.5 | M4: 5.7
A5: 3 | B5: 0 | C5: 6.2 | D5: 17.8 | E5: 0.5 | F5: 3.5 | G5: 6.4 | H5: 52.2 | I5: 8 | J5: 3.5 | K5: 6.3 | L5: 49.4 | M5: 7
A6: 4 | B6: 3.3 | C6: 6 | D6: 23.8 | E6: 3.2 | F6: 3.4 | G6: 7 | H6: 52.7 | I6: 7.8 | J6: 3.5 | K6: 6 | L6: 52 | M6: 7.4
A7: 5 | B7: 3.5 | C7: 5.9 | D7: 43.2 | E7: 6.2 | F7: 3.4 | G7: 6.8 | H7: 53.3 | I7: 7.6 | J7: 3.5 | K7: 6.1 | L7: 52.9 | M7: 7.6
A8: 6 | B8: 3.5 | C8: 6.9 | D8: 50.7 | E8: 7.4 | F8: 3.5 | G8: 6.3 | H8: 53.6 | I8: 7.7 | J8: 3.4 | K8: 6.9 | L8: 53.7 | M8: 7.6
A9: 7 | B9: 3.5 | C9: 7 | D9: 53 | E9: 8.1 | F9: 3.5 | G9: 5.9 | H9: 53.9 | I9: 7.9 | J9: 3.5 | K9: 6.4 | L9: 54 | M9: 8.2
A10: 8 | B10: 3.5 | C10: 6.8 | D10: 53.8 | E10: 8.2 | F10: 3.5 | G10: 6 | H10: 53.6 | I10: 7.9 | J10: 3.5 | K10: 6 | L10: 52.7 | M10: 7.4
A11: 9 | B11: 3.5 | C11: 6.5 | D11: 54.3 | E11: 8.3 | F11: 3.4 | G11: 6.9 | H11: 53 | I11: 7.9 | J11: 3.5 | K11: 6.1 | L11: 52.5 | M11: 7.8
A12: 10 | B12: 3.5 | C12: 6.1 | D12: 54.2 | E12: 8.3 | F12: 3.5 | G12: 6.4 | H12: 53.3 | I12: 7.8 | J12: 3.4 | K12: 6.8 | L12: 52.8 | M12: 7.7
A13: 11 | B13: 3.5 | C13: 5.8 | D13: 54.1 | E13: 8.3 | F13: 3.5 | G13: 6 | H13: 53.7 | I13: 8 | J13: 3.4 | K13: 6.4 | L13: 53 | M13: 7.5
A14: 12 | B14: 3.5 | C14: 6.9 | D14: 54.1 | E14: 8.4 | F14: 3.5 | G14: 6 | H14: 53.1 | I14: 7.4 | J14: 3.5 | K14: 6 | L14: 53.2 | M14: 7.5
... A187: 185 | B187: 3.4 | C187: 5.9 | D187: 57 | E187: 7.2 | F187: 2.6 | G187: 5.9 | H187: 56.9 | I187: 7.3 | J187: 3.4 | K187: 6.8 | L187: 57.3 | M187: 8.5
A188: 186 | B188: 3.4 | C188: 6.6 | D188: 57 | E188: 7.7 | J188: 1 | K188: 6.3 | L188: 57.3 | M188: 7.7
A189: 187 | B189: 0.1 | C189: 6.7 | D189: 57.2 | E189: 4
