Workbook

Sheet Lote 1
A2: Muestra | B2: Tiempo [min] | C2: Pellets/g | H2: m | I2: s | J2: Diametro [mm] Microscopio | M2: m | N2: s | O2: Espesor [mm] Microscopio | R2: m | S2: s | T2: Densidad 00 [g/ml] | Y2: Densidad 0 [g/ml] | AD2: m | AE2: s
C3: 1 | D3: 2 | E3: 3 | F3: 4 | G3: 5 | J3: 1 | K3: 2 | L3: 3 | O3: 1 | P3: 2 | Q3: 3 | T3: 1 | U3: 2 | V3: 3 | W3: 4 | X3: 5 | Y3: 1 | Z3: 2 | AA3: 3 | AB3: 4 | AC3: 5
A4: 0 | B4: 0 | C4: 1540 | D4: 1532 | E4: 1539 | F4: 1535 | G4: 1542 | H4: =ROUNDDOWN(AVERAGE(C4:G4),0) -> 1537 | I4: =_xlfn.STDEV.S(C4:G4) -> 4.0373258 | K4: 0.9117 | M4: =AVERAGE(J4:L4) -> 0.9117 | N4: =_xlfn.STDEV.S(J4:L4) -> #DIV/0! | O4: 0 | P4: 0 | Q4: 0 | R4: =AVERAGE(O4:Q4) -> 0 | S4: =_xlfn.STDEV.S(O4:Q4) -> 0 | T4: 0.9253 | U4: 0.9143 | V4: 0.9165 | W4: 0.911 | X4: 0.9231 | Y4: 0.8853 | Z4: 0.8853 | AA4: 0.8779 | AB4: 0.8779 | AC4: 0.8824 | AD4: =AVERAGE(T4:AC4) -> 0.8999 | AE4: =_xlfn.STDEV.S(T4:AC4) -> 0.019692356
A5: 1 | B5: 20 | C5: 1470 | D5: 1512 | E5: 1462 | F5: 1521 | G5: 1502 | H5: =ROUNDDOWN(AVERAGE(C5:G5),0) -> 1493 | I5: =_xlfn.STDEV.S(C5:G5) -> 26.053791 | K5: 1.0175 | M5: =AVERAGE(J5:L5) -> 1.0175 | N5: =_xlfn.STDEV.S(J5:L5) -> #DIV/0! | P5: 0.0067 | R5: =AVERAGE(O5:Q5) -> 0.0067 | S5: =_xlfn.STDEV.S(O5:Q5) -> #DIV/0! | T5: 0.9021978 | U5: 0.89120879 | V5: 0.90879121 | W5: 0.91538462 | X5: 0.90549451 | Y5: 0.89705882 | Z5: 0.90588235 | AA5: 0.89705882 | AB5: 0.89264706 | AC5: 0.89705882 | AD5: =AVERAGE(T5:AC5) -> 0.90127828 | AE5: =_xlfn.STDEV.S(T5:AC5) -> 0.0076343987
A6: 2 | B6: 40 | C6: 1444 | D6: 1451 | E6: 1425 | F6: 1447 | G6: 1547 | H6: =ROUNDDOWN(AVERAGE(C6:G6),0) -> 1462 | I6: =_xlfn.STDEV.S(C6:G6) -> 48.116525 | K6: 1.0222 | M6: =AVERAGE(J6:L6) -> 1.0222 | N6: =_xlfn.STDEV.S(J6:L6) -> #DIV/0! | P6: 0.0111 | R6: =AVERAGE(O6:Q6) -> 0.0111 | S6: =_xlfn.STDEV.S(O6:Q6) -> #DIV/0! | T6: 0.94175824 | U6: 0.93076923 | V6: 0.95054945 | W6: 0.93406593 | X6: 0.94175824 | Y6: 0.89852941 | Z6: 0.91176471 | AA6: 0.91323529 | AB6: 0.91764706 | AC6: 0.90294118 | AD6: =AVERAGE(T6:AC6) -> 0.92430187 | AE6: =_xlfn.STDEV.S(T6:AC6) -> 0.017888494
A7: 3 | B7: 60 | C7: 1444 | D7: 1447 | E7: 1405 | F7: 1437 | G7: 1427 | H7: =ROUNDDOWN(AVERAGE(C7:G7),0) -> 1432 | I7: =_xlfn.STDEV.S(C7:G7) -> 16.941074 | K7: 1.0159 | M7: =AVERAGE(J7:L7) -> 1.0159 | N7: =_xlfn.STDEV.S(J7:L7) -> #DIV/0! | P7: 0.0143 | R7: =AVERAGE(O7:Q7) -> 0.0143 | S7: =_xlfn.STDEV.S(O7:Q7) -> #DIV/0! | T7: 0.93626374 | U7: 0.95604396 | V7: 0.93296703 | W7: 0.96813187 | X7: 0.94065934 | Y7: 0.92205882 | Z7: 0.92352941 | AA7: 0.92352941 | AB7: 0.91764706 | AC7: 0.92058824 | AD7: =AVERAGE(T7:AC7) -> 0.93414189 | AE7: =_xlfn.STDEV.S(T7:AC7) -> 0.01670133
A8: 4 | B8: 80 | C8: 1398 | D8: 1401 | E8: 1428 | F8: 1408 | G8: 1416 | H8: =ROUNDDOWN(AVERAGE(C8:G8),0) -> 1410 | I8: =_xlfn.STDEV.S(C8:G8) -> 12.132601 | K8: 1.057 | M8: =AVERAGE(J8:L8) -> 1.057 | N8: =_xlfn.STDEV.S(J8:L8) -> #DIV/0! | P8: 0.0206 | R8: =AVERAGE(O8:Q8) -> 0.0206 | S8: =_xlfn.STDEV.S(O8:Q8) -> #DIV/0! | T8: 0.94395604 | U8: 0.95274725 | V8: 0.95934066 | W8: 0.94725275 | X8: 0.95604396 | Y8: 0.91617647 | Z8: 0.925 | AA8: 0.93529412 | AB8: 0.93088235 | AC8: 0.93970588 | AD8: =AVERAGE(T8:AC8) -> 0.94063995 | AE8: =_xlfn.STDEV.S(T8:AC8) -> 0.01396839
A9: 5 | B9: 100 | C9: 1409 | D9: 1400 | E9: 1407 | F9: 1401 | G9: 1413 | H9: =ROUNDDOWN(AVERAGE(C9:G9),0) -> 1406 | I9: =_xlfn.STDEV.S(C9:G9) -> 5.4772256 | K9: 1.1209 | M9: =AVERAGE(J9:L9) -> 1.1209 | N9: =_xlfn.STDEV.S(J9:L9) -> #DIV/0! | P9: 0.0212 | R9: =AVERAGE(O9:Q9) -> 0.0212 | S9: =_xlfn.STDEV.S(O9:Q9) -> #DIV/0! | T9: 0.94725275 | U9: 0.95934066 | V9: 0.96813187 | W9: 0.96923077 | X9: 0.96043956 | Y9: 0.92647059 | Z9: 0.92794118 | AA9: 0.93088235 | AB9: 0.94117647 | AC9: 0.93676471 | AD9: =AVERAGE(T9:AC9) -> 0.94676309 | AE9: =_xlfn.STDEV.S(T9:AC9) -> 0.016520452
A10: 6 | B10: 120 | C10: 1375 | D10: 1394 | E10: 1363 | F10: 1389 | G10: 1383 | H10: =ROUNDDOWN(AVERAGE(C10:G10),0) -> 1380 | I10: =_xlfn.STDEV.S(C10:G10) -> 12.214745 | K10: 1.0381 | M10: =AVERAGE(J10:L10) -> 1.0381 | N10: =_xlfn.STDEV.S(J10:L10) -> #DIV/0! | P10: 0.0286 | R10: =AVERAGE(O10:Q10) -> 0.0286 | S10: =_xlfn.STDEV.S(O10:Q10) -> #DIV/0! | T10: 0.97032967 | U10: 0.95714286 | V10: 0.97802198 | W10: 0.97362637 | X10: 0.96043956 | Y10: 0.94852941 | Z10: 0.94558824 | AA10: 0.95147059 | AB10: 0.94852941 | AC10: 0.95147059 | AD10: =AVERAGE(T10:AC10) -> 0.95851487 | AE10: =_xlfn.STDEV.S(T10:AC10) -> 0.011641982
A11: 7 | B11: 140 | C11: 1357 | D11: 1353 | E11: 1333 | F11: 1353 | G11: 1343 | H11: =ROUNDDOWN(AVERAGE(C11:G11),0) -> 1347 | I11: =_xlfn.STDEV.S(C11:G11) -> 9.7570487 | K11: 1.003 | M11: =AVERAGE(J11:L11) -> 1.003 | N11: =_xlfn.STDEV.S(J11:L11) -> #DIV/0! | P11: 0.0401 | R11: =AVERAGE(O11:Q11) -> 0.0401 | S11: =_xlfn.STDEV.S(O11:Q11) -> #DIV/0! | T11: 0.98021978 | U11: 0.96923077 | V11: 0.96813187 | W11: 0.96923077 | X11: 0.96703297 | Y11: 0.93970588 | Z11: 0.95147059 | AA11: 0.95882353 | AB11: 0.96029412 | AC11: 0.95 | AD11: =AVERAGE(T11:AC11) -> 0.96141403 | AE11: =_xlfn.STDEV.S(T11:AC11) -> 0.011836486
A12: 8 | B12: 160 | C12: 1353 | D12: 1332 | E12: 1263 | F12: 1342 | G12: 1330 | H12: =ROUNDDOWN(AVERAGE(C12:G12),0) -> 1324 | I12: =_xlfn.STDEV.S(C12:G12) -> 35.305807 | K12: 1.0127 | M12: =AVERAGE(J12:L12) -> 1.0127 | N12: =_xlfn.STDEV.S(J12:L12) -> #DIV/0! | P12: 0.0454 | R12: =AVERAGE(O12:Q12) -> 0.0454 | S12: =_xlfn.STDEV.S(O12:Q12) -> #DIV/0! | T12: 0.97252747 | U12: 0.96923077 | V12: 0.97252747 | W12: 0.97802198 | X12: 0.98131868 | Y12: 0.95441176 | Z12: 0.95588235 | AA12: 0.96911765 | AB12: 0.95882353 | AC12: 0.95735294 | AD12: =AVERAGE(T12:AC12) -> 0.96692146 | AE12: =_xlfn.STDEV.S(T12:AC12) -> 0.0096551643
A13: 9 | B13: 180 | C13: 1295 | D13: 1301 | E13: 1287 | F13: 1299 | G13: 1324 | H13: =ROUNDDOWN(AVERAGE(C13:G13),0) -> 1301 | I13: =_xlfn.STDEV.S(C13:G13) -> 13.827509 | K13: 0.9413 | M13: =AVERAGE(J13:L13) -> 0.9413 | N13: =_xlfn.STDEV.S(J13:L13) -> #DIV/0! | P13: 0.0508 | R13: =AVERAGE(O13:Q13) -> 0.0508 | S13: =_xlfn.STDEV.S(O13:Q13) -> #DIV/0! | T13: 0.97802198 | U13: 0.98131868 | V13: 0.99230769 | W13: 0.99340659 | X13: 0.97252747 | Y13: 0.95294118 | Z13: 0.96176471 | AA13: 0.97794118 | AB13: 0.95735294 | AC13: 0.97058824 | AD13: =AVERAGE(T13:AC13) -> 0.97381707 | AE13: =_xlfn.STDEV.S(T13:AC13) -> 0.013665994
A14: Final | B14: 200 | C14: 1283 | D14: 1302 | E14: 1287 | F14: 1294 | G14: 1285 | H14: =ROUNDDOWN(AVERAGE(C14:G14),0) -> 1290 | I14: =_xlfn.STDEV.S(C14:G14) -> 7.7910205 | K14: 0.9964 | M14: =AVERAGE(J14:L14) -> 0.9964 | N14: =_xlfn.STDEV.S(J14:L14) -> #DIV/0! | P14: 0.0533 | R14: =AVERAGE(O14:Q14) -> 0.0533 | S14: =_xlfn.STDEV.S(O14:Q14) -> #DIV/0! | T14: 1.0087912 | U14: 1.0175824 | V14: 1.021978 | W14: 1.0098901 | X14: 1.0285714 | Y14: 0.97352941 | Z14: 0.97352941 | AA14: 0.97647059 | AB14: 0.98088235 | AC14: 0.96911765 | AD14: =AVERAGE(T14:AC14) -> 0.99603426 | AE14: =_xlfn.STDEV.S(T14:AC14) -> 0.023334646

Sheet Lote 2
A2: Muestra | B2: Tiempo [min] | C2: Pellets/g | H2: m | I2: s | J2: Diametro [mm] Microscopio | M2: m | N2: s | O2: Espesor [mm] Microscopio | R2: m | S2: s | T2: Densidad 00 [g/ml] | W2: Densidad 0 [g/ml] | Z2: m | AA2: s
C3: 1 | D3: 2 | E3: 3 | F3: 4 | G3: 5 | J3: 1 | K3: 2 | L3: 3 | O3: 1 | P3: 2 | Q3: 3 | T3: 1 | U3: 2 | V3: 3 | W3: 1 | X3: 2 | Y3: 3
A4: 0 | B4: 0 | C4: 1531 | D4: 1530 | E4: 1548 | F4: 1558 | G4: 1520 | H4: =ROUNDDOWN(AVERAGE(C4:G4),0) -> 1537 | I4: =_xlfn.STDEV.S(C4:G4) -> 15.29052 | K4: 0.9651 | M4: =AVERAGE(J4:L4) -> 0.9651 | N4: =_xlfn.STDEV.S(J4:L4) -> #DIV/0! | O4: 0 | P4: 0 | Q4: 0 | R4: =AVERAGE(O4:Q4) -> 0 | S4: =_xlfn.STDEV.S(O4:Q4) -> 0 | T4: 0.922 | U4: 0.922 | V4: 0.9187 | W4: 0.8676 | X4: 0.8779 | Y4: 0.8721 | Z4: =AVERAGE(T4:Y4) -> 0.89671667 | AA4: =_xlfn.STDEV.S(T4:Y4) -> 0.026719238
A5: 1 | B5: 20 | H5: =ROUNDDOWN(AVERAGE(C5:G5),0) -> #DIV/0! | I5: =_xlfn.STDEV.S(C5:G5) -> #DIV/0! | K5: 1.0698 | M5: =AVERAGE(J5:L5) -> 1.0698 | N5: =_xlfn.STDEV.S(J5:L5) -> #DIV/0! | P5: 0.0063 | R5: =AVERAGE(O5:Q5) -> 0.0063 | S5: =_xlfn.STDEV.S(O5:Q5) -> #DIV/0! | T5: 0.9187 | U5: 0.9253 | V5: 0.9264 | W5: 0.8838 | X5: 0.8824 | Y5: 0.8676 | Z5: =AVERAGE(T5:Y5) -> 0.9007 | AA5: =_xlfn.STDEV.S(T5:Y5) -> 0.025712876
A6: 2 | B6: 40 | H6: =ROUNDDOWN(AVERAGE(C6:G6),0) -> #DIV/0! | I6: =_xlfn.STDEV.S(C6:G6) -> #DIV/0! | K6: 1.0603 | M6: =AVERAGE(J6:L6) -> 1.0603 | N6: =_xlfn.STDEV.S(J6:L6) -> #DIV/0! | P6: 0.0124 | R6: =AVERAGE(O6:Q6) -> 0.0124 | S6: =_xlfn.STDEV.S(O6:Q6) -> #DIV/0! | T6: 0.933 | U6: 0.9374 | V6: 0.9396 | W6: 0.9074 | X6: 0.8985 | Y6: 0.9059 | Z6: =AVERAGE(T6:Y6) -> 0.9203 | AA6: =_xlfn.STDEV.S(T6:Y6) -> 0.018304098
A7: 3 | B7: 60 | H7: =ROUNDDOWN(AVERAGE(C7:G7),0) -> #DIV/0! | I7: =_xlfn.STDEV.S(C7:G7) -> #DIV/0! | K7: 1.0841 | M7: =AVERAGE(J7:L7) -> 1.0841 | N7: =_xlfn.STDEV.S(J7:L7) -> #DIV/0! | P7: 0.0222 | R7: =AVERAGE(O7:Q7) -> 0.0222 | S7: =_xlfn.STDEV.S(O7:Q7) -> #DIV/0! | T7: 0.944 | U7: 0.9484 | V7: 0.9516 | W7: 0.9059 | X7: 0.9088 | Y7: 0.9132 | Z7: =AVERAGE(T7:Y7) -> 0.92865 | AA7: =_xlfn.STDEV.S(T7:Y7) -> 0.021460079
A8: 4 | B8: 80 | H8: =ROUNDDOWN(AVERAGE(C8:G8),0) -> #DIV/0! | I8: =_xlfn.STDEV.S(C8:G8) -> #DIV/0! | K8: 1.0857 | M8: =AVERAGE(J8:L8) -> 1.0857 | N8: =_xlfn.STDEV.S(J8:L8) -> #DIV/0! | P8: 0.0365 | Q8: 0.0317 | R8: =AVERAGE(O8:Q8) -> 0.0341 | S8: =_xlfn.STDEV.S(O8:Q8) -> 0.0033941125 | T8: 0.9582 | U8: 0.9615 | V8: 0.9593 | W8: 0.9221 | X8: 0.9265 | Y8: 0.9162 | Z8: =AVERAGE(T8:Y8) -> 0.94063333 | AA8: =_xlfn.STDEV.S(T8:Y8) -> 0.021131367
A9: 5 | B9: 100 | H9: =ROUNDDOWN(AVERAGE(C9:G9),0) -> #DIV/0! | I9: =_xlfn.STDEV.S(C9:G9) -> #DIV/0! | K9: 1.1571 | M9: =AVERAGE(J9:L9) -> 1.1571 | N9: =_xlfn.STDEV.S(J9:L9) -> #DIV/0! | P9: 0.0413 | R9: =AVERAGE(O9:Q9) -> 0.0413 | S9: =_xlfn.STDEV.S(O9:Q9) -> #DIV/0! | T9: 0.9615 | U9: 0.967 | V9: 0.9648 | W9: 0.9221 | X9: 0.9279 | Y9: 0.9368 | Z9: =AVERAGE(T9:Y9) -> 0.94668333 | AA9: =_xlfn.STDEV.S(T9:Y9) -> 0.020076595
A10: 6 | B10: 120 | H10: =ROUNDDOWN(AVERAGE(C10:G10),0) -> #DIV/0! | I10: =_xlfn.STDEV.S(C10:G10) -> #DIV/0! | K10: 1.1333 | M10: =AVERAGE(J10:L10) -> 1.1333 | N10: =_xlfn.STDEV.S(J10:L10) -> #DIV/0! | P10: 0.0483 | R10: =AVERAGE(O10:Q10) -> 0.0483 | S10: =_xlfn.STDEV.S(O10:Q10) -> #DIV/0! | T10: 0.9659 | U10: 0.9813 | V10: 0.978 | W10: 0.9338 | X10: 0.9441 | Y10: 0.9485 | Z10: =AVERAGE(T10:Y10) -> 0.9586 | AA10: =_xlfn.STDEV.S(T10:Y10) -> 0.019350659
A11: 7 | B11: 140 | H11: =ROUNDDOWN(AVERAGE(C11:G11),0) -> #DIV/0! | I11: =_xlfn.STDEV.S(C11:G11) -> #DIV/0! | K11: 1.1111 | M11: =AVERAGE(J11:L11) -> 1.1111 | N11: =_xlfn.STDEV.S(J11:L11) -> #DIV/0! | P11: 0.0528 | R11: =AVERAGE(O11:Q11) -> 0.0528 | S11: =_xlfn.STDEV.S(O11:Q11) -> #DIV/0! | T11: 0.9736 | U11: 0.989 | V11: 0.9791 | W11: 0.9456 | X11: 0.9441 | Y11: 0.9456 | Z11: =AVERAGE(T11:Y11) -> 0.96283333 | AA11: =_xlfn.STDEV.S(T11:Y11) -> 0.020050603
A12: 8 | B12: 160 | H12: =ROUNDDOWN(AVERAGE(C12:G12),0) -> #DIV/0! | I12: =_xlfn.STDEV.S(C12:G12) -> #DIV/0! | K12: 1.1905 | M12: =AVERAGE(J12:L12) -> 1.1905 | N12: =_xlfn.STDEV.S(J12:L12) -> #DIV/0! | P12: 0.0587 | R12: =AVERAGE(O12:Q12) -> 0.0587 | S12: =_xlfn.STDEV.S(O12:Q12) -> #DIV/0! | T12: 0.9813 | U12: 0.9802 | V12: 0.9868 | W12: 0.9441 | X12: 0.9647 | Y12: 0.9735 | Z12: =AVERAGE(T12:Y12) -> 0.97176667 | AA12: =_xlfn.STDEV.S(T12:Y12) -> 0.015533147
A13: 9 | B13: 180 | H13: =ROUNDDOWN(AVERAGE(C13:G13),0) -> #DIV/0! | I13: =_xlfn.STDEV.S(C13:G13) -> #DIV/0! | K13: 1.1841 | M13: =AVERAGE(J13:L13) -> 1.1841 | N13: =_xlfn.STDEV.S(J13:L13) -> #DIV/0! | P13: 0.0593 | R13: =AVERAGE(O13:Q13) -> 0.0593 | S13: =_xlfn.STDEV.S(O13:Q13) -> #DIV/0! | T13: 0.9989 | U13: 0.989 | V13: 0.9879 | W13: 0.9618 | X13: 0.9632 | Y13: 0.9721 | Z13: =AVERAGE(T13:Y13) -> 0.97881667 | AA13: =_xlfn.STDEV.S(T13:Y13) -> 0.015284687
A14: Final | B14: 200 | C14: 1292 | D14: 1298 | E14: 1284 | F14: 1275 | G14: 1285 | H14: =ROUNDDOWN(AVERAGE(C14:G14),0) -> 1286 | I14: =_xlfn.STDEV.S(C14:G14) -> 8.7005747 | K14: 1.3302 | M14: =AVERAGE(J14:L14) -> 1.3302 | N14: =_xlfn.STDEV.S(J14:L14) -> #DIV/0! | P14: 0.0603 | R14: =AVERAGE(O14:Q14) -> 0.0603 | S14: =_xlfn.STDEV.S(O14:Q14) -> #DIV/0! | T14: 1.0022 | U14: 1.0055 | V14: 1.0165 | W14: 0.9721 | X14: 0.9765 | Y14: 0.9765 | Z14: =AVERAGE(T14:Y14) -> 0.99155 | AA14: =_xlfn.STDEV.S(T14:Y14) -> 0.018771441

Sheet Lote 3
A2: Muestra | B2: Tiempo [min] | C2: Pellets/g | H2: m | I2: s | J2: Diametro [mm] Microscopio | M2: m | N2: s | O2: Espesor [mm] Microscopio | R2: m | S2: s | T2: Densidad 00 [g/ml] | W2: Densidad 0 [g/ml] | Z2: m | AA2: s
C3: 1 | D3: 2 | E3: 3 | F3: 4 | G3: 5 | J3: 1 | K3: 2 | L3: 3 | O3: 1 | P3: 2 | Q3: 3 | T3: 1 | U3: 2 | V3: 3 | W3: 1 | X3: 2 | Y3: 3
A4: 0 | B4: 0 | C4: 1565 | D4: 1558 | E4: 1514 | F4: 1521 | G4: 1530 | H4: =ROUNDDOWN(AVERAGE(C4:G4),0) -> 1537 | I4: =_xlfn.STDEV.S(C4:G4) -> 22.678183 | K4: 1.0665 | M4: =AVERAGE(J4:L4) -> 1.0665 | N4: =_xlfn.STDEV.S(J4:L4) -> #DIV/0! | O4: 0 | P4: 0 | Q4: 0 | R4: =AVERAGE(O4:Q4) -> 0 | S4: =_xlfn.STDEV.S(O4:Q4) -> 0 | T4: 0.9053 | U4: 0.931 | V4: 0.9198 | W4: 0.8509 | X4: 0.8754 | Y4: 0.8866 | Z4: =AVERAGE(T4:Y4) -> 0.89483333 | AA4: =_xlfn.STDEV.S(T4:Y4) -> 0.029720341
A5: 1 | B5: 20 | C5: 1545 | D5: 1521 | E5: 1553 | F5: 1514 | G5: 1506 | H5: =ROUNDDOWN(AVERAGE(C5:G5),0) -> 1527 | I5: =_xlfn.STDEV.S(C5:G5) -> 20.265735 | K5: 1.1159 | M5: =AVERAGE(J5:L5) -> 1.1159 | N5: =_xlfn.STDEV.S(J5:L5) -> #DIV/0! | P5: 0.0063 | R5: =AVERAGE(O5:Q5) -> 0.0063 | S5: =_xlfn.STDEV.S(O5:Q5) -> #DIV/0! | T5: 0.9315 | U5: 0.9215 | V5: 0.9202 | W5: 0.8824 | X5: 0.8929 | Y5: 0.8813 | Z5: =AVERAGE(T5:Y5) -> 0.90496667 | AA5: =_xlfn.STDEV.S(T5:Y5) -> 0.022019961
A6: 2 | B6: 40 | C6: 1498 | D6: 1442 | E6: 1533 | F6: 1535 | G6: 1484 | H6: =ROUNDDOWN(AVERAGE(C6:G6),0) -> 1498 | I6: =_xlfn.STDEV.S(C6:G6) -> 38.48766 | K6: 1.0175 | M6: =AVERAGE(J6:L6) -> 1.0175 | N6: =_xlfn.STDEV.S(J6:L6) -> #DIV/0! | P6: 0.0111 | R6: =AVERAGE(O6:Q6) -> 0.0111 | S6: =_xlfn.STDEV.S(O6:Q6) -> #DIV/0! | T6: 0.9326 | U6: 0.934 | V6: 0.9396 | W6: 0.8971 | X6: 0.8991 | Y6: 0.8896 | Z6: =AVERAGE(T6:Y6) -> 0.91533333 | AA6: =_xlfn.STDEV.S(T6:Y6) -> 0.022332189
A7: 3 | B7: 60 | C7: 1474 | D7: 1526 | E7: 1416 | F7: 1500 | G7: 1480 | H7: =ROUNDDOWN(AVERAGE(C7:G7),0) -> 1479 | I7: =_xlfn.STDEV.S(C7:G7) -> 40.757821 | K7: 1.0476 | M7: =AVERAGE(J7:L7) -> 1.0476 | N7: =_xlfn.STDEV.S(J7:L7) -> #DIV/0! | P7: 0.0159 | R7: =AVERAGE(O7:Q7) -> 0.0159 | S7: =_xlfn.STDEV.S(O7:Q7) -> #DIV/0! | T7: 0.9366 | U7: 0.9389 | V7: 0.9533 | W7: 0.9054 | X7: 0.9065 | Y7: 0.9104 | Z7: =AVERAGE(T7:Y7) -> 0.92518333 | AA7: =_xlfn.STDEV.S(T7:Y7) -> 0.020337297
A8: 4 | B8: 80 | C8: 1417 | D8: 1400 | E8: 1518 | F8: 1464 | G8: 1465 | H8: =ROUNDDOWN(AVERAGE(C8:G8),0) -> 1452 | I8: =_xlfn.STDEV.S(C8:G8) -> 46.354072 | K8: 1.0794 | M8: =AVERAGE(J8:L8) -> 1.0794 | N8: =_xlfn.STDEV.S(J8:L8) -> #DIV/0! | P8: 0.0227 | R8: =AVERAGE(O8:Q8) -> 0.0227 | S8: =_xlfn.STDEV.S(O8:Q8) -> #DIV/0! | T8: 0.9543 | U8: 0.9551 | V8: 0.9455 | W8: 0.9109 | X8: 0.9226 | Y8: 0.9241 | Z8: =AVERAGE(T8:Y8) -> 0.93541667 | AA8: =_xlfn.STDEV.S(T8:Y8) -> 0.01864987
A9: 5 | B9: 100 | C9: 1432 | D9: 1407 | E9: 1414 | F9: 1451 | G9: 1445 | H9: =ROUNDDOWN(AVERAGE(C9:G9),0) -> 1429 | I9: =_xlfn.STDEV.S(C9:G9) -> 19.07092 | K9: 1.1616 | M9: =AVERAGE(J9:L9) -> 1.1616 | N9: =_xlfn.STDEV.S(J9:L9) -> #DIV/0! | P9: 0.0293 | R9: =AVERAGE(O9:Q9) -> 0.0293 | S9: =_xlfn.STDEV.S(O9:Q9) -> #DIV/0! | T9: 0.9541 | U9: 0.958 | V9: 0.964 | W9: 0.9197 | X9: 0.9304 | Y9: 0.9353 | Z9: =AVERAGE(T9:Y9) -> 0.94358333 | AA9: =_xlfn.STDEV.S(T9:Y9) -> 0.01759607
A10: 6 | B10: 120 | C10: 1428 | D10: 1361 | E10: 1428 | F10: 1443 | G10: 1422 | H10: =ROUNDDOWN(AVERAGE(C10:G10),0) -> 1416 | I10: =_xlfn.STDEV.S(C10:G10) -> 31.926478 | K10: 1.1714 | M10: =AVERAGE(J10:L10) -> 1.1714 | N10: =_xlfn.STDEV.S(J10:L10) -> #DIV/0! | P10: 0.0348 | R10: =AVERAGE(O10:Q10) -> 0.0348 | S10: =_xlfn.STDEV.S(O10:Q10) -> #DIV/0! | T10: 0.9845 | U10: 0.9822 | V10: 0.9358 | W10: 0.9337 | X10: 0.9366 | Y10: 0.9441 | Z10: =AVERAGE(T10:Y10) -> 0.95281667 | AA10: =_xlfn.STDEV.S(T10:Y10) -> 0.02392149
A11: 7 | B11: 140 | C11: 1362 | D11: 1328 | E11: 1402 | F11: 1398 | G11: 1399 | H11: =ROUNDDOWN(AVERAGE(C11:G11),0) -> 1377 | I11: =_xlfn.STDEV.S(C11:G11) -> 32.298607 | K11: 1.109 | M11: =AVERAGE(J11:L11) -> 1.109 | N11: =_xlfn.STDEV.S(J11:L11) -> #DIV/0! | P11: 0.0402 | R11: =AVERAGE(O11:Q11) -> 0.0402 | S11: =_xlfn.STDEV.S(O11:Q11) -> #DIV/0! | T11: 0.9745 | U11: 0.9704 | V11: 0.9763 | W11: 0.9435 | X11: 0.9404 | Y11: 0.9607 | Z11: =AVERAGE(T11:Y11) -> 0.96096667 | AA11: =_xlfn.STDEV.S(T11:Y11) -> 0.015718736
A12: 8 | B12: 160 | C12: 1322 | D12: 1292 | E12: 1379 | F12: 1365 | G12: 1343 | H12: =ROUNDDOWN(AVERAGE(C12:G12),0) -> 1340 | I12: =_xlfn.STDEV.S(C12:G12) -> 34.578895 | K12: 1.2317 | M12: =AVERAGE(J12:L12) -> 1.2317 | N12: =_xlfn.STDEV.S(J12:L12) -> #DIV/0! | P12: 0.046 | R12: =AVERAGE(O12:Q12) -> 0.046 | S12: =_xlfn.STDEV.S(O12:Q12) -> #DIV/0! | T12: 0.9836 | U12: 0.9875 | V12: 0.9778 | W12: 0.9466 | X12: 0.9479 | Y12: 0.9735 | Z12: =AVERAGE(T12:Y12) -> 0.96948333 | AA12: =_xlfn.STDEV.S(T12:Y12) -> 0.017881098
A13: 9 | B13: 180 | C13: 1285 | D13: 1221 | E13: 1327 | F13: 1338 | G13: 1363 | H13: =ROUNDDOWN(AVERAGE(C13:G13),0) -> 1306 | I13: =_xlfn.STDEV.S(C13:G13) -> 55.625534 | K13: 1.2466 | M13: =AVERAGE(J13:L13) -> 1.2466 | N13: =_xlfn.STDEV.S(J13:L13) -> #DIV/0! | P13: 0.0528 | R13: =AVERAGE(O13:Q13) -> 0.0528 | S13: =_xlfn.STDEV.S(O13:Q13) -> #DIV/0! | T13: 0.9905 | U13: 0.9812 | V13: 0.9914 | W13: 0.964 | X13: 0.9565 | Y13: 0.9647 | Z13: =AVERAGE(T13:Y13) -> 0.97471667 | AA13: =_xlfn.STDEV.S(T13:Y13) -> 0.014943282
A14: Final | B14: 200 | C14: 1403 | D14: 1402 | E14: 1365 | F14: 1332 | G14: 1318 | H14: =ROUNDDOWN(AVERAGE(C14:G14),0) -> 1364 | I14: =_xlfn.STDEV.S(C14:G14) -> 39.070449 | K14: 1.2587 | M14: =AVERAGE(J14:L14) -> 1.2587 | N14: =_xlfn.STDEV.S(J14:L14) -> #DIV/0! | P14: 0.0553 | R14: =AVERAGE(O14:Q14) -> 0.0553 | S14: =_xlfn.STDEV.S(O14:Q14) -> #DIV/0! | T14: 0.9936 | U14: 0.9953 | V14: 1.018 | W14: 0.9729 | X14: 0.9703 | Y14: 0.9899 | Z14: =AVERAGE(T14:Y14) -> 0.99 | AA14: =_xlfn.STDEV.S(T14:Y14) -> 0.017352579

Sheet %Ganancia
A1: Lote 1
A2: Conteo de pellet/g | K2: Ganancia en peso [g] | S2: % de Ganancia
A3: Muestra | B3: Tiempo | C3: 1 | D3: 2 | E3: 3 | F3: 4 | G3: 5 | H3: m | I3: s | K3: Tiempo | L3: 1 | M3: 2 | N3: 3 | O3: 4 | P3: 5 | Q3: m | S3: Tiempo | T3: 1 | U3: 2 | V3: 3 | W3: 4 | X3: 5 | Y3: m
A4: Desnudo | B4: 0 | C4: ='Lote 1'!C4 -> 1540 | D4: ='Lote 1'!D4 -> 1532 | E4: ='Lote 1'!E4 -> 1539 | F4: ='Lote 1'!F4 -> 1535 | G4: ='Lote 1'!G4 -> 1542 | H4: =ROUND(AVERAGE(C4:G4),0) -> 1538 | I4: =_xlfn.STDEV.S(C4:G4) -> 4.0373258 | K4: 0 | L4: =1/C4 -> 0.00064935065 | M4: =1/D4 -> 0.00065274151 | N4: =1/E4 -> 0.00064977258 | O4: =1/F4 -> 0.0006514658 | P4: =1/G4 -> 0.00064850843 | Q4: =AVERAGE(L4:P4) -> 0.00065036779 | S4: 0 | T4: 0 | U4: 0 | V4: 0 | W4: 0 | X4: 0 | Y4: 0
A5: 1 | B5: 20 | C5: ='Lote 1'!C5 -> 1470 | D5: ='Lote 1'!D5 -> 1512 | E5: ='Lote 1'!E5 -> 1462 | F5: ='Lote 1'!F5 -> 1521 | G5: ='Lote 1'!G5 -> 1502 | H5: =ROUND(AVERAGE(C5:G5),0) -> 1493 | I5: =_xlfn.STDEV.S(C5:G5) -> 26.053791 | K5: 20 | L5: =1/C5 -> 0.00068027211 | M5: =1/D5 -> 0.00066137566 | N5: =1/E5 -> 0.00068399453 | O5: =1/F5 -> 0.0006574622 | P5: =1/G5 -> 0.00066577896 | Q5: =AVERAGE(L5:P5) -> 0.00066977669 | S5: 20 | T5: =(L5-$M$46)/$M$46 -> 0.046031746 | U5: =(M5-$M$46)/$M$46 -> 0.016975309 | V5: =(N5-$M$46)/$M$46 -> 0.051755586 | W5: =(O5-$M$46)/$M$46 -> 0.010957703 | X5: =(P5-$M$46)/$M$46 -> 0.023746116 | Y5: =AVERAGE(T5:X5) -> 0.029893292
A6: 2 | B6: 40 | C6: ='Lote 1'!C6 -> 1444 | D6: ='Lote 1'!D6 -> 1451 | E6: ='Lote 1'!E6 -> 1425 | F6: ='Lote 1'!F6 -> 1447 | G6: ='Lote 1'!G6 -> 1547 | H6: =ROUND(AVERAGE(C6:G6),0) -> 1463 | I6: =_xlfn.STDEV.S(C6:G6) -> 48.116525 | K6: 40 | L6: =1/C6 -> 0.00069252078 | M6: =1/D6 -> 0.00068917988 | N6: =1/E6 -> 0.00070175439 | O6: =1/F6 -> 0.000691085 | P6: =1/G6 -> 0.00064641241 | Q6: =AVERAGE(L6:P6) -> 0.00068419049 | S6: 40 | T6: =(L6-$M$46)/$M$46 -> 0.064866113 | U6: =(M6-$M$46)/$M$46 -> 0.059728923 | V6: =(N6-$M$46)/$M$46 -> 0.079064327 | W6: =(O6-$M$46)/$M$46 -> 0.062658374 | X6: =(P6-$M$46)/$M$46 -> -0.0060331825 | Y6: =AVERAGE(T6:X6) -> 0.052056911
A7: 3 | B7: 60 | C7: ='Lote 1'!C7 -> 1444 | D7: ='Lote 1'!D7 -> 1447 | E7: ='Lote 1'!E7 -> 1405 | F7: ='Lote 1'!F7 -> 1437 | G7: ='Lote 1'!G7 -> 1427 | H7: =ROUND(AVERAGE(C7:G7),0) -> 1432 | I7: =_xlfn.STDEV.S(C7:G7) -> 16.941074 | K7: 60 | L7: =1/C7 -> 0.00069252078 | M7: =1/D7 -> 0.000691085 | N7: =1/E7 -> 0.00071174377 | O7: =1/F7 -> 0.00069589422 | P7: =1/G7 -> 0.00070077085 | Q7: =AVERAGE(L7:P7) -> 0.00069840292 | S7: 60 | T7: =(L7-$M$46)/$M$46 -> 0.064866113 | U7: =(M7-$M$46)/$M$46 -> 0.062658374 | V7: =(N7-$M$46)/$M$46 -> 0.094424674 | W7: =(O7-$M$46)/$M$46 -> 0.070053352 | X7: =(P7-$M$46)/$M$46 -> 0.077551974 | Y7: =AVERAGE(T7:X7) -> 0.073910897
A8: 4 | B8: 80 | C8: ='Lote 1'!C8 -> 1398 | D8: ='Lote 1'!D8 -> 1401 | E8: ='Lote 1'!E8 -> 1428 | F8: ='Lote 1'!F8 -> 1408 | G8: ='Lote 1'!G8 -> 1416 | H8: =ROUND(AVERAGE(C8:G8),0) -> 1410 | I8: =_xlfn.STDEV.S(C8:G8) -> 12.132601 | K8: 80 | L8: =1/C8 -> 0.00071530758 | M8: =1/D8 -> 0.00071377587 | N8: =1/E8 -> 0.00070028011 | O8: =1/F8 -> 0.00071022727 | P8: =1/G8 -> 0.00070621469 | Q8: =AVERAGE(L8:P8) -> 0.00070916111 | S8: 80 | T8: =(L8-$M$46)/$M$46 -> 0.099904626 | U8: =(M8-$M$46)/$M$46 -> 0.097549369 | V8: =(N8-$M$46)/$M$46 -> 0.076797386 | W8: =(O8-$M$46)/$M$46 -> 0.092092803 | X8: =(P8-$M$46)/$M$46 -> 0.085922787 | Y8: =AVERAGE(T8:X8) -> 0.090453394
A9: 5 | B9: 100 | C9: ='Lote 1'!C9 -> 1409 | D9: ='Lote 1'!D9 -> 1400 | E9: ='Lote 1'!E9 -> 1407 | F9: ='Lote 1'!F9 -> 1401 | G9: ='Lote 1'!G9 -> 1413 | H9: =ROUND(AVERAGE(C9:G9),0) -> 1406 | I9: =_xlfn.STDEV.S(C9:G9) -> 5.4772256 | K9: 100 | L9: =1/C9 -> 0.00070972321 | M9: =1/D9 -> 0.00071428571 | N9: =1/E9 -> 0.00071073205 | O9: =1/F9 -> 0.00071377587 | P9: =1/G9 -> 0.00070771408 | Q9: =AVERAGE(L9:P9) -> 0.00071124619 | S9: 100 | T9: =(L9-$M$46)/$M$46 -> 0.091317719 | U9: =(M9-$M$46)/$M$46 -> 0.098333333 | V9: =(N9-$M$46)/$M$46 -> 0.092868988 | W9: =(O9-$M$46)/$M$46 -> 0.097549369 | X9: =(P9-$M$46)/$M$46 -> 0.088228356 | Y9: =AVERAGE(T9:X9) -> 0.093659553
A10: 6 | B10: 120 | C10: ='Lote 1'!C10 -> 1375 | D10: ='Lote 1'!D10 -> 1394 | E10: ='Lote 1'!E10 -> 1363 | F10: ='Lote 1'!F10 -> 1389 | G10: ='Lote 1'!G10 -> 1383 | H10: =ROUND(AVERAGE(C10:G10),0) -> 1381 | I10: =_xlfn.STDEV.S(C10:G10) -> 12.214745 | K10: 120 | L10: =1/C10 -> 0.00072727273 | M10: =1/D10 -> 0.00071736011 | N10: =1/E10 -> 0.00073367572 | O10: =1/F10 -> 0.0007199424 | P10: =1/G10 -> 0.0007230658 | Q10: =AVERAGE(L10:P10) -> 0.00072426335 | S10: 120 | T10: =(L10-$M$46)/$M$46 -> 0.11830303 | U10: =(M10-$M$46)/$M$46 -> 0.10306074 | V10: =(N10-$M$46)/$M$46 -> 0.12814869 | W10: =(O10-$M$46)/$M$46 -> 0.10703144 | X10: =(P10-$M$46)/$M$46 -> 0.11183418 | Y10: =AVERAGE(T10:X10) -> 0.11367561
A11: 7 | B11: 140 | C11: ='Lote 1'!C11 -> 1357 | D11: ='Lote 1'!D11 -> 1353 | E11: ='Lote 1'!E11 -> 1333 | F11: ='Lote 1'!F11 -> 1353 | G11: ='Lote 1'!G11 -> 1343 | H11: =ROUND(AVERAGE(C11:G11),0) -> 1348 | I11: =_xlfn.STDEV.S(C11:G11) -> 9.7570487 | K11: 140 | L11: =1/C11 -> 0.00073691968 | M11: =1/D11 -> 0.0007390983 | N11: =1/E11 -> 0.00075018755 | O11: =1/F11 -> 0.0007390983 | P11: =1/G11 -> 0.00074460164 | Q11: =AVERAGE(L11:P11) -> 0.00074198109 | S11: 140 | T11: =(L11-$M$46)/$M$46 -> 0.13313682 | U11: =(M11-$M$46)/$M$46 -> 0.13648682 | V11: =(N11-$M$46)/$M$46 -> 0.15353838 | W11: =(O11-$M$46)/$M$46 -> 0.13648682 | X11: =(P11-$M$46)/$M$46 -> 0.14494912 | Y11: =AVERAGE(T11:X11) -> 0.14091959
A12: 8 | B12: 160 | C12: ='Lote 1'!C12 -> 1353 | D12: ='Lote 1'!D12 -> 1332 | E12: ='Lote 1'!E12 -> 1263 | F12: ='Lote 1'!F12 -> 1342 | G12: ='Lote 1'!G12 -> 1330 | H12: =ROUND(AVERAGE(C12:G12),0) -> 1324 | I12: =_xlfn.STDEV.S(C12:G12) -> 35.305807 | K12: 160 | L12: =1/C12 -> 0.0007390983 | M12: =1/D12 -> 0.00075075075 | N12: =1/E12 -> 0.00079176564 | O12: =1/F12 -> 0.00074515648 | P12: =1/G12 -> 0.0007518797 | Q12: =AVERAGE(L12:P12) -> 0.00075573017 | S12: 160 | T12: =(L12-$M$46)/$M$46 -> 0.13648682 | U12: =(M12-$M$46)/$M$46 -> 0.1544044 | V12: =(N12-$M$46)/$M$46 -> 0.21747163 | W12: =(O12-$M$46)/$M$46 -> 0.14580229 | X12: =(P12-$M$46)/$M$46 -> 0.15614035 | Y12: =AVERAGE(T12:X12) -> 0.1620611
A13: 9 | B13: 180 | C13: ='Lote 1'!C13 -> 1295 | D13: ='Lote 1'!D13 -> 1301 | E13: ='Lote 1'!E13 -> 1287 | F13: ='Lote 1'!F13 -> 1299 | G13: ='Lote 1'!G13 -> 1324 | H13: =ROUND(AVERAGE(C13:G13),0) -> 1301 | I13: =_xlfn.STDEV.S(C12:G12) -> 35.305807 | K13: 180 | L13: =1/C13 -> 0.00077220077 | M13: =1/D13 -> 0.00076863951 | N13: =1/E13 -> 0.00077700078 | O13: =1/F13 -> 0.00076982294 | P13: =1/G13 -> 0.00075528701 | Q13: =AVERAGE(L13:P13) -> 0.0007685902 | S13: 180 | T13: =(L13-$M$46)/$M$46 -> 0.18738739 | U13: =(M13-$M$46)/$M$46 -> 0.18191135 | V13: =(N13-$M$46)/$M$46 -> 0.19476819 | W13: =(O13-$M$46)/$M$46 -> 0.18373108 | X13: =(P13-$M$46)/$M$46 -> 0.16137966 | Y13: =AVERAGE(T13:X13) -> 0.18183553
A14: Final | B14: 200 | C14: ='Lote 1'!C14 -> 1283 | D14: ='Lote 1'!D14 -> 1302 | E14: ='Lote 1'!E14 -> 1287 | F14: ='Lote 1'!F14 -> 1294 | G14: ='Lote 1'!G14 -> 1285 | H14: =ROUND(AVERAGE(C14:G14),0) -> 1290 | I14: =_xlfn.STDEV.S(C14:G14) -> 7.7910205 | K14: 200 | L14: =1/C14 -> 0.00077942323 | M14: =1/D14 -> 0.00076804916 | N14: =1/E14 -> 0.00077700078 | O14: =1/F14 -> 0.00077279753 | P14: =1/G14 -> 0.00077821012 | Q14: =AVERAGE(L14:P14) -> 0.00077509616 | S14: 200 | T14: =(L14-$M$46)/$M$46 -> 0.19849312 | U14: =(M14-$M$46)/$M$46 -> 0.18100358 | V14: =(N14-$M$46)/$M$46 -> 0.19476819 | W14: =(O14-$M$46)/$M$46 -> 0.188305 | X14: =(P14-$M$46)/$M$46 -> 0.19662776 | Y14: =AVERAGE(T14:X14) -> 0.19183953
A16: Lote 2
A17: Conteo de pellet/g | K17: Ganancia en peso [g] | S17: % de Ganancia
A18: Muestra | B18: Tiempo | C18: 1 | D18: 2 | E18: 3 | F18: 4 | G18: 5 | H18: m | I18: s | K18: Tiempo | L18: 1 | M18: 2 | N18: 3 | O18: 4 | P18: 5 | Q18: m | S18: Tiempo | T18: 1 | U18: 2 | V18: 3 | W18: 4 | X18: 5 | Y18: m
A19: Desnudo | B19: 0 | C19: ='Lote 2'!C4 -> 1531 | D19: ='Lote 2'!D4 -> 1530 | E19: ='Lote 2'!E4 -> 1548 | F19: ='Lote 2'!F4 -> 1558 | G19: ='Lote 2'!G4 -> 1520 | H19: =ROUND(AVERAGE(C19:G19),0) -> 1537 | I19: =_xlfn.STDEV.S(C19:G19) -> 15.29052 | K19: 0 | L19: =1/C19 -> 0.00065316786 | M19: =1/D19 -> 0.00065359477 | N19: =1/E19 -> 0.00064599483 | O19: =1/F19 -> 0.00064184852 | P19: =1/G19 -> 0.00065789474 | Q19: =AVERAGE(L19:P19) -> 0.00065050015 | S19: 0 | T19: 0 | U19: 0 | V19: 0 | W19: 0 | X19: 0 | Y19: 0
A20: 1 | B20: 20 | C20: ='Lote 2'!C5 -> 0 | D20: ='Lote 2'!D5 -> 0 | E20: ='Lote 2'!E5 -> 0 | F20: ='Lote 2'!F5 -> 0 | G20: ='Lote 2'!G5 -> 0 | H20: =ROUND(AVERAGE(C20:G20),0) -> 0 | I20: =_xlfn.STDEV.S(C20:G20) -> 0 | K20: 20 | L20: =1/C20 -> #DIV/0! | M20: =1/D20 -> #DIV/0! | N20: =1/E20 -> #DIV/0! | O20: =1/F20 -> #DIV/0! | P20: =1/G20 -> #DIV/0! | Q20: =AVERAGE(L20:P20) -> #DIV/0! | S20: 20 | T20: =ABS((L20-$M$46)/$M$46) -> #DIV/0! | U20: =ABS((M20-$M$46)/$M$46) -> #DIV/0! | V20: =ABS((N20-$M$46)/$M$46) -> #DIV/0! | W20: =ABS((O20-$M$46)/$M$46) -> #DIV/0! | X20: =ABS((P20-$M$46)/$M$46) -> #DIV/0! | Y20: =AVERAGE(T20:X20) -> #DIV/0!
A21: 2 | B21: 40 | C21: ='Lote 2'!C6 -> 0 | D21: ='Lote 2'!D6 -> 0 | E21: ='Lote 2'!E6 -> 0 | F21: ='Lote 2'!F6 -> 0 | G21: ='Lote 2'!G6 -> 0 | H21: =ROUND(AVERAGE(C21:G21),0) -> 0 | I21: =_xlfn.STDEV.S(C21:G21) -> 0 | K21: 40 | L21: =1/C21 -> #DIV/0! | M21: =1/D21 -> #DIV/0! | N21: =1/E21 -> #DIV/0! | O21: =1/F21 -> #DIV/0! | P21: =1/G21 -> #DIV/0! | Q21: =AVERAGE(L21:P21) -> #DIV/0! | S21: 40 | T21: =ABS((L21-$M$46)/$M$46) -> #DIV/0! | U21: =ABS((M21-$M$46)/$M$46) -> #DIV/0! | V21: =ABS((N21-$M$46)/$M$46) -> #DIV/0! | W21: =ABS((O21-$M$46)/$M$46) -> #DIV/0! | X21: =ABS((P21-$M$46)/$M$46) -> #DIV/0! | Y21: =AVERAGE(T21:X21) -> #DIV/0!
A22: 3 | B22: 60 | C22: ='Lote 2'!C7 -> 0 | D22: ='Lote 2'!D7 -> 0 | E22: ='Lote 2'!E7 -> 0 | F22: ='Lote 2'!F7 -> 0 | G22: ='Lote 2'!G7 -> 0 | H22: =ROUND(AVERAGE(C22:G22),0) -> 0 | I22: =_xlfn.STDEV.S(C22:G22) -> 0 | K22: 60 | L22: =1/C22 -> #DIV/0! | M22: =1/D22 -> #DIV/0! | N22: =1/E22 -> #DIV/0! | O22: =1/F22 -> #DIV/0! | P22: =1/G22 -> #DIV/0! | Q22: =AVERAGE(L22:P22) -> #DIV/0! | S22: 60 | T22: =ABS((L22-$M$46)/$M$46) -> #DIV/0! | U22: =ABS((M22-$M$46)/$M$46) -> #DIV/0! | V22: =ABS((N22-$M$46)/$M$46) -> #DIV/0! | W22: =ABS((O22-$M$46)/$M$46) -> #DIV/0! | X22: =ABS((P22-$M$46)/$M$46) -> #DIV/0! | Y22: =AVERAGE(T22:X22) -> #DIV/0!
A23: 4 | B23: 80 | C23: ='Lote 2'!C8 -> 0 | D23: ='Lote 2'!D8 -> 0 | E23: ='Lote 2'!E8 -> 0 | F23: ='Lote 2'!F8 -> 0 | G23: ='Lote 2'!G8 -> 0 | H23: =ROUND(AVERAGE(C23:G23),0) -> 0 | I23: =_xlfn.STDEV.S(C23:G23) -> 0 | K23: 80 | L23: =1/C23 -> #DIV/0! | M23: =1/D23 -> #DIV/0! | N23: =1/E23 -> #DIV/0! | O23: =1/F23 -> #DIV/0! | P23: =1/G23 -> #DIV/0! | Q23: =AVERAGE(L23:P23) -> #DIV/0! | S23: 80 | T23: =ABS((L23-$M$46)/$M$46) -> #DIV/0! | U23: =ABS((M23-$M$46)/$M$46) -> #DIV/0! | V23: =ABS((N23-$M$46)/$M$46) -> #DIV/0! | W23: =ABS((O23-$M$46)/$M$46) -> #DIV/0! | X23: =ABS((P23-$M$46)/$M$46) -> #DIV/0! | Y23: =AVERAGE(T23:X23) -> #DIV/0!
A24: 5 | B24: 100 | C24: ='Lote 2'!C9 -> 0 | D24: ='Lote 2'!D9 -> 0 | E24: ='Lote 2'!E9 -> 0 | F24: ='Lote 2'!F9 -> 0 | G24: ='Lote 2'!G9 -> 0 | H24: =ROUND(AVERAGE(C24:G24),0) -> 0 | I24: =_xlfn.STDEV.S(C24:G24) -> 0 | K24: 100 | L24: =1/C24 -> #DIV/0! | M24: =1/D24 -> #DIV/0! | N24: =1/E24 -> #DIV/0! | O24: =1/F24 -> #DIV/0! | P24: =1/G24 -> #DIV/0! | Q24: =AVERAGE(L24:P24) -> #DIV/0! | S24: 100 | T24: =ABS((L24-$M$46)/$M$46) -> #DIV/0! | U24: =ABS((M24-$M$46)/$M$46) -> #DIV/0! | V24: =ABS((N24-$M$46)/$M$46) -> #DIV/0! | W24: =ABS((O24-$M$46)/$M$46) -> #DIV/0! | X24: =ABS((P24-$M$46)/$M$46) -> #DIV/0! | Y24: =AVERAGE(T24:X24) -> #DIV/0!
A25: 6 | B25: 120 | C25: ='Lote 2'!C10 -> 0 | D25: ='Lote 2'!D10 -> 0 | E25: ='Lote 2'!E10 -> 0 | F25: ='Lote 2'!F10 -> 0 | G25: ='Lote 2'!G10 -> 0 | H25: =ROUND(AVERAGE(C25:G25),0) -> 0 | I25: =_xlfn.STDEV.S(C25:G25) -> 0 | K25: 120 | L25: =1/C25 -> #DIV/0! | M25: =1/D25 -> #DIV/0! | N25: =1/E25 -> #DIV/0! | O25: =1/F25 -> #DIV/0! | P25: =1/G25 -> #DIV/0! | Q25: =AVERAGE(L25:P25) -> #DIV/0! | S25: 120 | T25: =ABS((L25-$M$46)/$M$46) -> #DIV/0! | U25: =ABS((M25-$M$46)/$M$46) -> #DIV/0! | V25: =ABS((N25-$M$46)/$M$46) -> #DIV/0! | W25: =ABS((O25-$M$46)/$M$46) -> #DIV/0! | X25: =ABS((P25-$M$46)/$M$46) -> #DIV/0! | Y25: =AVERAGE(T25:X25) -> #DIV/0!
A26: 7 | B26: 140 | C26: ='Lote 2'!C11 -> 0 | D26: ='Lote 2'!D11 -> 0 | E26: ='Lote 2'!E11 -> 0 | F26: ='Lote 2'!F11 -> 0 | G26: ='Lote 2'!G11 -> 0 | H26: =ROUND(AVERAGE(C26:G26),0) -> 0 | I26: =_xlfn.STDEV.S(C26:G26) -> 0 | K26: 140 | L26: =1/C26 -> #DIV/0! | M26: =1/D26 -> #DIV/0! | N26: =1/E26 -> #DIV/0! | O26: =1/F26 -> #DIV/0! | P26: =1/G26 -> #DIV/0! | Q26: =AVERAGE(L26:P26) -> #DIV/0! | S26: 140 | T26: =ABS((L26-$M$46)/$M$46) -> #DIV/0! | U26: =ABS((M26-$M$46)/$M$46) -> #DIV/0! | V26: =ABS((N26-$M$46)/$M$46) -> #DIV/0! | W26: =ABS((O26-$M$46)/$M$46) -> #DIV/0! | X26: =ABS((P26-$M$46)/$M$46) -> #DIV/0! | Y26: =AVERAGE(T26:X26) -> #DIV/0!
A27: 8 | B27: 160 | C27: ='Lote 2'!C12 -> 0 | D27: ='Lote 2'!D12 -> 0 | E27: ='Lote 2'!E12 -> 0 | F27: ='Lote 2'!F12 -> 0 | G27: ='Lote 2'!G12 -> 0 | H27: =ROUND(AVERAGE(C27:G27),0) -> 0 | I27: =_xlfn.STDEV.S(C27:G27) -> 0 | K27: 160 | L27: =1/C27 -> #DIV/0! | M27: =1/D27 -> #DIV/0! | N27: =1/E27 -> #DIV/0! | O27: =1/F27 -> #DIV/0! | P27: =1/G27 -> #DIV/0! | Q27: =AVERAGE(L27:P27) -> #DIV/0! | S27: 160 | T27: =ABS((L27-$M$46)/$M$46) -> #DIV/0! | U27: =ABS((M27-$M$46)/$M$46) -> #DIV/0! | V27: =ABS((N27-$M$46)/$M$46) -> #DIV/0! | W27: =ABS((O27-$M$46)/$M$46) -> #DIV/0! | X27: =ABS((P27-$M$46)/$M$46) -> #DIV/0! | Y27: =AVERAGE(T27:X27) -> #DIV/0!
A28: 9 | B28: 180 | C28: ='Lote 2'!C13 -> 0 | D28: ='Lote 2'!D13 -> 0 | E28: ='Lote 2'!E13 -> 0 | F28: ='Lote 2'!F13 -> 0 | G28: ='Lote 2'!G13 -> 0 | H28: =ROUND(AVERAGE(C28:G28),0) -> 0 | I28: =_xlfn.STDEV.S(C28:G28) -> 0 | K28: 180 | L28: =1/C28 -> #DIV/0! | M28: =1/D28 -> #DIV/0! | N28: =1/E28 -> #DIV/0! | O28: =1/F28 -> #DIV/0! | P28: =1/G28 -> #DIV/0! | Q28: =AVERAGE(L28:P28) -> #DIV/0! | S28: 180 | T28: =ABS((L28-$M$46)/$M$46) -> #DIV/0! | U28: =ABS((M28-$M$46)/$M$46) -> #DIV/0! | V28: =ABS((N28-$M$46)/$M$46) -> #DIV/0! | W28: =ABS((O28-$M$46)/$M$46) -> #DIV/0! | X28: =ABS((P28-$M$46)/$M$46) -> #DIV/0! | Y28: =AVERAGE(T28:X28) -> #DIV/0!
A29: Final | B29: 210 | C29: ='Lote 2'!C14 -> 1292 | D29: ='Lote 2'!D14 -> 1298 | E29: ='Lote 2'!E14 -> 1284 | F29: ='Lote 2'!F14 -> 1275 | G29: ='Lote 2'!G14 -> 1285 | H29: =ROUND(AVERAGE(C29:G29),0) -> 1287 | I29: =_xlfn.STDEV.S(C29:G29) -> 8.7005747 | K29: 210 | L29: =1/C29 -> 0.00077399381 | M29: =1/D29 -> 0.00077041602 | N29: =1/E29 -> 0.0007788162 | O29: =1/F29 -> 0.00078431373 | P29: =1/G29 -> 0.00077821012 | Q29: =AVERAGE(L29:P29) -> 0.00077714997 | S29: 210 | T29: =ABS((L29-$M$46)/$M$46) -> 0.19014448 | U29: =ABS((M29-$M$46)/$M$46) -> 0.18464304 | V29: =ABS((N29-$M$46)/$M$46) -> 0.19755971 | W29: =ABS((O29-$M$46)/$M$46) -> 0.20601307 | X29: =ABS((P29-$M$46)/$M$46) -> 0.19662776 | Y29: =AVERAGE(T29:X29) -> 0.19499761
A31: Lote 3
A32: Conteo de pellet/g | K32: Ganancia en peso [g] | S32: % de Ganancia
A33: Muestra | B33: Tiempo | C33: 1 | D33: 2 | E33: 3 | F33: 4 | G33: 5 | H33: m | I33: s | K33: Tiempo | L33: 1 | M33: 2 | N33: 3 | O33: 4 | P33: 5 | Q33: m | S33: Tiempo | T33: 1 | U33: 2 | V33: 3 | W33: 4 | X33: 5 | Y33: m
A34: Desnudo | B34: 0 | C34: ='Lote 3'!C4 -> 1565 | D34: ='Lote 3'!D4 -> 1558 | E34: ='Lote 3'!E4 -> 1514 | F34: ='Lote 3'!F4 -> 1521 | G34: ='Lote 3'!G4 -> 1530 | H34: =ROUND(AVERAGE(C34:G34),0) -> 1538 | I34: =_xlfn.STDEV.S(C34:G34) -> 22.678183 | K34: 0 | L34: =1/C34 -> 0.00063897764 | M34: =1/D34 -> 0.00064184852 | N34: =1/E34 -> 0.00066050198 | O34: =1/F34 -> 0.0006574622 | P34: =1/G34 -> 0.00065359477 | Q34: =AVERAGE(L34:P34) -> 0.00065047702 | S34: 0 | T34: 0 | U34: 0 | V34: 0 | W34: 0 | X34: 0 | Y34: 0
A35: 1 | B35: 20 | C35: ='Lote 3'!C5 -> 1545 | D35: ='Lote 3'!D5 -> 1521 | E35: ='Lote 3'!E5 -> 1553 | F35: ='Lote 3'!F5 -> 1514 | G35: ='Lote 3'!G5 -> 1506 | H35: =ROUND(AVERAGE(C35:G35),0) -> 1528 | I35: =_xlfn.STDEV.S(C35:G35) -> 20.265735 | K35: 20 | L35: =1/C35 -> 0.00064724919 | M35: =1/D35 -> 0.0006574622 | N35: =1/E35 -> 0.000643915 | O35: =1/F35 -> 0.00066050198 | P35: =1/G35 -> 0.00066401062 | Q35: =AVERAGE(L35:P35) -> 0.0006546278 | S35: 20 | T35: =(L35-$M$46)/$M$46 -> -0.0047464941 | U35: =(M35-$M$46)/$M$46 -> 0.010957703 | V35: =(N35-$M$46)/$M$46 -> -0.0098733634 | W35: =(O35-$M$46)/$M$46 -> 0.01563188 | X35: =(P35-$M$46)/$M$46 -> 0.021027003 | Y35: =AVERAGE(T35:X35) -> 0.0065993458
A36: 2 | B36: 40 | C36: ='Lote 3'!C6 -> 1498 | D36: ='Lote 3'!D6 -> 1442 | E36: ='Lote 3'!E6 -> 1533 | F36: ='Lote 3'!F6 -> 1535 | G36: ='Lote 3'!G6 -> 1484 | H36: =ROUND(AVERAGE(C36:G36),0) -> 1498 | I36: =_xlfn.STDEV.S(C36:G36) -> 38.48766 | K36: 40 | L36: =1/C36 -> 0.00066755674 | M36: =1/D36 -> 0.00069348128 | N36: =1/E36 -> 0.00065231572 | O36: =1/F36 -> 0.0006514658 | P36: =1/G36 -> 0.00067385445 | Q36: =AVERAGE(L36:P36) -> 0.0006677348 | S36: 40 | T36: =(L36-$M$46)/$M$46 -> 0.026479751 | U36: =(M36-$M$46)/$M$46 -> 0.066343042 | V36: =(N36-$M$46)/$M$46 -> 0.00304414 | W36: =(O36-$M$46)/$M$46 -> 0.0017372421 | X36: =(P36-$M$46)/$M$46 -> 0.036163522 | Y36: =AVERAGE(T36:X36) -> 0.026753539
A37: 3 | B37: 60 | C37: ='Lote 3'!C7 -> 1474 | D37: ='Lote 3'!D7 -> 1526 | E37: ='Lote 3'!E7 -> 1416 | F37: ='Lote 3'!F7 -> 1500 | G37: ='Lote 3'!G7 -> 1480 | H37: =ROUND(AVERAGE(C37:G37),0) -> 1479 | I37: =_xlfn.STDEV.S(C37:G37) -> 40.757821 | K37: 60 | L37: =1/C37 -> 0.00067842605 | M37: =1/D37 -> 0.00065530799 | N37: =1/E37 -> 0.00070621469 | O37: =1/F37 -> 0.00066666667 | P37: =1/G37 -> 0.00067567568 | Q37: =AVERAGE(L37:P37) -> 0.00067645822 | S37: 60 | T37: =(L37-$M$46)/$M$46 -> 0.043193125 | U37: =(M37-$M$46)/$M$46 -> 0.0076452599 | V37: =(N37-$M$46)/$M$46 -> 0.085922787 | W37: =(O37-$M$46)/$M$46 -> 0.025111111 | X37: =(P37-$M$46)/$M$46 -> 0.038963964 | Y37: =AVERAGE(T37:X37) -> 0.040167249
A38: 4 | B38: 80 | C38: ='Lote 3'!C8 -> 1417 | D38: ='Lote 3'!D8 -> 1400 | E38: ='Lote 3'!E8 -> 1518 | F38: ='Lote 3'!F8 -> 1464 | G38: ='Lote 3'!G8 -> 1465 | H38: =ROUND(AVERAGE(C38:G38),0) -> 1453 | I38: =_xlfn.STDEV.S(C38:G38) -> 46.354072 | K38: 80 | L38: =1/C38 -> 0.0007057163 | M38: =1/D38 -> 0.00071428571 | N38: =1/E38 -> 0.00065876153 | O38: =1/F38 -> 0.00068306011 | P38: =1/G38 -> 0.00068259386 | Q38: =AVERAGE(L38:P38) -> 0.0006888835 | S38: 80 | T38: =(L38-$M$46)/$M$46 -> 0.085156434 | U38: =(M38-$M$46)/$M$46 -> 0.098333333 | V38: =(N38-$M$46)/$M$46 -> 0.012955643 | W38: =(O38-$M$46)/$M$46 -> 0.050318761 | X38: =(P38-$M$46)/$M$46 -> 0.04960182 | Y38: =AVERAGE(T38:X38) -> 0.059273198
A39: 5 | B39: 100 | C39: ='Lote 3'!C9 -> 1432 | D39: ='Lote 3'!D9 -> 1407 | E39: ='Lote 3'!E9 -> 1414 | F39: ='Lote 3'!F9 -> 1451 | G39: ='Lote 3'!G9 -> 1445 | H39: =ROUND(AVERAGE(C39:G39),0) -> 1430 | I39: =_xlfn.STDEV.S(C39:G39) -> 19.07092 | K39: 100 | L39: =1/C39 -> 0.00069832402 | M39: =1/D39 -> 0.00071073205 | N39: =1/E39 -> 0.00070721358 | O39: =1/F39 -> 0.00068917988 | P39: =1/G39 -> 0.00069204152 | Q39: =AVERAGE(L39:P39) -> 0.00069949821 | S39: 100 | T39: =(L39-$M$46)/$M$46 -> 0.073789572 | U39: =(M39-$M$46)/$M$46 -> 0.092868988 | V39: =(N39-$M$46)/$M$46 -> 0.087458746 | W39: =(O39-$M$46)/$M$46 -> 0.059728923 | X39: =(P39-$M$46)/$M$46 -> 0.064129181 | Y39: =AVERAGE(T39:X39) -> 0.075595082
A40: 6 | B40: 120 | C40: ='Lote 3'!C10 -> 1428 | D40: ='Lote 3'!D10 -> 1361 | E40: ='Lote 3'!E10 -> 1428 | F40: ='Lote 3'!F10 -> 1443 | G40: ='Lote 3'!G10 -> 1422 | H40: =ROUND(AVERAGE(C40:G40),0) -> 1416 | I40: =_xlfn.STDEV.S(C40:G40) -> 31.926478 | K40: 120 | L40: =1/C40 -> 0.00070028011 | M40: =1/D40 -> 0.00073475386 | N40: =1/E40 -> 0.00070028011 | O40: =1/F40 -> 0.00069300069 | P40: =1/G40 -> 0.00070323488 | Q40: =AVERAGE(L40:P40) -> 0.00070630993 | S40: 120 | T40: =(L40-$M$46)/$M$46 -> 0.076797386 | U40: =(M40-$M$46)/$M$46 -> 0.12980651 | V40: =(N40-$M$46)/$M$46 -> 0.076797386 | W40: =(O40-$M$46)/$M$46 -> 0.065604066 | X40: =(P40-$M$46)/$M$46 -> 0.081340835 | Y40: =AVERAGE(T40:X40) -> 0.086069237
A41: 7 | B41: 140 | C41: ='Lote 3'!C11 -> 1362 | D41: ='Lote 3'!D11 -> 1328 | E41: ='Lote 3'!E11 -> 1402 | F41: ='Lote 3'!F11 -> 1398 | G41: ='Lote 3'!G11 -> 1399 | H41: =ROUND(AVERAGE(C41:G41),0) -> 1378 | I41: =_xlfn.STDEV.S(C41:G41) -> 32.298607 | K41: 140 | L41: =1/C41 -> 0.00073421439 | M41: =1/D41 -> 0.00075301205 | N41: =1/E41 -> 0.00071326676 | O41: =1/F41 -> 0.00071530758 | P41: =1/G41 -> 0.00071479628 | Q41: =AVERAGE(L41:P41) -> 0.00072611941 | S41: 140 | T41: =(L41-$M$46)/$M$46 -> 0.12897699 | U41: =(M41-$M$46)/$M$46 -> 0.15788153 | V41: =(N41-$M$46)/$M$46 -> 0.096766524 | W41: =(O41-$M$46)/$M$46 -> 0.099904626 | X41: =(P41-$M$46)/$M$46 -> 0.099118418 | Y41: =AVERAGE(T41:X41) -> 0.11652962
A42: 8 | B42: 160 | C42: ='Lote 3'!C12 -> 1322 | D42: ='Lote 3'!D12 -> 1292 | E42: ='Lote 3'!E12 -> 1379 | F42: ='Lote 3'!F12 -> 1365 | G42: ='Lote 3'!G12 -> 1343 | H42: =ROUND(AVERAGE(C42:G42),0) -> 1340 | I42: =_xlfn.STDEV.S(C42:G42) -> 34.578895 | K42: 160 | L42: =1/C42 -> 0.00075642965 | M42: =1/D42 -> 0.00077399381 | N42: =1/E42 -> 0.00072516316 | O42: =1/F42 -> 0.00073260073 | P42: =1/G42 -> 0.00074460164 | Q42: =AVERAGE(L42:P42) -> 0.0007465578 | S42: 160 | T42: =(L42-$M$46)/$M$46 -> 0.16313666 | U42: =(M42-$M$46)/$M$46 -> 0.19014448 | V42: =(N42-$M$46)/$M$46 -> 0.11505922 | W42: =(O42-$M$46)/$M$46 -> 0.12649573 | X42: =(P42-$M$46)/$M$46 -> 0.14494912 | Y42: =AVERAGE(T42:X42) -> 0.14795704
...

Sheet Resumen
A1: Muestra | B1: Tiempo [min] | C1: Lote 1 | H1: Lote 2 | M1: Lote 3
C2: Pellets/g | D2: %Ganancia | E2: Diametro [mm] | F2: e [mm] | G2: r [g/ml] | H2: Pellets/g | I2: %Ganancia | J2: Diametro [mm] | K2: e [mm] | L2: r [g/ml] | M2: Pellets/g | N2: %Ganancia | O2: Diametro [mm] | P2: e [mm] | Q2: r [g/ml]
A3: 0 | B3: 0 | C3: ='Lote 1'!H4 -> 1537 | D3: ='%Ganancia'!Y4 -> 0 | E3: ='Lote 1'!M4 -> 0.9117 | F3: ='Lote 1'!R4 -> 0 | G3: ='Lote 1'!AD4 -> 0.8999 | H3: ='Lote 2'!H4 -> 1537 | I3: ='%Ganancia'!Y19 -> 0 | J3: ='Lote 2'!M4 -> 0.9651 | K3: ='Lote 2'!R4 -> 0 | L3: ='Lote 2'!Z4 -> 0.89671667 | M3: ='Lote 3'!H4 -> 1537 | N3: ='%Ganancia'!Y34 -> 0 | O3: ='Lote 3'!M4 -> 1.0665 | P3: ='Lote 3'!R4 -> 0 | Q3: ='Lote 3'!Z4 -> 0.89483333
A4: 1 | B4: 20 | C4: ='Lote 1'!H5 -> 1493 | D4: ='%Ganancia'!Y5 -> 0.029893292 | E4: ='Lote 1'!M5 -> 1.0175 | F4: ='Lote 1'!R5 -> 0.0067 | G4: ='Lote 1'!AD5 -> 0.90127828 | H4: ='Lote 2'!H5 -> #DIV/0! | I4: ='%Ganancia'!Y20 -> #DIV/0! | J4: ='Lote 2'!M5 -> 1.0698 | K4: ='Lote 2'!R5 -> 0.0063 | L4: ='Lote 2'!Z5 -> 0.9007 | M4: ='Lote 3'!H5 -> 1527 | N4: ='%Ganancia'!Y35 -> 0.0065993458 | O4: ='Lote 3'!M5 -> 1.1159 | P4: ='Lote 3'!R5 -> 0.0063 | Q4: ='Lote 3'!Z5 -> 0.90496667
A5: 2 | B5: 40 | C5: ='Lote 1'!H6 -> 1462 | D5: ='%Ganancia'!Y6 -> 0.052056911 | E5: ='Lote 1'!M6 -> 1.0222 | F5: ='Lote 1'!R6 -> 0.0111 | G5: ='Lote 1'!AD6 -> 0.92430187 | H5: ='Lote 2'!H6 -> #DIV/0! | I5: ='%Ganancia'!Y21 -> #DIV/0! | J5: ='Lote 2'!M6 -> 1.0603 | K5: ='Lote 2'!R6 -> 0.0124 | L5: ='Lote 2'!Z6 -> 0.9203 | M5: ='Lote 3'!H6 -> 1498 | N5: ='%Ganancia'!Y36 -> 0.026753539 | O5: ='Lote 3'!M6 -> 1.0175 | P5: ='Lote 3'!R6 -> 0.0111 | Q5: ='Lote 3'!Z6 -> 0.91533333
A6: 3 | B6: 60 | C6: ='Lote 1'!H7 -> 1432 | D6: ='%Ganancia'!Y7 -> 0.073910897 | E6: ='Lote 1'!M7 -> 1.0159 | F6: ='Lote 1'!R7 -> 0.0143 | G6: ='Lote 1'!AD7 -> 0.93414189 | H6: ='Lote 2'!H7 -> #DIV/0! | I6: ='%Ganancia'!Y22 -> #DIV/0! | J6: ='Lote 2'!M7 -> 1.0841 | K6: ='Lote 2'!R7 -> 0.0222 | L6: ='Lote 2'!Z7 -> 0.92865 | M6: ='Lote 3'!H7 -> 1479 | N6: ='%Ganancia'!Y37 -> 0.040167249 | O6: ='Lote 3'!M7 -> 1.0476 | P6: ='Lote 3'!R7 -> 0.0159 | Q6: ='Lote 3'!Z7 -> 0.92518333
A7: 4 | B7: 80 | C7: ='Lote 1'!H8 -> 1410 | D7: ='%Ganancia'!Y8 -> 0.090453394 | E7: ='Lote 1'!M8 -> 1.057 | F7: ='Lote 1'!R8 -> 0.0206 | G7: ='Lote 1'!AD8 -> 0.94063995 | H7: ='Lote 2'!H8 -> #DIV/0! | I7: ='%Ganancia'!Y23 -> #DIV/0! | J7: ='Lote 2'!M8 -> 1.0857 | K7: ='Lote 2'!R8 -> 0.0341 | L7: ='Lote 2'!Z8 -> 0.94063333 | M7: ='Lote 3'!H8 -> 1452 | N7: ='%Ganancia'!Y38 -> 0.059273198 | O7: ='Lote 3'!M8 -> 1.0794 | P7: ='Lote 3'!R8 -> 0.0227 | Q7: ='Lote 3'!Z8 -> 0.93541667
A8: 5 | B8: 100 | C8: ='Lote 1'!H9 -> 1406 | D8: ='%Ganancia'!Y9 -> 0.093659553 | E8: ='Lote 1'!M9 -> 1.1209 | F8: ='Lote 1'!R9 -> 0.0212 | G8: ='Lote 1'!AD9 -> 0.94676309 | H8: ='Lote 2'!H9 -> #DIV/0! | I8: ='%Ganancia'!Y24 -> #DIV/0! | J8: ='Lote 2'!M9 -> 1.1571 | K8: ='Lote 2'!R9 -> 0.0413 | L8: ='Lote 2'!Z9 -> 0.94668333 | M8: ='Lote 3'!H9 -> 1429 | N8: ='%Ganancia'!Y39 -> 0.075595082 | O8: ='Lote 3'!M9 -> 1.1616 | P8: ='Lote 3'!R9 -> 0.0293 | Q8: ='Lote 3'!Z9 -> 0.94358333
A9: 6 | B9: 120 | C9: ='Lote 1'!H10 -> 1380 | D9: ='%Ganancia'!Y10 -> 0.11367561 | E9: ='Lote 1'!M10 -> 1.0381 | F9: ='Lote 1'!R10 -> 0.0286 | G9: ='Lote 1'!AD10 -> 0.95851487 | H9: ='Lote 2'!H10 -> #DIV/0! | I9: ='%Ganancia'!Y25 -> #DIV/0! | J9: ='Lote 2'!M10 -> 1.1333 | K9: ='Lote 2'!R10 -> 0.0483 | L9: ='Lote 2'!Z10 -> 0.9586 | M9: ='Lote 3'!H10 -> 1416 | N9: ='%Ganancia'!Y40 -> 0.086069237 | O9: ='Lote 3'!M10 -> 1.1714 | P9: ='Lote 3'!R10 -> 0.0348 | Q9: ='Lote 3'!Z10 -> 0.95281667
A10: 7 | B10: 140 | C10: ='Lote 1'!H11 -> 1347 | D10: ='%Ganancia'!Y11 -> 0.14091959 | E10: ='Lote 1'!M11 -> 1.003 | F10: ='Lote 1'!R11 -> 0.0401 | G10: ='Lote 1'!AD11 -> 0.96141403 | H10: ='Lote 2'!H11 -> #DIV/0! | I10: ='%Ganancia'!Y26 -> #DIV/0! | J10: ='Lote 2'!M11 -> 1.1111 | K10: ='Lote 2'!R11 -> 0.0528 | L10: ='Lote 2'!Z11 -> 0.96283333 | M10: ='Lote 3'!H11 -> 1377 | N10: ='%Ganancia'!Y41 -> 0.11652962 | O10: ='Lote 3'!M11 -> 1.109 | P10: ='Lote 3'!R11 -> 0.0402 | Q10: ='Lote 3'!Z11 -> 0.96096667
A11: 8 | B11: 160 | C11: ='Lote 1'!H12 -> 1324 | D11: ='%Ganancia'!Y12 -> 0.1620611 | E11: ='Lote 1'!M12 -> 1.0127 | F11: ='Lote 1'!R12 -> 0.0454 | G11: ='Lote 1'!AD12 -> 0.96692146 | H11: ='Lote 2'!H12 -> #DIV/0! | I11: ='%Ganancia'!Y27 -> #DIV/0! | J11: ='Lote 2'!M12 -> 1.1905 | K11: ='Lote 2'!R12 -> 0.0587 | L11: ='Lote 2'!Z12 -> 0.97176667 | M11: ='Lote 3'!H12 -> 1340 | N11: ='%Ganancia'!Y42 -> 0.14795704 | O11: ='Lote 3'!M12 -> 1.2317 | P11: ='Lote 3'!R12 -> 0.046 | Q11: ='Lote 3'!Z12 -> 0.96948333
A12: 9 | B12: 180 | C12: ='Lote 1'!H13 -> 1301 | D12: ='%Ganancia'!Y13 -> 0.18183553 | E12: ='Lote 1'!M13 -> 0.9413 | F12: ='Lote 1'!R13 -> 0.0508 | G12: ='Lote 1'!AD13 -> 0.97381707 | H12: ='Lote 2'!H13 -> #DIV/0! | I12: ='%Ganancia'!Y28 -> #DIV/0! | J12: ='Lote 2'!M13 -> 1.1841 | K12: ='Lote 2'!R13 -> 0.0593 | L12: ='Lote 2'!Z13 -> 0.97881667 | M12: ='Lote 3'!H13 -> 1306 | N12: ='%Ganancia'!Y43 -> 0.1784217 | O12: ='Lote 3'!M13 -> 1.2466 | P12: ='Lote 3'!R13 -> 0.0528 | Q12: ='Lote 3'!Z13 -> 0.97471667
A13: Final | B13: 200 | C13: ='Lote 1'!H14 -> 1290 | D13: ='%Ganancia'!Y14 -> 0.19183953 | E13: ='Lote 1'!M14 -> 0.9964 | F13: ='Lote 1'!R14 -> 0.0533 | G13: ='Lote 1'!AD14 -> 0.99603426 | H13: ='Lote 2'!H14 -> 1286 | I13: ='%Ganancia'!Y29 -> 0.19499761 | J13: ='Lote 2'!M14 -> 1.3302 | K13: ='Lote 2'!R14 -> 0.0603 | L13: ='Lote 2'!Z14 -> 0.99155 | M13: ='Lote 3'!H14 -> 1364 | N13: ='%Ganancia'!Y44 -> 0.12806362 | O13: ='Lote 3'!M14 -> 1.2587 | P13: ='Lote 3'!R14 -> 0.0553 | Q13: ='Lote 3'!Z14 -> 0.99
K15: r_s [g/mm3] | M15: 0.000559 | P15: r_p [g/mm3] | R15: =G13 -> 0.99603426
P16: r_d [g/mm3] | R16: 0.9023
M17: 1 | R17: 1
K18: Do [mm] | M18: 0.932 | P18: Do [mm] | R18: 0.932
K19: e [mm] | M19: 0.0533 | P19: e [mm] | R19: 0.0533
K21: mc_teo [g] | M21: =((PI()/6)*((3*(M18^2)*M19)+(3*M18*(M19^2))+(M19^3)))*M15 -> 4.3022031e-05 | P21: mc_teo [g] | R21: =(PI()/6)*(R15-R16)*((3*(R18^2)*R19)+(3*R18*(R19^2))+(R19^3)) -> 0.0072140219
K22: mc_exp [g] | M22: ='%Ganancia'!Q14-'%Ganancia'!M46 -> 0.00012476015 | P22: mc_exp [g] | R22: =M22 -> 0.00012476015
K23: %ERROR | M23: =ABS(M21-M22)/M22 -> 0.65516209 | P23: %ERROR | R23: =ABS(R21-R22)/R21 -> 0.98270588
Q25: r | R25: =R15-R16 -> 0.09373426
Q26: V | R26: =((3*(R18^2)*R19)+(3*R18*(R19^2))+(R19^3))*(PI()/6) -> 0.076962488

Sheet Analisis Cp
A1: Lote | B1: Medición | G1: m | H1: Max | I1: Min | J1: Rango
B2: 1 | C2: 2 | D2: 3 | E2: 4 | F2: 5
A3: 1 | B3: ='Lote 1'!C14 -> 1283 | C3: ='Lote 1'!D14 -> 1302 | D3: ='Lote 1'!E14 -> 1287 | E3: ='Lote 1'!F14 -> 1294 | F3: ='Lote 1'!G14 -> 1285 | G3: =ROUNDDOWN(AVERAGE(B3:F3),0) -> 1290 | H3: =MAX(B3:F3) -> 1302 | I3: =MIN(B3:F3) -> 1283 | J3: =H3-I3 -> 19
A4: 2 | B4: ='Lote 2'!C14 -> 1292 | C4: ='Lote 2'!D14 -> 1298 | D4: ='Lote 2'!E14 -> 1284 | E4: ='Lote 2'!F14 -> 1275 | F4: ='Lote 2'!G14 -> 1285 | G4: =ROUNDDOWN(AVERAGE(B4:F4),0) -> 1286 | H4: =MAX(B4:F4) -> 1298 | I4: =MIN(B4:F4) -> 1275 | J4: =H4-I4 -> 23
A5: 3 | B5: ='Lote 3'!C14 -> 1403 | C5: ='Lote 3'!D14 -> 1402 | D5: ='Lote 3'!E14 -> 1365 | E5: ='Lote 3'!F14 -> 1332 | F5: ='Lote 3'!G14 -> 1318 | G5: =ROUNDDOWN(AVERAGE(B5:F5),0) -> 1364 | H5: =MAX(B5:F5) -> 1403 | I5: =MIN(B5:F5) -> 1318 | J5: =H5-I5 -> 85
F7: Media de medias | G7: =ROUNDDOWN(AVERAGE(G3:G4),0) -> 1288 | I7: Rango promedio | J7: =ROUNDDOWN(AVERAGE(J3:J4),0) -> 21
A9: ES | B9: =ROUNDDOWN(B10*1.03,0) -> 1326 | E9: Cpi | F9: =(G7-B11)/(3*B14) -> 1.4399048
A10: Nomilanl | B10: 1288 | E10: Cps | F10: =(B9-G7)/(3*B14) -> 1.4029841
A11: EI | B11: =ROUNDDOWN(B10*0.97,0) -> 1249 | E11: Cpk | F11: =MIN(F9:F10) -> 1.4029841
A13: d2 | B13: 2.326 | E13: Ppi | F13: =(G7-B11)/(3*B15) -> 1.62712
A14: Desv. Corto | B14: =J7/B13 -> 9.0283749 | E14: Pps | F14: =(B9-G7)/(3*B15) -> 1.585399
A15: Desv. Largo | B15: =_xlfn.STDEV.S(B3:F4) -> 7.9895765 | E15: Ppk | F15: =MIN(F13:F14) -> 1.585399
A17: Cp | B17: =(B9-B11)/(6*B14) -> 1.4214444
A18: Pp | B18: =(B9-B11)/(6*B15) -> 1.6062595

Sheet Parámetros proc.
B1: Lote 1 | F1: Lote 2 | J1: Lote 3
A2: Tiempo [min] | B2: P atomiz [bar ] | C2: P. aire comp [bar] | D2: T. producto [°C ] | E2: Velocidad Aire [m/s ] | F2: P atomiz [bar ] | G2: P. aire comp [bar] | H2: T. producto [°C ] | I2: Velocidad Aire [m/s ] | J2: P atomiz [bar ] | K2: P. aire comp [bar] | L2: T. producto [°C ] | M2: Velocidad Aire [m/s ]
A3: 1 | B3: 3.5 | C3: 6 | D3: 27.9 | E3: 0.66 | F3: 1.2 | G3: 5.8 | H3: 18.5 | I3: 0.6 | J3: 3.5 | K3: 5.8 | L3: 43.4 | M3: 6.6
A4: 2 | B4: 3.5 | C4: 5.9 | D4: 44.5 | E4: 3.13 | F4: 3.5 | G4: 6.7 | H4: 29.1 | I4: 4 | J4: 3.4 | K4: 6.8 | L4: 44.9 | M4: 6.1
A5: 3 | B5: 3.5 | C5: 6.3 | D5: 47.9 | E5: 5.84 | F5: 3.5 | G5: 6.5 | H5: 40.8 | I5: 7.4 | J5: 3.4 | K5: 6.5 | L5: 47 | M5: 6.9
A6: 4 | B6: 3.5 | C6: 6.3 | D6: 47.3 | E6: 2.1 | F6: 3.5 | G6: 6.1 | H6: 43.2 | I6: 7.9 | J6: 3.5 | K6: 6.1 | L6: 48.8 | M6: 7.5
A7: 5 | B7: 3.5 | C7: 6.3 | D7: 48.2 | E7: 2.5 | F7: 3.5 | G7: 6 | H7: 44 | I7: 8.2 | J7: 3.5 | K7: 5.8 | L7: 49.8 | M7: 8.6
A8: 6 | B8: 3.5 | C8: 6.3 | D8: 49.7 | E8: 2.16 | F8: 3.4 | G8: 6.8 | H8: 44.7 | I8: 8.2 | J8: 3.4 | K8: 6.8 | L8: 50.6 | M8: 8.4
A9: 7 | B9: 3.5 | C9: 6.3 | D9: 50.5 | E9: 2.16 | F9: 3.5 | G9: 6.3 | H9: 45.1 | I9: 8.2 | J9: 3.4 | K9: 6.6 | L9: 51 | M9: 8.8
A10: 8 | B10: 3.5 | C10: 6.2 | D10: 50.6 | E10: 2.11 | F10: 3.5 | G10: 5.9 | H10: 45.5 | I10: 8.1 | J10: 3.5 | K10: 5.6 | L10: 50.7 | M10: 8.5
A11: 9 | B11: 3.5 | C11: 6.2 | D11: 50.9 | E11: 2.14 | F11: 3.5 | G11: 6.3 | H11: 45.9 | I11: 8 | J11: 3.4 | K11: 6.6 | L11: 50 | M11: 8.1
A12: 10 | B12: 3.5 | C12: 5.8 | D12: 51.1 | E12: 2.22 | F12: 3.4 | G12: 6.7 | H12: 46.1 | I12: 7.9 | J12: 3.4 | K12: 6.7 | L12: 49 | M12: 8.1
A13: 11 | B13: 3.5 | C13: 6.3 | D13: 51.3 | E13: 3.86 | F13: 3.4 | G13: 6.2 | H13: 47.1 | I13: 8.2 | J13: 3.5 | K13: 6.2 | L13: 48.6 | M13: 7.7
A14: 12 | B14: 3.5 | C14: 6.3 | D14: 49.6 | E14: 4.14 | F14: 3.5 | G14: 5.8 | H14: 47.7 | I14: 8.4 | J14: 3.5 | K14: 5.9 | L14: 48.5 | M14: 7.4
... A232: 230 | B232: 3.4 | C232: 5.8 | D232: 52.8 | E232: 2.67 | F232: 3.4 | G232: 6.8 | H232: 55.7 | I232: 9.6 | J232: 0.5 | K232: 6.5 | L232: 55.4 | M232: 5.1
A233: 231 | B233: 3.4 | C233: 6.3 | D233: 52.7 | E233: 2.69 | F233: 3.4 | G233: 6.3 | H233: 55.3 | I233: 8.1
A234: 232 | B234: 3.4 | C234: 6.2 | D234: 52.7 | E234: 2.78 | F234: 3.4 | G234: 5.9 | H234: 55.1 | I234: 9.7
A235: 233 | B235: 3.4 | C235: 6.2 | D235: 52.8 | E235: 2.86 | F235: 3.4 | G235: 6.4 | H235: 54.6 | I235: 8.6
A236: 234 | B236: 3.4 | C236: 6 | D236: 52.8 | E236: 2.9 | F236: 3.4 | G236: 6.7 | H236: 54.6 | I236: 9.6
A237: 235 | B237: 3.4 | C237: 6.2 | D237: 53.1 | E237: 2.92 | F237: 3.4 | G237: 6.3 | H237: 54.4 | I237: 8.4
A238: 236 | B238: 3.4 | C238: 6.3 | D238: 53.2 | E238: 2.98 | F238: 3.4 | G238: 5.9 | H238: 54.4 | I238: 9.2
A239: 237 | B239: 3.4 | C239: 6.2 | D239: 53.2 | E239: 2.9 | F239: 3.4 | G239: 6.6 | H239: 54.2 | I239: 8.8
A240: 238 | B240: 3.4 | C240: 6.1 | D240: 53.5 | E240: 2.89 | F240: 3.4 | G240: 6.7 | H240: 54.3 | I240: 9
A241: 239 | B241: 3.4 | C241: 4.1 | D241: 53.6 | E241: 3 | F241: 3.4 | G241: 6.2 | H241: 54.2 | I241: 8.9
A242: 240 | B242: 3.4 | C242: 6.3 | D242: 53.5 | E242: 2.98 | F242: 3.4 | G242: 5.9 | H242: 54.2 | I242: 8.5
A243: 241 | B243: 3.4 | C243: 6.2 | D243: 53.6 | E243: 2.95 | F243: 3.4 | G243: 6.7 | H243: 54.3 | I243: 9.3
A244: 242 | B244: 3.4 | C244: 6.1 | D244: 54.2 | E244: 2.89 | F244: 3.4 | G244: 6.6 | H244: 54.2 | I244: 8.5
... A259: 257 | B259: 3.4 | C259: 6.1 | D259: 55.1 | E259: 2.89 | F259: 3.3 | G259: 6.9 | H259: 57.1 | I259: 9.6
A260: 258 | B260: 3.4 | C260: 5.9 | D260: 55 | E260: 2.92
A261: 259 | B261: 3.4 | C261: 6.3 | D261: 54.8 | E261: 2.95
A262: 260 | B262: 3.4 | C262: 6.3 | D262: 54.7 | E262: 2.95
A263: 261 | B263: 3.4 | C263: 6.2 | D263: 54.4 | E263: 2.98
A264: 262 | B264: 3.4 | C264: 6.1 | D264: 53.8 | E264: 2.89
A265: 263 | B265: 3.4 | C265: 6 | D265: 53.3 | E265: 2.92
A266: 264 | B266: 3.4 | C266: 5.8 | D266: 53 | E266: 2.9
A267: 265 | B267: 3.4 | C267: 6.3 | D267: 52.7 | E267: 2.84
A268: 266 | B268: 3.4 | C268: 6.2 | D268: 52.5 | E268: 2.81
A269: 267 | B269: 3.4 | C269: 6.1 | D269: 52.2 | E269: 2.78
A270: 268 | B270: 3.4 | C270: 5.9 | D270: 52.1 | E270: 2.78
A271: 269 | B271: 3.4 | C271: 6 | D271: 51.6 | E271: 2.78
...
