Workbook

Sheet Lote 1
A2: Muestra | B2: Tiempo [min] | C2: Pellets/g | H2: m | I2: s | J2: Diametro [mm] Microscopio | M2: m | N2: s | O2: Espesor [mm] Microscopio | R2: m | S2: s | T2: Densidad 00 [g/ml] | W2: Densidad 0 [g/ml] | Z2: m | AA2: s
C3: 1 | D3: 2 | E3: 3 | F3: 4 | G3: 5 | J3: 1 | K3: 2 | L3: 3 | O3: 1 | P3: 2 | Q3: 3 | T3: 1 | U3: 2 | V3: 3 | W3: 1 | X3: 2 | Y3: 3
A4: 0 | B4: 0 | C4: 1523 | D4: 1499 | E4: 1493 | F4: 1496 | G4: 1501 | H4: =ROUNDDOWN(AVERAGE(C4:G4),0) -> 1502 | I4: =_xlfn.STDEV.S(C4:G4) -> 11.907981 | J4: 0.932 | M4: =AVERAGE(J4:L4) -> 0.932 | N4: =_xlfn.STDEV.S(J4:L4) -> #DIV/0! | O4: 0 | P4: 0 | Q4: 0 | R4: =AVERAGE(O4:Q4) -> 0 | S4: =_xlfn.STDEV.S(O4:Q4) -> 0 | T4: 0.9231 | U4: 0.911 | V4: 0.922 | W4: 0.8926 | X4: 0.8868 | Y4: 0.8794 | Z4: =AVERAGE(T4:Y4) -> 0.90248333 | AA4: =_xlfn.STDEV.S(T4:Y4) -> 0.018734825
A5: 1 | B5: 20 | C5: 1491 | D5: 1515 | E5: 1512 | F5: 1524 | G5: 1510 | H5: =ROUNDDOWN(AVERAGE(C5:G5),0) -> 1510 | I5: =_xlfn.STDEV.S(C5:G5) -> 12.095454 | J5: 0.92 | M5: =AVERAGE(J5:L5) -> 0.92 | N5: =_xlfn.STDEV.S(J5:L5) -> #DIV/0! | O5: 0 | R5: =AVERAGE(O5:Q5) -> 0 | S5: =_xlfn.STDEV.S(O5:Q5) -> #DIV/0! | T5: 0.9253 | U5: 0.9222 | V5: 0.9253 | W5: 0.9044 | X5: 0.8956 | Y5: 0.8868 | Z5: =AVERAGE(T5:Y5) -> 0.90993333 | AA5: =_xlfn.STDEV.S(T5:Y5) -> 0.016697026
A6: 2 | B6: 40 | C6: 1485 | D6: 1490 | E6: 1507 | F6: 1511 | G6: 1500 | H6: =ROUNDDOWN(AVERAGE(C6:G6),0) -> 1498 | I6: =_xlfn.STDEV.S(C6:G6) -> 11.013628 | J6: 0.95 | M6: =AVERAGE(J6:L6) -> 0.95 | N6: =_xlfn.STDEV.S(J6:L6) -> #DIV/0! | O6: 0 | R6: =AVERAGE(O6:Q6) -> 0 | S6: =_xlfn.STDEV.S(O6:Q6) -> #DIV/0! | T6: 0.93736264 | U6: 0.93956044 | V6: 0.94065934 | W6: 0.9 | X6: 0.91470588 | Y6: 0.89852941 | Z6: =AVERAGE(T6:Y6) -> 0.92180295 | AA6: =_xlfn.STDEV.S(T6:Y6) -> 0.01990171
A7: 3 | B7: 60 | C7: 1473 | D7: 1489 | E7: 1480 | F7: 1457 | G7: 1489 | H7: =ROUNDDOWN(AVERAGE(C7:G7),0) -> 1477 | I7: =_xlfn.STDEV.S(C7:G7) -> 13.334167 | J7: 0.91 | M7: =AVERAGE(J7:L7) -> 0.91 | N7: =_xlfn.STDEV.S(J7:L7) -> #DIV/0! | O7: 0 | R7: =AVERAGE(O7:Q7) -> 0 | S7: =_xlfn.STDEV.S(O7:Q7) -> #DIV/0! | T7: 0.93406593 | U7: 0.94945055 | V7: 0.94835165 | W7: 0.91470588 | X7: 0.91617647 | Y7: 0.91029412 | Z7: =AVERAGE(T7:Y7) -> 0.92884077 | AA7: =_xlfn.STDEV.S(T7:Y7) -> 0.017532242
A8: 4 | B8: 80 | C8: 1439 | D8: 1450 | E8: 1471 | F8: 1477 | G8: 1448 | H8: =ROUNDDOWN(AVERAGE(C8:G8),0) -> 1457 | I8: =_xlfn.STDEV.S(C8:G8) -> 16.201852 | J8: 0.95 | M8: =AVERAGE(J8:L8) -> 0.95 | N8: =_xlfn.STDEV.S(J8:L8) -> #DIV/0! | O8: 0 | R8: =AVERAGE(O8:Q8) -> 0 | S8: =_xlfn.STDEV.S(O8:Q8) -> #DIV/0! | T8: 0.95604396 | U8: 0.95164835 | V8: 0.95274725 | W8: 0.92205882 | X8: 0.91764706 | Y8: 0.91911765 | Z8: =AVERAGE(T8:Y8) -> 0.93654385 | AA8: =_xlfn.STDEV.S(T8:Y8) -> 0.018662945
A9: 5 | B9: 100 | C9: 1441 | D9: 1431 | E9: 1443 | F9: 1440 | G9: 1460 | H9: =ROUNDDOWN(AVERAGE(C9:G9),0) -> 1443 | I9: =_xlfn.STDEV.S(C9:G9) -> 10.559356 | J9: 0.93 | M9: =AVERAGE(J9:L9) -> 0.93 | N9: =_xlfn.STDEV.S(J9:L9) -> #DIV/0! | O9: 0.01 | R9: =AVERAGE(O9:Q9) -> 0.01 | S9: =_xlfn.STDEV.S(O9:Q9) -> #DIV/0! | T9: 0.95274725 | U9: 0.97032967 | V9: 0.95604396 | W9: 0.91764706 | X9: 0.92205882 | Y9: 0.92352941 | Z9: =AVERAGE(T9:Y9) -> 0.9403927 | AA9: =_xlfn.STDEV.S(T9:Y9) -> 0.022053048
A10: 6 | B10: 120 | C10: 1399 | D10: 1395 | E10: 1411 | F10: 1396 | G10: 1419 | H10: =ROUNDDOWN(AVERAGE(C10:G10),0) -> 1404 | I10: =_xlfn.STDEV.S(C10:G10) -> 10.535654 | J10: 0.98 | M10: =AVERAGE(J10:L10) -> 0.98 | N10: =_xlfn.STDEV.S(J10:L10) -> #DIV/0! | O10: 0.01 | R10: =AVERAGE(O10:Q10) -> 0.01 | S10: =_xlfn.STDEV.S(O10:Q10) -> #DIV/0! | T10: 0.96923077 | U10: 0.97032967 | V10: 0.94615385 | W10: 0.94117647 | X10: 0.92647059 | Y10: 0.91470588 | Z10: =AVERAGE(T10:Y10) -> 0.94467787 | AA10: =_xlfn.STDEV.S(T10:Y10) -> 0.02238358
A11: 7 | B11: 140 | C11: 1388 | D11: 1375 | E11: 1392 | F11: 1400 | G11: 1397 | H11: =ROUNDDOWN(AVERAGE(C11:G11),0) -> 1390 | I11: =_xlfn.STDEV.S(C11:G11) -> 9.7621719 | J11: 0.95 | M11: =AVERAGE(J11:L11) -> 0.95 | N11: =_xlfn.STDEV.S(J11:L11) -> #DIV/0! | O11: 0.02 | R11: =AVERAGE(O11:Q11) -> 0.02 | S11: =_xlfn.STDEV.S(O11:Q11) -> #DIV/0! | T11: 0.96593407 | U11: 0.96593407 | V11: 0.95824176 | W11: 0.92205882 | X11: 0.94852941 | Y11: 0.92647059 | Z11: =AVERAGE(T11:Y11) -> 0.94786145 | AA11: =_xlfn.STDEV.S(T11:Y11) -> 0.019415357
A12: 8 | B12: 160 | C12: 1380 | D12: 1380 | E12: 1375 | F12: 1379 | G12: 1380 | H12: =ROUNDDOWN(AVERAGE(C12:G12),0) -> 1378 | I12: =_xlfn.STDEV.S(C12:G12) -> 2.1679483 | J12: 0.97 | M12: =AVERAGE(J12:L12) -> 0.97 | N12: =_xlfn.STDEV.S(J12:L12) -> #DIV/0! | O12: 0.02 | R12: =AVERAGE(O12:Q12) -> 0.02 | S12: =_xlfn.STDEV.S(O12:Q12) -> #DIV/0! | T12: 0.97582418 | U12: 0.97362637 | V12: 0.96153846 | W12: 0.94117647 | X12: 0.93382353 | Y12: 0.93088235 | Z12: =AVERAGE(T12:Y12) -> 0.95281189 | AA12: =_xlfn.STDEV.S(T12:Y12) -> 0.020078877
A13: 9 | B13: 180 | C13: 1359 | D13: 1376 | E13: 1383 | F13: 1379 | G13: 1382 | H13: =ROUNDDOWN(AVERAGE(C13:G13),0) -> 1375 | I13: =_xlfn.STDEV.S(C13:G13) -> 9.7826377 | J13: 0.95 | M13: =AVERAGE(J13:L13) -> 0.95 | N13: =_xlfn.STDEV.S(J13:L13) -> #DIV/0! | O13: 0.02 | R13: =AVERAGE(O13:Q13) -> 0.02 | S13: =_xlfn.STDEV.S(O13:Q13) -> #DIV/0! | T13: 0.96703297 | U13: 0.98241758 | V13: 0.97472527 | W13: 0.93529412 | X13: 0.94411765 | Y13: 0.93970588 | Z13: =AVERAGE(T13:Y13) -> 0.95721558 | AA13: =_xlfn.STDEV.S(T13:Y13) -> 0.01998403
A14: Final | B14: 200 | C14: 1345 | D14: 1341 | E14: 1344 | F14: 1356 | G14: 1340 | H14: =ROUNDDOWN(AVERAGE(C14:G14),0) -> 1345 | I14: =_xlfn.STDEV.S(C14:G14) -> 6.3796552 | J14: 0.95 | M14: =AVERAGE(J14:L14) -> 0.95 | N14: =_xlfn.STDEV.S(J14:L14) -> #DIV/0! | O14: 0.02 | R14: =AVERAGE(O14:Q14) -> 0.02 | S14: =_xlfn.STDEV.S(O14:Q14) -> #DIV/0! | T14: 0.98021978 | U14: 0.97802198 | V14: 0.97472527 | W14: 0.95 | X14: 0.94117647 | Y14: 0.94117647 | Z14: =AVERAGE(T14:Y14) -> 0.96088666 | AA14: =_xlfn.STDEV.S(T14:Y14) -> 0.018731783

Sheet Lote 2
A2: Muestra | B2: Tiempo [min] | C2: Pellets/g | H2: m | I2: s | J2: Diametro [mm] Microscopio | M2: m | N2: s | O2: Espesor [mm] Microscopio | R2: m | S2: s | T2: Densidad 00 [g/ml] | W2: Densidad 0 [g/ml] | Z2: m | AA2: s
C3: 1 | D3: 2 | E3: 3 | F3: 4 | G3: 5 | J3: 1 | K3: 2 | L3: 3 | O3: 1 | P3: 2 | Q3: 3 | T3: 1 | U3: 2 | V3: 3 | W3: 1 | X3: 2 | Y3: 3
A4: 0 | B4: 0 | C4: 1529 | D4: 1519 | E4: 1503 | F4: 1512 | G4: 1512 | H4: =ROUNDDOWN(AVERAGE(C4:G4),0) -> 1515 | I4: =_xlfn.STDEV.S(C4:G4) -> 9.6695398 | J4: 0.88 | M4: =AVERAGE(J4:L4) -> 0.88 | N4: =_xlfn.STDEV.S(J4:L4) -> #DIV/0! | P4: 0 | R4: =AVERAGE(O4:Q4) -> 0 | S4: =_xlfn.STDEV.S(O4:Q4) -> #DIV/0! | T4: 0.9242 | U4: 0.922 | V4: 0.922 | W4: 0.8868 | X4: 0.8897 | Y4: 0.875 | Z4: =AVERAGE(T4:Y4) -> 0.90328333 | AA4: =_xlfn.STDEV.S(T4:Y4) -> 0.021882817
A5: 1 | B5: 20 | C5: 1518 | D5: 1509 | E5: 1522 | F5: 1518 | G5: 1540 | H5: =ROUNDDOWN(AVERAGE(C5:G5),0) -> 1521 | I5: =_xlfn.STDEV.S(C5:G5) -> 11.436783 | J5: 0.99 | M5: =AVERAGE(J5:L5) -> 0.99 | N5: =_xlfn.STDEV.S(J5:L5) -> #DIV/0! | P5: 0.008 | R5: =AVERAGE(O5:Q5) -> 0.008 | S5: =_xlfn.STDEV.S(O5:Q5) -> #DIV/0! | T5: 0.91978022 | U5: 0.92197802 | V5: 0.93406593 | W5: 0.89705882 | X5: 0.91029412 | Y5: 0.88823529 | Z5: =AVERAGE(T5:Y5) -> 0.91190207 | AA5: =_xlfn.STDEV.S(T5:Y5) -> 0.016957893
A6: 2 | B6: 40 | C6: 1501 | D6: 1500 | E6: 1499 | F6: 1500 | G6: 1517 | H6: =ROUNDDOWN(AVERAGE(C6:G6),0) -> 1503 | I6: =_xlfn.STDEV.S(C6:G6) -> 7.6354437 | K6: 0.886 | M6: =AVERAGE(J6:L6) -> 0.886 | N6: =_xlfn.STDEV.S(J6:L6) -> #DIV/0! | P6: 0.013 | R6: =AVERAGE(O6:Q6) -> 0.013 | S6: =_xlfn.STDEV.S(O6:Q6) -> #DIV/0! | T6: 0.93736264 | U6: 0.92417582 | V6: 0.93626374 | W6: 0.90441176 | X6: 0.90294118 | Y6: 0.90294118 | Z6: =AVERAGE(T6:Y6) -> 0.91801605 | AA6: =_xlfn.STDEV.S(T6:Y6) -> 0.016642064
A7: 3 | B7: 60 | C7: 1489 | D7: 1495 | E7: 1480 | F7: 1502 | G7: 1502 | H7: =ROUNDDOWN(AVERAGE(C7:G7),0) -> 1493 | I7: =_xlfn.STDEV.S(C7:G7) -> 9.3434469 | K7: 0.893 | M7: =AVERAGE(J7:L7) -> 0.893 | N7: =_xlfn.STDEV.S(J7:L7) -> #DIV/0! | P7: 0.016 | R7: =AVERAGE(O7:Q7) -> 0.016 | S7: =_xlfn.STDEV.S(O7:Q7) -> #DIV/0! | T7: 0.92857143 | U7: 0.94175824 | V7: 0.93296703 | W7: 0.90441176 | X7: 0.90441176 | Y7: 0.91470588 | Z7: =AVERAGE(T7:Y7) -> 0.92113769 | AA7: =_xlfn.STDEV.S(T7:Y7) -> 0.015628706
A8: 4 | B8: 80 | C8: 1451 | D8: 1464 | E8: 1474 | F8: 1470 | G8: 1487 | H8: =ROUNDDOWN(AVERAGE(C8:G8),0) -> 1469 | I8: =_xlfn.STDEV.S(C8:G8) -> 13.217413 | K8: 0.919 | M8: =AVERAGE(J8:L8) -> 0.919 | N8: =_xlfn.STDEV.S(J8:L8) -> #DIV/0! | P8: 0.032 | R8: =AVERAGE(O8:Q8) -> 0.032 | S8: =_xlfn.STDEV.S(O8:Q8) -> #DIV/0! | T8: 0.94505495 | U8: 0.95054945 | V8: 0.93186813 | W8: 0.91323529 | X8: 0.91470588 | Y8: 0.91323529 | Z8: =AVERAGE(T8:Y8) -> 0.92810817 | AA8: =_xlfn.STDEV.S(T8:Y8) -> 0.016893595
A9: 5 | B9: 100 | C9: 1438 | D9: 1432 | E9: 1462 | F9: 1437 | G9: 1424 | H9: =ROUNDDOWN(AVERAGE(C9:G9),0) -> 1438 | I9: =_xlfn.STDEV.S(C9:G9) -> 14.205633 | K9: 0.924 | M9: =AVERAGE(J9:L9) -> 0.924 | N9: =_xlfn.STDEV.S(J9:L9) -> #DIV/0! | P9: 0.037 | R9: =AVERAGE(O9:Q9) -> 0.037 | S9: =_xlfn.STDEV.S(O9:Q9) -> #DIV/0! | T9: 0.93846154 | U9: 0.94175824 | V9: 0.95384615 | W9: 0.91029412 | X9: 0.925 | Y9: 0.91470588 | Z9: =AVERAGE(T9:Y9) -> 0.93067766 | AA9: =_xlfn.STDEV.S(T9:Y9) -> 0.016869911
A10: 6 | B10: 120 | C10: 1402 | D10: 1390 | E10: 1422 | F10: 1416 | G10: 1412 | H10: =ROUNDDOWN(AVERAGE(C10:G10),0) -> 1408 | I10: =_xlfn.STDEV.S(C10:G10) -> 12.601587 | K10: 0.959 | M10: =AVERAGE(J10:L10) -> 0.959 | N10: =_xlfn.STDEV.S(J10:L10) -> #DIV/0! | P10: 0.038 | R10: =AVERAGE(O10:Q10) -> 0.038 | S10: =_xlfn.STDEV.S(O10:Q10) -> #DIV/0! | T10: 0.94945055 | U10: 0.95934066 | V10: 0.93956044 | W10: 0.92352941 | X10: 0.92205882 | Y10: 0.92794118 | Z10: =AVERAGE(T10:Y10) -> 0.93698018 | AA10: =_xlfn.STDEV.S(T10:Y10) -> 0.015148812
A11: 7 | B11: 140 | C11: 1383 | D11: 1397 | E11: 1380 | F11: 1386 | G11: 1384 | H11: =ROUNDDOWN(AVERAGE(C11:G11),0) -> 1386 | I11: =_xlfn.STDEV.S(C11:G11) -> 6.5192024 | K11: 0.924 | M11: =AVERAGE(J11:L11) -> 0.924 | N11: =_xlfn.STDEV.S(J11:L11) -> #DIV/0! | P11: 0.043 | R11: =AVERAGE(O11:Q11) -> 0.043 | S11: =_xlfn.STDEV.S(O11:Q11) -> #DIV/0! | T11: 0.95384615 | U11: 0.95494505 | V11: 0.95494505 | W11: 0.925 | X11: 0.93970588 | Y11: 0.92941176 | Z11: =AVERAGE(T11:Y11) -> 0.94297565 | AA11: =_xlfn.STDEV.S(T11:Y11) -> 0.013583045
A12: 8 | B12: 160 | C12: 1374 | D12: 1360 | E12: 1357 | F12: 1374 | G12: 1356 | H12: =ROUNDDOWN(AVERAGE(C12:G12),0) -> 1364 | I12: =_xlfn.STDEV.S(C12:G12) -> 9.0664216 | K12: 0.978 | M12: =AVERAGE(J12:L12) -> 0.978 | N12: =_xlfn.STDEV.S(J12:L12) -> #DIV/0! | P12: 0.0444 | R12: =AVERAGE(O12:Q12) -> 0.0444 | S12: =_xlfn.STDEV.S(O12:Q12) -> #DIV/0! | T12: 0.95494505 | U12: 0.95604396 | V12: 0.96813187 | W12: 0.94705882 | X12: 0.92941176 | Y12: 0.93676471 | Z12: =AVERAGE(T12:Y12) -> 0.94872603 | AA12: =_xlfn.STDEV.S(T12:Y12) -> 0.014054953
A13: 9 | B13: 180 | C13: 1349 | D13: 1341 | E13: 1356 | F13: 1363 | G13: 1348 | H13: =ROUNDDOWN(AVERAGE(C13:G13),0) -> 1351 | I13: =_xlfn.STDEV.S(C13:G13) -> 8.3845095 | K13: 0.9106 | M13: =AVERAGE(J13:L13) -> 0.9106 | N13: =_xlfn.STDEV.S(J13:L13) -> #DIV/0! | P13: 0.046 | R13: =AVERAGE(O13:Q13) -> 0.046 | S13: =_xlfn.STDEV.S(O13:Q13) -> #DIV/0! | T13: 0.95714286 | U13: 0.96373626 | V13: 0.97142857 | W13: 0.94117647 | X13: 0.93970588 | Y13: 0.93676471 | Z13: =AVERAGE(T13:Y13) -> 0.95165913 | AA13: =_xlfn.STDEV.S(T13:Y13) -> 0.014431697
A14: Final | B14: 200 | C14: 1353 | D14: 1350 | E14: 1342 | F14: 1359 | G14: 1336 | H14: =ROUNDDOWN(AVERAGE(C14:G14),0) -> 1348 | I14: =_xlfn.STDEV.S(C14:G14) -> 9.0829511 | K14: 1.0148 | M14: =AVERAGE(J14:L14) -> 1.0148 | N14: =_xlfn.STDEV.S(J14:L14) -> #DIV/0! | P14: 0.0556 | R14: =AVERAGE(O14:Q14) -> 0.0556 | S14: =_xlfn.STDEV.S(O14:Q14) -> #DIV/0! | T14: 0.96813187 | U14: 0.96703297 | V14: 0.98571429 | W14: 0.94264706 | X14: 0.93970588 | Y14: 0.94705882 | Z14: =AVERAGE(T14:Y14) -> 0.95838181 | AA14: =_xlfn.STDEV.S(T14:Y14) -> 0.018119344

Sheet Lote 3
A2: Muestra | B2: Tiempo [min] | C2: Pellets/g | H2: m | I2: s | J2: Diametro [mm] Microscopio | M2: m | N2: s | O2: Espesor [mm] Microscopio | R2: m | S2: s | T2: Densidad 00 [g/ml] | W2: Densidad 0 [g/ml] | Z2: m | AA2: s
C3: 1 | D3: 2 | E3: 3 | F3: 4 | G3: 5 | J3: 1 | K3: 2 | L3: 3 | O3: 1 | P3: 2 | Q3: 3 | T3: 1 | U3: 2 | V3: 3 | W3: 1 | X3: 2 | Y3: 3
A4: 0 | B4: 0 | C4: 1532 | D4: 1514 | E4: 1525 | F4: 1522 | G4: 1539 | H4: =ROUNDDOWN(AVERAGE(C4:G4),0) -> 1526 | I4: =_xlfn.STDEV.S(C4:G4) -> 9.5551033 | J4: 0.979 | M4: =AVERAGE(J4:L4) -> 0.979 | N4: =_xlfn.STDEV.S(J4:L4) -> #DIV/0! | O4: 0 | R4: =AVERAGE(O4:Q4) -> 0 | S4: =_xlfn.STDEV.S(O4:Q4) -> #DIV/0! | T4: 0.9165 | U4: 0.9187 | V4: 0.9198 | W4: 0.8838 | X4: 0.8794 | Y4: 0.8765 | Z4: =AVERAGE(T4:Y4) -> 0.89911667 | AA4: =_xlfn.STDEV.S(T4:Y4) -> 0.021205416
A5: 1 | B5: 20 | C5: 1484 | D5: 1503 | E5: 1493 | F5: 1523 | G5: 1512 | H5: =ROUNDDOWN(AVERAGE(C5:G5),0) -> 1503 | I5: =_xlfn.STDEV.S(C5:G5) -> 15.346009 | J5: 0.936 | M5: =AVERAGE(J5:L5) -> 0.936 | N5: =_xlfn.STDEV.S(J5:L5) -> #DIV/0! | O5: 0.012 | R5: =AVERAGE(O5:Q5) -> 0.012 | S5: =_xlfn.STDEV.S(O5:Q5) -> #DIV/0! | T5: 0.92087912 | U5: 0.93736264 | V5: 0.92087912 | W5: 0.89264706 | X5: 0.90294118 | Y5: 0.90735294 | Z5: =AVERAGE(T5:Y5) -> 0.91367701 | AA5: =_xlfn.STDEV.S(T5:Y5) -> 0.015888742
A6: 2 | B6: 40 | C6: 1478 | D6: 1470 | E6: 1491 | F6: 1473 | G6: 1495 | H6: =ROUNDDOWN(AVERAGE(C6:G6),0) -> 1481 | I6: =_xlfn.STDEV.S(C6:G6) -> 11.058933 | J6: 0.936 | M6: =AVERAGE(J6:L6) -> 0.936 | N6: =_xlfn.STDEV.S(J6:L6) -> #DIV/0! | O6: 0.014 | R6: =AVERAGE(O6:Q6) -> 0.014 | S6: =_xlfn.STDEV.S(O6:Q6) -> #DIV/0! | T6: 0.93736264 | U6: 0.92967033 | V6: 0.93296703 | W6: 0.91176471 | X6: 0.90441176 | Y6: 0.90441176 | Z6: =AVERAGE(T6:Y6) -> 0.92009804 | AA6: =_xlfn.STDEV.S(T6:Y6) -> 0.014945695
A7: 3 | B7: 60 | C7: 1468 | D7: 1470 | E7: 1458 | F7: 1450 | G7: 1444 | H7: =ROUNDDOWN(AVERAGE(C7:G7),0) -> 1458 | I7: =_xlfn.STDEV.S(C7:G7) -> 11.224972 | J7: 0.832 | M7: =AVERAGE(J7:L7) -> 0.832 | N7: =_xlfn.STDEV.S(J7:L7) -> #DIV/0! | O7: 0.018 | R7: =AVERAGE(O7:Q7) -> 0.018 | S7: =_xlfn.STDEV.S(O7:Q7) -> #DIV/0! | T7: 0.93076923 | U7: 0.94505495 | V7: 0.93296703 | W7: 0.90735294 | X7: 0.90147059 | Y7: 0.91911765 | Z7: =AVERAGE(T7:Y7) -> 0.92278873 | AA7: =_xlfn.STDEV.S(T7:Y7) -> 0.01654856
A8: 4 | B8: 80 | C8: 1429 | D8: 1448 | E8: 1449 | F8: 1454 | G8: 1445 | H8: =ROUNDDOWN(AVERAGE(C8:G8),0) -> 1445 | I8: =_xlfn.STDEV.S(C8:G8) -> 9.5131488 | J8: 0.904 | M8: =AVERAGE(J8:L8) -> 0.904 | N8: =_xlfn.STDEV.S(J8:L8) -> #DIV/0! | O8: 0.019 | R8: =AVERAGE(O8:Q8) -> 0.019 | S8: =_xlfn.STDEV.S(O8:Q8) -> #DIV/0! | T8: 0.92967033 | U8: 0.94175824 | V8: 0.95274725 | W8: 0.91323529 | X8: 0.90735294 | Y8: 0.92058824 | Z8: =AVERAGE(T8:Y8) -> 0.92755872 | AA8: =_xlfn.STDEV.S(T8:Y8) -> 0.017335335
A9: 5 | B9: 100 | C9: 1397 | D9: 1415 | E9: 1404 | F9: 1390 | G9: 1385 | H9: =ROUNDDOWN(AVERAGE(C9:G9),0) -> 1398 | I9: =_xlfn.STDEV.S(C9:G9) -> 11.819475 | J9: 0.91 | M9: =AVERAGE(J9:L9) -> 0.91 | N9: =_xlfn.STDEV.S(J9:L9) -> #DIV/0! | O9: 0.02 | R9: =AVERAGE(O9:Q9) -> 0.02 | S9: =_xlfn.STDEV.S(O9:Q9) -> #DIV/0! | T9: 0.94065934 | U9: 0.94285714 | V9: 0.94725275 | W9: 0.91029412 | X9: 0.91617647 | Y9: 0.91911765 | Z9: =AVERAGE(T9:Y9) -> 0.92939291 | AA9: =_xlfn.STDEV.S(T9:Y9) -> 0.015951244
A10: 6 | B10: 120 | C10: 1388 | D10: 1396 | E10: 1376 | F10: 1366 | G10: 1392 | H10: =ROUNDDOWN(AVERAGE(C10:G10),0) -> 1383 | I10: =_xlfn.STDEV.S(C10:G10) -> 12.36123 | J10: 0.922 | M10: =AVERAGE(J10:L10) -> 0.922 | N10: =_xlfn.STDEV.S(J10:L10) -> #DIV/0! | O10: 0.023 | R10: =AVERAGE(O10:Q10) -> 0.023 | S10: =_xlfn.STDEV.S(O10:Q10) -> #DIV/0! | T10: 0.95494505 | U10: 0.93956044 | V10: 0.95494505 | W10: 0.91470588 | X10: 0.91764706 | Y10: 0.92352941 | Z10: =AVERAGE(T10:Y10) -> 0.93422215 | AA10: =_xlfn.STDEV.S(T10:Y10) -> 0.018206196
A11: 7 | B11: 140 | C11: 1375 | D11: 1383 | E11: 1363 | F11: 1359 | G11: 1350 | H11: =ROUNDDOWN(AVERAGE(C11:G11),0) -> 1366 | I11: =_xlfn.STDEV.S(C11:G11) -> 13.076697 | J11: 0.905 | M11: =AVERAGE(J11:L11) -> 0.905 | N11: =_xlfn.STDEV.S(J11:L11) -> #DIV/0! | O11: 0.024 | R11: =AVERAGE(O11:Q11) -> 0.024 | S11: =_xlfn.STDEV.S(O11:Q11) -> #DIV/0! | T11: 0.95274725 | U11: 0.95824176 | V11: 0.96043956 | W11: 0.925 | X11: 0.91617647 | Y11: 0.91911765 | Z11: =AVERAGE(T11:Y11) -> 0.93862045 | AA11: =_xlfn.STDEV.S(T11:Y11) -> 0.02064095
A12: 8 | B12: 160 | C12: 1346 | D12: 1332 | E12: 1350 | F12: 1351 | G12: 1356 | H12: =ROUNDDOWN(AVERAGE(C12:G12),0) -> 1347 | I12: =_xlfn.STDEV.S(C12:G12) -> 9.1104336 | J12: 0.97 | M12: =AVERAGE(J12:L12) -> 0.97 | N12: =_xlfn.STDEV.S(J12:L12) -> #DIV/0! | O12: 0.027 | R12: =AVERAGE(O12:Q12) -> 0.027 | S12: =_xlfn.STDEV.S(O12:Q12) -> #DIV/0! | T12: 0.96373626 | U12: 0.95054945 | V12: 0.96373626 | W12: 0.92205882 | X12: 0.93235294 | Y12: 0.925 | Z12: =AVERAGE(T12:Y12) -> 0.94290562 | AA12: =_xlfn.STDEV.S(T12:Y12) -> 0.01893578
A13: 9 | B13: 180 | C13: 1336 | D13: 1303 | E13: 1324 | F13: 1342 | G13: 1317 | H13: =ROUNDDOWN(AVERAGE(C13:G13),0) -> 1324 | I13: =_xlfn.STDEV.S(C13:G13) -> 15.469324 | J13: 0.925 | M13: =AVERAGE(J13:L13) -> 0.925 | N13: =_xlfn.STDEV.S(J13:L13) -> #DIV/0! | O13: 0.025 | R13: =AVERAGE(O13:Q13) -> 0.025 | S13: =_xlfn.STDEV.S(O13:Q13) -> #DIV/0! | T13: 0.96703297 | U13: 0.96373626 | V13: 0.95604396 | W13: 0.92941176 | X13: 0.93235294 | Y13: 0.93529412 | Z13: =AVERAGE(T13:Y13) -> 0.947312 | AA13: =_xlfn.STDEV.S(T13:Y13) -> 0.016873301
A14: Final | B14: 200 | C14: 1322 | D14: 1325 | E14: 1344 | F14: 1329 | G14: 1331 | H14: =ROUNDDOWN(AVERAGE(C14:G14),0) -> 1330 | I14: =_xlfn.STDEV.S(C14:G14) -> 8.4675853 | J14: 0.966 | M14: =AVERAGE(J14:L14) -> 0.966 | N14: =_xlfn.STDEV.S(J14:L14) -> #DIV/0! | O14: 0.031 | R14: =AVERAGE(O14:Q14) -> 0.031 | S14: =_xlfn.STDEV.S(O14:Q14) -> #DIV/0! | T14: 0.97142857 | U14: 0.97582418 | V14: 0.98021978 | W14: 0.95147059 | X14: 0.93529412 | Y14: 0.94558824 | Z14: =AVERAGE(T14:Y14) -> 0.95997091 | AA14: =_xlfn.STDEV.S(T14:Y14) -> 0.018334021

Sheet Lote 4
A2: Muestra | B2: Tiempo [min] | C2: Pellets/g | H2: m | I2: s | J2: Diametro [mm] Microscopio | M2: m | N2: s | O2: Espesor [mm] Microscopio | R2: m | S2: s | T2: Densidad 00 [g/ml] | Y2: Densidad 0 [g/ml] | AD2: m | AE2: s
C3: 1 | D3: 2 | E3: 3 | F3: 4 | G3: 5 | J3: 1 | K3: 2 | L3: 3 | O3: 1 | P3: 2 | Q3: 3 | T3: 1 | U3: 2 | V3: 3 | W3: 4 | X3: 5 | Y3: 1 | Z3: 2 | AA3: 3 | AB3: 4 | AC3: 5
A4: 0 | B4: 0 | C4: 1514 | D4: 1488 | E4: 1499 | F4: 1501 | G4: 1512 | H4: =ROUNDDOWN(AVERAGE(C4:G4),0) -> 1502 | I4: =_xlfn.STDEV.S(C4:G4) -> 10.568822 | K4: 0.9984 | M4: =AVERAGE(J4:L4) -> 0.9984 | N4: =_xlfn.STDEV.S(J4:L4) -> #DIV/0! | P4: 0 | R4: =AVERAGE(O4:Q4) -> 0 | S4: =_xlfn.STDEV.S(O4:Q4) -> #DIV/0! | T4: 0.9143 | U4: 0.922 | V4: 0.9187 | Y4: 0.8706 | Z4: 0.8809 | AA4: 0.8794 | AD4: =AVERAGE(T4:AC4) -> 0.89765 | AE4: =_xlfn.STDEV.S(T4:AC4) -> 0.023058946
A5: 1 | B5: 20 | C5: 1475 | D5: 1488 | E5: 1491 | F5: 1504 | G5: 1529 | H5: =ROUNDDOWN(AVERAGE(C5:G5),0) -> 1497 | I5: =_xlfn.STDEV.S(C5:G5) -> 20.452384 | K5: 0.9349 | M5: =AVERAGE(J5:L5) -> 0.9349 | N5: =_xlfn.STDEV.S(J5:L5) -> #DIV/0! | P5: 0.0143 | R5: =AVERAGE(O5:Q5) -> 0.0143 | S5: =_xlfn.STDEV.S(O5:Q5) -> #DIV/0! | T5: 0.92747253 | U5: 0.93406593 | V5: 0.92417582 | W5: 0.92417582 | X5: 0.92527473 | Y5: 0.90735294 | Z5: 0.90735294 | AA5: 0.90441176 | AB5: 0.90147059 | AC5: 0.89117647 | AD5: =AVERAGE(T5:AC5) -> 0.91469295 | AE5: =_xlfn.STDEV.S(T5:AC5) -> 0.014030775
A6: 2 | B6: 40 | C6: 1485 | D6: 1491 | E6: 1500 | F6: 1485 | G6: 1485 | H6: =ROUNDDOWN(AVERAGE(C6:G6),0) -> 1489 | I6: =_xlfn.STDEV.S(C6:G6) -> 6.5726707 | K6: 1.0032 | M6: =AVERAGE(J6:L6) -> 1.0032 | N6: =_xlfn.STDEV.S(J6:L6) -> #DIV/0! | P6: 0.0159 | R6: =AVERAGE(O6:Q6) -> 0.0159 | S6: =_xlfn.STDEV.S(O6:Q6) -> #DIV/0! | T6: 0.93406593 | U6: 0.93846154 | V6: 0.93516484 | W6: 0.93516484 | X6: 0.94175824 | Y6: 0.89705882 | Z6: 0.91029412 | AA6: 0.92058824 | AB6: 0.90588235 | AC6: 0.90735294 | AD6: =AVERAGE(T6:AC6) -> 0.92257919 | AE6: =_xlfn.STDEV.S(T6:AC6) -> 0.016280958
A7: 3 | B7: 60 | C7: 1452 | D7: 1464 | E7: 1453 | F7: 1471 | G7: 1471 | H7: =ROUNDDOWN(AVERAGE(C7:G7),0) -> 1462 | I7: =_xlfn.STDEV.S(C7:G7) -> 9.3112835 | K7: 0.9651 | M7: =AVERAGE(J7:L7) -> 0.9651 | N7: =_xlfn.STDEV.S(J7:L7) -> #DIV/0! | P7: 0.019 | R7: =AVERAGE(O7:Q7) -> 0.019 | S7: =_xlfn.STDEV.S(O7:Q7) -> #DIV/0! | T7: 0.93076923 | U7: 0.93736264 | V7: 0.93846154 | W7: 0.94505495 | X7: 0.94945055 | Y7: 0.91617647 | Z7: 0.90882353 | AA7: 0.90882353 | AB7: 0.90441176 | AC7: 0.91470588 | AD7: =AVERAGE(T7:AC7) -> 0.92540401 | AE7: =_xlfn.STDEV.S(T7:AC7) -> 0.016655947
A8: 4 | B8: 80 | C8: 1430 | D8: 1445 | E8: 1454 | F8: 1464 | G8: 1465 | H8: =ROUNDDOWN(AVERAGE(C8:G8),0) -> 1451 | I8: =_xlfn.STDEV.S(C8:G8) -> 14.570518 | K8: 0.946 | M8: =AVERAGE(J8:L8) -> 0.946 | N8: =_xlfn.STDEV.S(J8:L8) -> #DIV/0! | P8: 0.0222 | R8: =AVERAGE(O8:Q8) -> 0.0222 | S8: =_xlfn.STDEV.S(O8:Q8) -> #DIV/0! | T8: 0.93516484 | U8: 0.94285714 | V8: 0.95164835 | W8: 0.95274725 | X8: 0.95384615 | Y8: 0.90735294 | Z8: 0.91470588 | AA8: 0.93088235 | AB8: 0.92794118 | AC8: 0.91764706 | AD8: =AVERAGE(T8:AC8) -> 0.93347931 | AE8: =_xlfn.STDEV.S(T8:AC8) -> 0.016766583
A9: 5 | B9: 100 | C9: 1418 | D9: 1440 | E9: 1423 | F9: 1413 | G9: 1412 | H9: =ROUNDDOWN(AVERAGE(C9:G9),0) -> 1421 | I9: =_xlfn.STDEV.S(C9:G9) -> 11.388591 | K9: 0.9194 | M9: =AVERAGE(J9:L9) -> 0.9194 | N9: =_xlfn.STDEV.S(J9:L9) -> #DIV/0! | P9: 0.0302 | R9: =AVERAGE(O9:Q9) -> 0.0302 | S9: =_xlfn.STDEV.S(O9:Q9) -> #DIV/0! | T9: 0.94065934 | U9: 0.95714286 | V9: 0.94175824 | W9: 0.96263736 | X9: 0.96043956 | Y9: 0.92058824 | Z9: 0.93088235 | AA9: 0.91617647 | AB9: 0.92647059 | AC9: 0.92647059 | AD9: =AVERAGE(T9:AC9) -> 0.93832256 | AE9: =_xlfn.STDEV.S(T9:AC9) -> 0.016974131
A10: 6 | B10: 120 | C10: 1396 | D10: 1402 | E10: 1390 | F10: 1393 | G10: 1394 | H10: =ROUNDDOWN(AVERAGE(C10:G10),0) -> 1395 | I10: =_xlfn.STDEV.S(C10:G10) -> 4.472136 | K10: 0.91 | M10: =AVERAGE(J10:L10) -> 0.91 | N10: =_xlfn.STDEV.S(J10:L10) -> #DIV/0! | P10: 0.0349 | R10: =AVERAGE(O10:Q10) -> 0.0349 | S10: =_xlfn.STDEV.S(O10:Q10) -> #DIV/0! | T10: 0.93626374 | U10: 0.97912088 | V10: 0.96593407 | W10: 0.97692308 | X10: 0.93516484 | Y10: 0.92647059 | Z10: 0.92794118 | AA10: 0.92205882 | AB10: 0.93088235 | AC10: 0.93676471 | AD10: =AVERAGE(T10:AC10) -> 0.94375242 | AE10: =_xlfn.STDEV.S(T10:AC10) -> 0.021619972
A11: 7 | B11: 140 | C11: 1386 | D11: 1388 | E11: 1398 | F11: 1369 | G11: 1372 | H11: =ROUNDDOWN(AVERAGE(C11:G11),0) -> 1382 | I11: =_xlfn.STDEV.S(C11:G11) -> 11.991664 | K11: 0.8811 | M11: =AVERAGE(J11:L11) -> 0.8811 | N11: =_xlfn.STDEV.S(J11:L11) -> #DIV/0! | P11: 0.0365 | R11: =AVERAGE(O11:Q11) -> 0.0365 | S11: =_xlfn.STDEV.S(O11:Q11) -> #DIV/0! | T11: 0.94725275 | U11: 0.96153846 | V11: 0.96483516 | W11: 0.96263736 | X11: 0.96593407 | Y11: 0.94264706 | Z11: 0.93676471 | AA11: 0.92794118 | AB11: 0.92352941 | AC11: 0.92941176 | AD11: =AVERAGE(T11:AC11) -> 0.94624919 | AE11: =_xlfn.STDEV.S(T11:AC11) -> 0.016580026
A12: 8 | B12: 160 | C12: 1345 | D12: 1368 | E12: 1334 | F12: 1363 | G12: 1371 | H12: =ROUNDDOWN(AVERAGE(C12:G12),0) -> 1356 | I12: =_xlfn.STDEV.S(C12:G12) -> 15.990622 | K12: 0.954 | M12: =AVERAGE(J12:L12) -> 0.954 | N12: =_xlfn.STDEV.S(J12:L12) -> #DIV/0! | P12: 0.0413 | R12: =AVERAGE(O12:Q12) -> 0.0413 | S12: =_xlfn.STDEV.S(O12:Q12) -> #DIV/0! | T12: 0.97582418 | U12: 0.95714286 | V12: 0.96153846 | W12: 0.96813187 | X12: 0.96703297 | Y12: 0.92941176 | Z12: 0.94411765 | AA12: 0.93382353 | AB12: 0.93823529 | AC12: 0.95 | AD12: =AVERAGE(T12:AC12) -> 0.95252586 | AE12: =_xlfn.STDEV.S(T12:AC12) -> 0.01586294
A13: 9 | B13: 180 | C13: 1328 | D13: 1327 | E13: 1335 | F13: 1337 | G13: 1344 | H13: =ROUNDDOWN(AVERAGE(C13:G13),0) -> 1334 | I13: =_xlfn.STDEV.S(C13:G13) -> 6.9785385 | K13: 0.9366 | M13: =AVERAGE(J13:L13) -> 0.9366 | N13: =_xlfn.STDEV.S(J13:L13) -> #DIV/0! | P13: 0.0448 | R13: =AVERAGE(O13:Q13) -> 0.0448 | S13: =_xlfn.STDEV.S(O13:Q13) -> #DIV/0! | T13: 0.98681319 | U13: 0.98241758 | V13: 0.96153846 | W13: 0.95164835 | X13: 0.98461538 | Y13: 0.94117647 | Z13: 0.95147059 | AA13: 0.94705882 | AB13: 0.93970588 | AC13: 0.94264706 | AD13: =AVERAGE(T13:AC13) -> 0.95890918 | AE13: =_xlfn.STDEV.S(T13:AC13) -> 0.018841904
A14: Final | B14: 200 | C14: 1349 | D14: 1337 | E14: 1326 | F14: 1326 | G14: 1317 | H14: =ROUNDDOWN(AVERAGE(C14:G14),0) -> 1331 | I14: =_xlfn.STDEV.S(C14:G14) -> 12.308534 | K14: 0.9204 | M14: =AVERAGE(J14:L14) -> 0.9204 | N14: =_xlfn.STDEV.S(J14:L14) -> #DIV/0! | P14: 0.0508 | R14: =AVERAGE(O14:Q14) -> 0.0508 | S14: =_xlfn.STDEV.S(O14:Q14) -> #DIV/0! | T14: 0.97802198 | U14: 0.97472527 | V14: 0.97472527 | W14: 0.98131868 | X14: 0.97362637 | Y14: 0.94117647 | Z14: 0.95147059 | AA14: 0.95 | AB14: 0.95294118 | AC14: 0.94117647 | AD14: =AVERAGE(T14:AC14) -> 0.96191823 | AE14: =_xlfn.STDEV.S(T14:AC14) -> 0.015961954

Sheet %Ganancia
A1: Lote 1
A2: Conteo de pellet/g | K2: Ganancia en peso [g] | S2: % de Ganancia
A3: Muestra | B3: Tiempo | C3: 1 | D3: 2 | E3: 3 | F3: 4 | G3: 5 | H3: m | I3: s | K3: Tiempo | L3: 1 | M3: 2 | N3: 3 | O3: 4 | P3: 5 | Q3: m | S3: Tiempo | T3: 1 | U3: 2 | V3: 3 | W3: 4 | X3: 5 | Y3: m
A4: Desnudo | B4: 0 | C4: ='Lote 1'!C4 -> 1523 | D4: ='Lote 1'!D4 -> 1499 | E4: ='Lote 1'!E4 -> 1493 | F4: ='Lote 1'!F4 -> 1496 | G4: ='Lote 1'!G4 -> 1501 | H4: =ROUND(AVERAGE(C4:G4),0) -> 1502 | I4: =_xlfn.STDEV.S(C4:G4) -> 11.907981 | K4: 0 | L4: =1/C4 -> 0.00065659882 | M4: =1/D4 -> 0.00066711141 | N4: =1/E4 -> 0.00066979236 | O4: =1/F4 -> 0.0006684492 | P4: =1/G4 -> 0.00066622252 | Q4: =AVERAGE(L4:P4) -> 0.00066563486 | S4: 0 | T4: 0 | U4: 0 | V4: 0 | W4: 0 | X4: 0 | Y4: 0
A5: 1 | B5: 20 | C5: ='Lote 1'!C5 -> 1491 | D5: ='Lote 1'!D5 -> 1515 | E5: ='Lote 1'!E5 -> 1512 | F5: ='Lote 1'!F5 -> 1524 | G5: ='Lote 1'!G5 -> 1510 | H5: =ROUND(AVERAGE(C5:G5),0) -> 1510 | I5: =_xlfn.STDEV.S(C5:G5) -> 12.095454 | K5: 20 | L5: =1/C5 -> 0.00067069081 | M5: =1/D5 -> 0.00066006601 | N5: =1/E5 -> 0.00066137566 | O5: =1/F5 -> 0.00065616798 | P5: =1/G5 -> 0.00066225166 | Q5: =AVERAGE(L5:P5) -> 0.00066211042 | S5: 20 | T5: =(L5-$M$61)/$M$61 -> 0.013749162 | U5: =(M5-$M$61)/$M$61 -> -0.002310231 | V5: =(N5-$M$61)/$M$61 -> -0.00033068783 | W5: =(O5-$M$61)/$M$61 -> -0.0082020997 | X5: =(P5-$M$61)/$M$61 -> 0.00099337748 | Y5: =AVERAGE(T5:X5) -> 0.00077990411
A6: 2 | B6: 40 | C6: ='Lote 1'!C6 -> 1485 | D6: ='Lote 1'!D6 -> 1490 | E6: ='Lote 1'!E6 -> 1507 | F6: ='Lote 1'!F6 -> 1511 | G6: ='Lote 1'!G6 -> 1500 | H6: =ROUND(AVERAGE(C6:G6),0) -> 1499 | I6: =_xlfn.STDEV.S(C6:G6) -> 11.013628 | K6: 40 | L6: =1/C6 -> 0.00067340067 | M6: =1/D6 -> 0.00067114094 | N6: =1/E6 -> 0.00066357001 | O6: =1/F6 -> 0.00066181337 | P6: =1/G6 -> 0.00066666667 | Q6: =AVERAGE(L6:P6) -> 0.00066731833 | S6: 40 | T6: =(L6-$M$61)/$M$61 -> 0.017845118 | U6: =(M6-$M$61)/$M$61 -> 0.01442953 | V6: =(N6-$M$61)/$M$61 -> 0.002986065 | W6: =(O6-$M$61)/$M$61 -> 0.00033090668 | X6: =(P6-$M$61)/$M$61 -> 0.0076666667 | Y6: =AVERAGE(T6:X6) -> 0.0086516573
A7: 3 | B7: 60 | C7: ='Lote 1'!C7 -> 1473 | D7: ='Lote 1'!D7 -> 1489 | E7: ='Lote 1'!E7 -> 1480 | F7: ='Lote 1'!F7 -> 1457 | G7: ='Lote 1'!G7 -> 1489 | H7: =ROUND(AVERAGE(C7:G7),0) -> 1478 | I7: =_xlfn.STDEV.S(C7:G7) -> 13.334167 | K7: 60 | L7: =1/C7 -> 0.00067888663 | M7: =1/D7 -> 0.00067159167 | N7: =1/E7 -> 0.00067567568 | O7: =1/F7 -> 0.0006863418 | P7: =1/G7 -> 0.00067159167 | Q7: =AVERAGE(L7:P7) -> 0.00067681749 | S7: 60 | T7: =(L7-$M$61)/$M$61 -> 0.026137135 | U7: =(M7-$M$61)/$M$61 -> 0.015110813 | V7: =(N7-$M$61)/$M$61 -> 0.021283784 | W7: =(O7-$M$61)/$M$61 -> 0.037405628 | X7: =(P7-$M$61)/$M$61 -> 0.015110813 | Y7: =AVERAGE(T7:X7) -> 0.023009634
A8: 5 | B8: 80 | C8: ='Lote 1'!C8 -> 1439 | D8: ='Lote 1'!D8 -> 1450 | E8: ='Lote 1'!E8 -> 1471 | F8: ='Lote 1'!F8 -> 1477 | G8: ='Lote 1'!G8 -> 1448 | H8: =ROUND(AVERAGE(C8:G8),0) -> 1457 | I8: =_xlfn.STDEV.S(C8:G8) -> 16.201852 | K8: 80 | L8: =1/C8 -> 0.00069492703 | M8: =1/D8 -> 0.00068965517 | N8: =1/E8 -> 0.00067980965 | O8: =1/F8 -> 0.00067704807 | P8: =1/G8 -> 0.00069060773 | Q8: =AVERAGE(L8:P8) -> 0.00068640953 | S8: 80 | T8: =(L8-$M$61)/$M$61 -> 0.05038221 | U8: =(M8-$M$61)/$M$61 -> 0.042413793 | V8: =(N8-$M$61)/$M$61 -> 0.027532291 | W8: =(O8-$M$61)/$M$61 -> 0.023358158 | X8: =(P8-$M$61)/$M$61 -> 0.043853591 | Y8: =AVERAGE(T8:X8) -> 0.037508009
A9: 7 | B9: 100 | C9: ='Lote 1'!C9 -> 1441 | D9: ='Lote 1'!D9 -> 1431 | E9: ='Lote 1'!E9 -> 1443 | F9: ='Lote 1'!F9 -> 1440 | G9: ='Lote 1'!G9 -> 1460 | H9: =ROUND(AVERAGE(C9:G9),0) -> 1443 | I9: =_xlfn.STDEV.S(C9:G9) -> 10.559356 | K9: 100 | L9: =1/C9 -> 0.00069396253 | M9: =1/D9 -> 0.00069881202 | N9: =1/E9 -> 0.00069300069 | O9: =1/F9 -> 0.00069444444 | P9: =1/G9 -> 0.00068493151 | Q9: =AVERAGE(L9:P9) -> 0.00069303024 | S9: 100 | T9: =(L9-$M$61)/$M$61 -> 0.048924358 | U9: =(M9-$M$61)/$M$61 -> 0.056254368 | V9: =(N9-$M$61)/$M$61 -> 0.047470547 | W9: =(O9-$M$61)/$M$61 -> 0.049652778 | X9: =(P9-$M$61)/$M$61 -> 0.035273973 | Y9: =AVERAGE(T9:X9) -> 0.047515205
A10: 9 | B10: 120 | C10: ='Lote 1'!C10 -> 1399 | D10: ='Lote 1'!D10 -> 1395 | E10: ='Lote 1'!E10 -> 1411 | F10: ='Lote 1'!F10 -> 1396 | G10: ='Lote 1'!G10 -> 1419 | H10: =ROUND(AVERAGE(C10:G10),0) -> 1404 | I10: =_xlfn.STDEV.S(C10:G10) -> 10.535654 | K10: 120 | L10: =1/C10 -> 0.00071479628 | M10: =1/D10 -> 0.00071684588 | N10: =1/E10 -> 0.00070871722 | O10: =1/F10 -> 0.00071633238 | P10: =1/G10 -> 0.00070472163 | Q10: =AVERAGE(L10:P10) -> 0.00071228268 | S10: 120 | T10: =(L10-$M$61)/$M$61 -> 0.080414582 | U10: =(M10-$M$61)/$M$61 -> 0.083512545 | V10: =(N10-$M$61)/$M$61 -> 0.071226081 | W10: =(O10-$M$61)/$M$61 -> 0.08273639 | X10: =(P10-$M$61)/$M$61 -> 0.065186751 | Y10: =AVERAGE(T10:X10) -> 0.07661527
A11: 10 | B11: 140 | C11: ='Lote 1'!C11 -> 1388 | D11: ='Lote 1'!D11 -> 1375 | E11: ='Lote 1'!E11 -> 1392 | F11: ='Lote 1'!F11 -> 1400 | G11: ='Lote 1'!G11 -> 1397 | H11: =ROUND(AVERAGE(C11:G11),0) -> 1390 | I11: =_xlfn.STDEV.S(C11:G11) -> 9.7621719 | K11: 140 | L11: =1/C11 -> 0.0007204611 | M11: =1/D11 -> 0.00072727273 | N11: =1/E11 -> 0.0007183908 | O11: =1/F11 -> 0.00071428571 | P11: =1/G11 -> 0.00071581961 | Q11: =AVERAGE(L11:P11) -> 0.00071924599 | S11: 140 | T11: =(L11-$M$61)/$M$61 -> 0.088976945 | U11: =(M11-$M$61)/$M$61 -> 0.099272727 | V11: =(N11-$M$61)/$M$61 -> 0.085847701 | W11: =(O11-$M$61)/$M$61 -> 0.079642857 | X11: =(P11-$M$61)/$M$61 -> 0.081961346 | Y11: =AVERAGE(T11:X11) -> 0.087140315
A12: 11 | B12: 160 | C12: ='Lote 1'!C12 -> 1380 | D12: ='Lote 1'!D12 -> 1380 | E12: ='Lote 1'!E12 -> 1375 | F12: ='Lote 1'!F12 -> 1379 | G12: ='Lote 1'!G12 -> 1380 | H12: =ROUND(AVERAGE(C12:G12),0) -> 1379 | I12: =_xlfn.STDEV.S(C12:G12) -> 2.1679483 | K12: 160 | L12: =1/C12 -> 0.00072463768 | M12: =1/D12 -> 0.00072463768 | N12: =1/E12 -> 0.00072727273 | O12: =1/F12 -> 0.00072516316 | P12: =1/G12 -> 0.00072463768 | Q12: =AVERAGE(L12:P12) -> 0.00072526979 | S12: 160 | T12: =(L12-$M$61)/$M$61 -> 0.095289855 | U12: =(M12-$M$61)/$M$61 -> 0.095289855 | V12: =(N12-$M$61)/$M$61 -> 0.099272727 | W12: =(O12-$M$61)/$M$61 -> 0.096084119 | X12: =(P12-$M$61)/$M$61 -> 0.095289855 | Y12: =AVERAGE(T12:X12) -> 0.096245282
A13: 13 | B13: 180 | C13: ='Lote 1'!C13 -> 1359 | D13: ='Lote 1'!D13 -> 1376 | E13: ='Lote 1'!E13 -> 1383 | F13: ='Lote 1'!F13 -> 1379 | G13: ='Lote 1'!G13 -> 1382 | H13: =ROUND(AVERAGE(C13:G13),0) -> 1376 | I13: =_xlfn.STDEV.S(C12:G12) -> 2.1679483 | K13: 180 | L13: =1/C13 -> 0.00073583517 | M13: =1/D13 -> 0.00072674419 | N13: =1/E13 -> 0.0007230658 | O13: =1/F13 -> 0.00072516316 | P13: =1/G13 -> 0.000723589 | Q13: =AVERAGE(L13:P13) -> 0.00072687946 | S13: 180 | T13: =(L13-$M$61)/$M$61 -> 0.11221486 | U13: =(M13-$M$61)/$M$61 -> 0.098473837 | V13: =(N13-$M$61)/$M$61 -> 0.092913955 | W13: =(O13-$M$61)/$M$61 -> 0.096084119 | X13: =(P13-$M$61)/$M$61 -> 0.093704776 | Y13: =AVERAGE(T13:X13) -> 0.09867831
A14: Final | B14: 210 | C14: ='Lote 1'!C14 -> 1345 | D14: ='Lote 1'!D14 -> 1341 | E14: ='Lote 1'!E14 -> 1344 | F14: ='Lote 1'!F14 -> 1356 | G14: ='Lote 1'!G14 -> 1340 | H14: =ROUND(AVERAGE(C14:G14),0) -> 1345 | I14: =_xlfn.STDEV.S(C14:G14) -> 6.3796552 | K14: 210 | L14: =1/C14 -> 0.00074349442 | M14: =1/D14 -> 0.00074571216 | N14: =1/E14 -> 0.00074404762 | O14: =1/F14 -> 0.00073746313 | P14: =1/G14 -> 0.00074626866 | Q14: =AVERAGE(L14:P14) -> 0.0007433972 | S14: 210 | T14: =(L14-$M$61)/$M$61 -> 0.12379182 | U14: =(M14-$M$61)/$M$61 -> 0.12714392 | V14: =(N14-$M$61)/$M$61 -> 0.12462798 | W14: =(O14-$M$61)/$M$61 -> 0.11467552 | X14: =(P14-$M$61)/$M$61 -> 0.12798507 | Y14: =AVERAGE(T14:X14) -> 0.12364486
A16: Lote 2
A17: Conteo de pellet/g | K17: Ganancia en peso [g] | S17: % de Ganancia
A18: Muestra | B18: Tiempo | C18: 1 | D18: 2 | E18: 3 | F18: 4 | G18: 5 | H18: m | I18: s | K18: Tiempo | L18: 1 | M18: 2 | N18: 3 | O18: 4 | P18: 5 | Q18: m | S18: Tiempo | T18: 1 | U18: 2 | V18: 3 | W18: 4 | X18: 5 | Y18: m
A19: Desnudo | B19: 0 | C19: ='Lote 2'!C4 -> 1529 | D19: ='Lote 2'!D4 -> 1519 | E19: ='Lote 2'!E4 -> 1503 | F19: ='Lote 2'!F4 -> 1512 | G19: ='Lote 2'!G4 -> 1512 | H19: =ROUND(AVERAGE(C19:G19),0) -> 1515 | I19: =_xlfn.STDEV.S(C19:G19) -> 9.6695398 | K19: 0 | L19: =1/C19 -> 0.00065402224 | M19: =1/D19 -> 0.00065832785 | N19: =1/E19 -> 0.00066533599 | O19: =1/F19 -> 0.00066137566 | P19: =1/G19 -> 0.00066137566 | Q19: =AVERAGE(L19:P19) -> 0.00066008748 | S19: 0 | T19: 0 | U19: 0 | V19: 0 | W19: 0 | X19: 0 | Y19: 0
A20: 1 | B20: 20 | C20: ='Lote 2'!C5 -> 1518 | D20: ='Lote 2'!D5 -> 1509 | E20: ='Lote 2'!E5 -> 1522 | F20: ='Lote 2'!F5 -> 1518 | G20: ='Lote 2'!G5 -> 1540 | H20: =ROUND(AVERAGE(C20:G20),0) -> 1521 | I20: =_xlfn.STDEV.S(C20:G20) -> 11.436783 | K20: 20 | L20: =1/C20 -> 0.00065876153 | M20: =1/D20 -> 0.00066269052 | N20: =1/E20 -> 0.00065703022 | O20: =1/F20 -> 0.00065876153 | P20: =1/G20 -> 0.00064935065 | Q20: =AVERAGE(L20:P20) -> 0.00065731889 | S20: 20 | T20: =ABS((L20-$M$61)/$M$61) -> 0.0042819499 | U20: =ABS((M20-$M$61)/$M$61) -> 0.0016567263 | V20: =ABS((N20-$M$61)/$M$61) -> 0.0068988173 | W20: =ABS((O20-$M$61)/$M$61) -> 0.0042819499 | X20: =ABS((P20-$M$61)/$M$61) -> 0.018506494 | Y20: =AVERAGE(T20:X20) -> 0.0071251874
A21: 2 | B21: 40 | C21: ='Lote 2'!C6 -> 1501 | D21: ='Lote 2'!D6 -> 1500 | E21: ='Lote 2'!E6 -> 1499 | F21: ='Lote 2'!F6 -> 1500 | G21: ='Lote 2'!G6 -> 1517 | H21: =ROUND(AVERAGE(C21:G21),0) -> 1503 | I21: =_xlfn.STDEV.S(C21:G21) -> 7.6354437 | K21: 40 | L21: =1/C21 -> 0.00066622252 | M21: =1/D21 -> 0.00066666667 | N21: =1/E21 -> 0.00066711141 | O21: =1/F21 -> 0.00066666667 | P21: =1/G21 -> 0.00065919578 | Q21: =AVERAGE(L21:P21) -> 0.00066517261 | S21: 40 | T21: =ABS((L21-$M$61)/$M$61) -> 0.0069953364 | U21: =ABS((M21-$M$61)/$M$61) -> 0.0076666667 | V21: =ABS((N21-$M$61)/$M$61) -> 0.0083388926 | W21: =ABS((O21-$M$61)/$M$61) -> 0.0076666667 | X21: =ABS((P21-$M$61)/$M$61) -> 0.0036255768 | Y21: =AVERAGE(T21:X21) -> 0.0068586278
A22: 3 | B22: 60 | C22: ='Lote 2'!C7 -> 1489 | D22: ='Lote 2'!D7 -> 1495 | E22: ='Lote 2'!E7 -> 1480 | F22: ='Lote 2'!F7 -> 1502 | G22: ='Lote 2'!G7 -> 1502 | H22: =ROUND(AVERAGE(C22:G22),0) -> 1494 | I22: =_xlfn.STDEV.S(C22:G22) -> 9.3434469 | K22: 60 | L22: =1/C22 -> 0.00067159167 | M22: =1/D22 -> 0.00066889632 | N22: =1/E22 -> 0.00067567568 | O22: =1/F22 -> 0.00066577896 | P22: =1/G22 -> 0.00066577896 | Q22: =AVERAGE(L22:P22) -> 0.00066954432 | S22: 60 | T22: =ABS((L22-$M$61)/$M$61) -> 0.015110813 | U22: =ABS((M22-$M$61)/$M$61) -> 0.011036789 | V22: =ABS((N22-$M$61)/$M$61) -> 0.021283784 | W22: =ABS((O22-$M$61)/$M$61) -> 0.0063249001 | X22: =ABS((P22-$M$61)/$M$61) -> 0.0063249001 | Y22: =AVERAGE(T22:X22) -> 0.012016237
A23: 5 | B23: 80 | C23: ='Lote 2'!C8 -> 1451 | D23: ='Lote 2'!D8 -> 1464 | E23: ='Lote 2'!E8 -> 1474 | F23: ='Lote 2'!F8 -> 1470 | G23: ='Lote 2'!G8 -> 1487 | H23: =ROUND(AVERAGE(C23:G23),0) -> 1469 | I23: =_xlfn.STDEV.S(C23:G23) -> 13.217413 | K23: 80 | L23: =1/C23 -> 0.00068917988 | M23: =1/D23 -> 0.00068306011 | N23: =1/E23 -> 0.00067842605 | O23: =1/F23 -> 0.00068027211 | P23: =1/G23 -> 0.00067249496 | Q23: =AVERAGE(L23:P23) -> 0.00068068662 | S23: 80 | T23: =ABS((L23-$M$61)/$M$61) -> 0.041695382 | U23: =ABS((M23-$M$61)/$M$61) -> 0.032445355 | V23: =ABS((N23-$M$61)/$M$61) -> 0.025440977 | W23: =ABS((O23-$M$61)/$M$61) -> 0.028231293 | X23: =ABS((P23-$M$61)/$M$61) -> 0.016476126 | Y23: =AVERAGE(T23:X23) -> 0.028857827
A24: 7 | B24: 100 | C24: ='Lote 2'!C9 -> 1438 | D24: ='Lote 2'!D9 -> 1432 | E24: ='Lote 2'!E9 -> 1462 | F24: ='Lote 2'!F9 -> 1437 | G24: ='Lote 2'!G9 -> 1424 | H24: =ROUND(AVERAGE(C24:G24),0) -> 1439 | I24: =_xlfn.STDEV.S(C24:G24) -> 14.205633 | K24: 100 | L24: =1/C24 -> 0.00069541029 | M24: =1/D24 -> 0.00069832402 | N24: =1/E24 -> 0.00068399453 | O24: =1/F24 -> 0.00069589422 | P24: =1/G24 -> 0.00070224719 | Q24: =AVERAGE(L24:P24) -> 0.00069517405 | S24: 100 | T24: =ABS((L24-$M$61)/$M$61) -> 0.051112656 | U24: =ABS((M24-$M$61)/$M$61) -> 0.05551676 | V24: =ABS((N24-$M$61)/$M$61) -> 0.033857729 | W24: =ABS((O24-$M$61)/$M$61) -> 0.05184412 | X24: =ABS((P24-$M$61)/$M$61) -> 0.061446629 | Y24: =AVERAGE(T24:X24) -> 0.050755579
A25: 9 | B25: 120 | C25: ='Lote 2'!C10 -> 1402 | D25: ='Lote 2'!D10 -> 1390 | E25: ='Lote 2'!E10 -> 1422 | F25: ='Lote 2'!F10 -> 1416 | G25: ='Lote 2'!G10 -> 1412 | H25: =ROUND(AVERAGE(C25:G25),0) -> 1408 | I25: =_xlfn.STDEV.S(C25:G25) -> 12.601587 | K25: 120 | L25: =1/C25 -> 0.00071326676 | M25: =1/D25 -> 0.00071942446 | N25: =1/E25 -> 0.00070323488 | O25: =1/F25 -> 0.00070621469 | P25: =1/G25 -> 0.0007082153 | Q25: =AVERAGE(L25:P25) -> 0.00071007122 | S25: 120 | T25: =ABS((L25-$M$61)/$M$61) -> 0.07810271 | U25: =ABS((M25-$M$61)/$M$61) -> 0.087410072 | V25: =ABS((N25-$M$61)/$M$61) -> 0.062939522 | W25: =ABS((O25-$M$61)/$M$61) -> 0.067443503 | X25: =ABS((P25-$M$61)/$M$61) -> 0.070467422 | Y25: =AVERAGE(T25:X25) -> 0.073272646
A26: 11 | B26: 140 | C26: ='Lote 2'!C11 -> 1383 | D26: ='Lote 2'!D11 -> 1397 | E26: ='Lote 2'!E11 -> 1380 | F26: ='Lote 2'!F11 -> 1386 | G26: ='Lote 2'!G11 -> 1384 | H26: =ROUND(AVERAGE(C26:G26),0) -> 1386 | I26: =_xlfn.STDEV.S(C26:G26) -> 6.5192024 | K26: 140 | L26: =1/C26 -> 0.0007230658 | M26: =1/D26 -> 0.00071581961 | N26: =1/E26 -> 0.00072463768 | O26: =1/F26 -> 0.00072150072 | P26: =1/G26 -> 0.00072254335 | Q26: =AVERAGE(L26:P26) -> 0.00072151343 | S26: 140 | T26: =ABS((L26-$M$61)/$M$61) -> 0.092913955 | U26: =ABS((M26-$M$61)/$M$61) -> 0.081961346 | V26: =ABS((N26-$M$61)/$M$61) -> 0.095289855 | W26: =ABS((O26-$M$61)/$M$61) -> 0.090548341 | X26: =ABS((P26-$M$61)/$M$61) -> 0.092124277 | Y26: =AVERAGE(T26:X26) -> 0.090567555
A27: 13 | B27: 160 | C27: ='Lote 2'!C12 -> 1374 | D27: ='Lote 2'!D12 -> 1360 | E27: ='Lote 2'!E12 -> 1357 | F27: ='Lote 2'!F12 -> 1374 | G27: ='Lote 2'!G12 -> 1356 | H27: =ROUND(AVERAGE(C27:G27),0) -> 1364 | I27: =_xlfn.STDEV.S(C27:G27) -> 9.0664216 | K27: 160 | L27: =1/C27 -> 0.00072780204 | M27: =1/D27 -> 0.00073529412 | N27: =1/E27 -> 0.00073691968 | O27: =1/F27 -> 0.00072780204 | P27: =1/G27 -> 0.00073746313 | Q27: =AVERAGE(L27:P27) -> 0.0007330562 | S27: 160 | T27: =ABS((L27-$M$61)/$M$61) -> 0.10007278 | U27: =ABS((M27-$M$61)/$M$61) -> 0.11139706 | V27: =ABS((N27-$M$61)/$M$61) -> 0.11385409 | W27: =ABS((O27-$M$61)/$M$61) -> 0.10007278 | X27: =ABS((P27-$M$61)/$M$61) -> 0.11467552 | Y27: =AVERAGE(T27:X27) -> 0.10801445
A28: 15 | B28: 180 | C28: ='Lote 2'!C13 -> 1349 | D28: ='Lote 2'!D13 -> 1341 | E28: ='Lote 2'!E13 -> 1356 | F28: ='Lote 2'!F13 -> 1363 | G28: ='Lote 2'!G13 -> 1348 | H28: =ROUND(AVERAGE(C28:G28),0) -> 1351 | I28: =_xlfn.STDEV.S(C28:G28) -> 8.3845095 | K28: 180 | L28: =1/C28 -> 0.00074128984 | M28: =1/D28 -> 0.00074571216 | N28: =1/E28 -> 0.00073746313 | O28: =1/F28 -> 0.00073367572 | P28: =1/G28 -> 0.00074183976 | Q28: =AVERAGE(L28:P28) -> 0.00073999612 | S28: 180 | T28: =ABS((L28-$M$61)/$M$61) -> 0.1204596 | U28: =ABS((M28-$M$61)/$M$61) -> 0.12714392 | V28: =ABS((N28-$M$61)/$M$61) -> 0.11467552 | W28: =ABS((O28-$M$61)/$M$61) -> 0.10895084 | X28: =ABS((P28-$M$61)/$M$61) -> 0.1212908 | Y28: =AVERAGE(T28:X28) -> 0.11850414
A29: Final | B29: 210 | C29: ='Lote 2'!C14 -> 1353 | D29: ='Lote 2'!D14 -> 1350 | E29: ='Lote 2'!E14 -> 1342 | F29: ='Lote 2'!F14 -> 1359 | G29: ='Lote 2'!G14 -> 1336 | H29: =ROUND(AVERAGE(C29:G29),0) -> 1348 | I29: =_xlfn.STDEV.S(C29:G29) -> 9.0829511 | K29: 210 | L29: =1/C29 -> 0.0007390983 | M29: =1/D29 -> 0.00074074074 | N29: =1/E29 -> 0.00074515648 | O29: =1/F29 -> 0.00073583517 | P29: =1/G29 -> 0.00074850299 | Q29: =AVERAGE(L29:P29) -> 0.00074186674 | S29: 210 | T29: =ABS((L29-$M$61)/$M$61) -> 0.11714708 | U29: =ABS((M29-$M$61)/$M$61) -> 0.11962963 | V29: =ABS((N29-$M$61)/$M$61) -> 0.12630402 | W29: =ABS((O29-$M$61)/$M$61) -> 0.11221486 | X29: =ABS((P29-$M$61)/$M$61) -> 0.13136228 | Y29: =AVERAGE(T29:X29) -> 0.12133157
A31: Lote 3
A32: Conteo de pellet/g | K32: Ganancia en peso [g] | S32: % de Ganancia
A33: Muestra | B33: Tiempo | C33: 1 | D33: 2 | E33: 3 | F33: 4 | G33: 5 | H33: m | I33: s | K33: Tiempo | L33: 1 | M33: 2 | N33: 3 | O33: 4 | P33: 5 | Q33: m | S33: Tiempo | T33: 1 | U33: 2 | V33: 3 | W33: 4 | X33: 5 | Y33: m
A34: Desnudo | B34: 0 | C34: ='Lote 3'!C4 -> 1532 | D34: ='Lote 3'!D4 -> 1514 | E34: ='Lote 3'!E4 -> 1525 | F34: ='Lote 3'!F4 -> 1522 | G34: ='Lote 3'!G4 -> 1539 | H34: =ROUND(AVERAGE(C34:G34),0) -> 1526 | I34: =_xlfn.STDEV.S(C34:G34) -> 9.5551033 | K34: 0 | L34: =1/C34 -> 0.00065274151 | M34: =1/D34 -> 0.00066050198 | N34: =1/E34 -> 0.0006557377 | O34: =1/F34 -> 0.00065703022 | P34: =1/G34 -> 0.00064977258 | Q34: =AVERAGE(L34:P34) -> 0.0006551568 | S34: 0 | T34: 0 | U34: 0 | V34: 0 | W34: 0 | X34: 0 | Y34: 0
A35: 1 | B35: 20 | C35: ='Lote 3'!C5 -> 1484 | D35: ='Lote 3'!D5 -> 1503 | E35: ='Lote 3'!E5 -> 1493 | F35: ='Lote 3'!F5 -> 1523 | G35: ='Lote 3'!G5 -> 1512 | H35: =ROUND(AVERAGE(C35:G35),0) -> 1503 | I35: =_xlfn.STDEV.S(C35:G35) -> 15.346009 | K35: 20 | L35: =1/C35 -> 0.00067385445 | M35: =1/D35 -> 0.00066533599 | N35: =1/E35 -> 0.00066979236 | O35: =1/F35 -> 0.00065659882 | P35: =1/G35 -> 0.00066137566 | Q35: =AVERAGE(L35:P35) -> 0.00066539146 | S35: 20 | T35: =(L35-$M$61)/$M$61 -> 0.018530997 | U35: =(M35-$M$61)/$M$61 -> 0.005655356 | V35: =(N35-$M$61)/$M$61 -> 0.012391159 | W35: =(O35-$M$61)/$M$61 -> -0.0075508864 | X35: =(P35-$M$61)/$M$61 -> -0.00033068783 | Y35: =AVERAGE(T35:X35) -> 0.0057391876
A36: 2 | B36: 40 | C36: ='Lote 3'!C6 -> 1478 | D36: ='Lote 3'!D6 -> 1470 | E36: ='Lote 3'!E6 -> 1491 | F36: ='Lote 3'!F6 -> 1473 | G36: ='Lote 3'!G6 -> 1495 | H36: =ROUND(AVERAGE(C36:G36),0) -> 1481 | I36: =_xlfn.STDEV.S(C36:G36) -> 11.058933 | K36: 40 | L36: =1/C36 -> 0.00067658999 | M36: =1/D36 -> 0.00068027211 | N36: =1/E36 -> 0.00067069081 | O36: =1/F36 -> 0.00067888663 | P36: =1/G36 -> 0.00066889632 | Q36: =AVERAGE(L36:P36) -> 0.00067506717 | S36: 40 | T36: =(L36-$M$61)/$M$61 -> 0.022665765 | U36: =(M36-$M$61)/$M$61 -> 0.028231293 | V36: =(N36-$M$61)/$M$61 -> 0.013749162 | W36: =(O36-$M$61)/$M$61 -> 0.026137135 | X36: =(P36-$M$61)/$M$61 -> 0.011036789 | Y36: =AVERAGE(T36:X36) -> 0.020364029
A37: 3 | B37: 60 | C37: ='Lote 3'!C7 -> 1468 | D37: ='Lote 3'!D7 -> 1470 | E37: ='Lote 3'!E7 -> 1458 | F37: ='Lote 3'!F7 -> 1450 | G37: ='Lote 3'!G7 -> 1444 | H37: =ROUND(AVERAGE(C37:G37),0) -> 1458 | I37: =_xlfn.STDEV.S(C37:G37) -> 11.224972 | K37: 60 | L37: =1/C37 -> 0.00068119891 | M37: =1/D37 -> 0.00068027211 | N37: =1/E37 -> 0.00068587106 | O37: =1/F37 -> 0.00068965517 | P37: =1/G37 -> 0.00069252078 | Q37: =AVERAGE(L37:P37) -> 0.0006859036 | S37: 60 | T37: =(L37-$M$61)/$M$61 -> 0.029632153 | U37: =(M37-$M$61)/$M$61 -> 0.028231293 | V37: =(N37-$M$61)/$M$61 -> 0.036694102 | W37: =(O37-$M$61)/$M$61 -> 0.042413793 | X37: =(P37-$M$61)/$M$61 -> 0.046745152 | Y37: =AVERAGE(T37:X37) -> 0.036743298
A38: 4 | B38: 80 | C38: ='Lote 3'!C8 -> 1429 | D38: ='Lote 3'!D8 -> 1448 | E38: ='Lote 3'!E8 -> 1449 | F38: ='Lote 3'!F8 -> 1454 | G38: ='Lote 3'!G8 -> 1445 | H38: =ROUND(AVERAGE(C38:G38),0) -> 1445 | I38: =_xlfn.STDEV.S(C38:G38) -> 9.5131488 | K38: 80 | L38: =1/C38 -> 0.00069979006 | M38: =1/D38 -> 0.00069060773 | N38: =1/E38 -> 0.00069013112 | O38: =1/F38 -> 0.00068775791 | P38: =1/G38 -> 0.00069204152 | Q38: =AVERAGE(L38:P38) -> 0.00069206567 | S38: 80 | T38: =(L38-$M$61)/$M$61 -> 0.05773268 | U38: =(M38-$M$61)/$M$61 -> 0.043853591 | V38: =(N38-$M$61)/$M$61 -> 0.043133195 | W38: =(O38-$M$61)/$M$61 -> 0.03954608 | X38: =(P38-$M$61)/$M$61 -> 0.046020761 | Y38: =AVERAGE(T38:X38) -> 0.046057262
A39: 5 | B39: 100 | C39: ='Lote 3'!C9 -> 1397 | D39: ='Lote 3'!D9 -> 1415 | E39: ='Lote 3'!E9 -> 1404 | F39: ='Lote 3'!F9 -> 1390 | G39: ='Lote 3'!G9 -> 1385 | H39: =ROUND(AVERAGE(C39:G39),0) -> 1398 | I39: =_xlfn.STDEV.S(C39:G39) -> 11.819475 | K39: 100 | L39: =1/C39 -> 0.00071581961 | M39: =1/D39 -> 0.00070671378 | N39: =1/E39 -> 0.00071225071 | O39: =1/F39 -> 0.00071942446 | P39: =1/G39 -> 0.00072202166 | Q39: =AVERAGE(L39:P39) -> 0.00071524605 | S39: 100 | T39: =(L39-$M$61)/$M$61 -> 0.081961346 | U39: =(M39-$M$61)/$M$61 -> 0.06819788 | V39: =(N39-$M$61)/$M$61 -> 0.076566952 | W39: =(O39-$M$61)/$M$61 -> 0.087410072 | X39: =(P39-$M$61)/$M$61 -> 0.09133574 | Y39: =AVERAGE(T39:X39) -> 0.081094398
A40: 6 | B40: 120 | C40: ='Lote 3'!C10 -> 1388 | D40: ='Lote 3'!D10 -> 1396 | E40: ='Lote 3'!E10 -> 1376 | F40: ='Lote 3'!F10 -> 1366 | G40: ='Lote 3'!G10 -> 1392 | H40: =ROUND(AVERAGE(C40:G40),0) -> 1384 | I40: =_xlfn.STDEV.S(C40:G40) -> 12.36123 | K40: 120 | L40: =1/C40 -> 0.0007204611 | M40: =1/D40 -> 0.00071633238 | N40: =1/E40 -> 0.00072674419 | O40: =1/F40 -> 0.00073206442 | P40: =1/G40 -> 0.0007183908 | Q40: =AVERAGE(L40:P40) -> 0.00072279858 | S40: 120 | T40: =(L40-$M$61)/$M$61 -> 0.088976945 | U40: =(M40-$M$61)/$M$61 -> 0.08273639 | V40: =(N40-$M$61)/$M$61 -> 0.098473837 | W40: =(O40-$M$61)/$M$61 -> 0.10651537 | X40: =(P40-$M$61)/$M$61 -> 0.085847701 | Y40: =AVERAGE(T40:X40) -> 0.092510049
A41: 7 | B41: 140 | C41: ='Lote 3'!C11 -> 1375 | D41: ='Lote 3'!D11 -> 1383 | E41: ='Lote 3'!E11 -> 1363 | F41: ='Lote 3'!F11 -> 1359 | G41: ='Lote 3'!G11 -> 1350 | H41: =ROUND(AVERAGE(C41:G41),0) -> 1366 | I41: =_xlfn.STDEV.S(C41:G41) -> 13.076697 | K41: 140 | L41: =1/C41 -> 0.00072727273 | M41: =1/D41 -> 0.0007230658 | N41: =1/E41 -> 0.00073367572 | O41: =1/F41 -> 0.00073583517 | P41: =1/G41 -> 0.00074074074 | Q41: =AVERAGE(L41:P41) -> 0.00073211803 | S41: 140 | T41: =(L41-$M$61)/$M$61 -> 0.099272727 | U41: =(M41-$M$61)/$M$61 -> 0.092913955 | V41: =(N41-$M$61)/$M$61 -> 0.10895084 | W41: =(O41-$M$61)/$M$61 -> 0.11221486 | X41: =(P41-$M$61)/$M$61 -> 0.11962963 | Y41: =AVERAGE(T41:X41) -> 0.1065964
A42: 8 | B42: 160 | C42: ='Lote 3'!C12 -> 1346 | D42: ='Lote 3'!D12 -> 1332 | E42: ='Lote 3'!E12 -> 1350 | F42: ='Lote 3'!F12 -> 1351 | G42: ='Lote 3'!G12 -> 1356 | H42: =ROUND(AVERAGE(C42:G42),0) -> 1347 | I42: =_xlfn.STDEV.S(C42:G42) -> 9.1104336 | K42: 160 | L42: =1/C42 -> 0.00074294205 | M42: =1/D42 -> 0.00075075075 | N42: =1/E42 -> 0.00074074074 | O42: =1/F42 -> 0.00074019245 | P42: =1/G42 -> 0.00073746313 | Q42: =AVERAGE(L42:P42) -> 0.00074241782 | S42: 160 | T42: =(L42-$M$61)/$M$61 -> 0.12295691 | U42: =(M42-$M$61)/$M$61 -> 0.13475976 | V42: =(N42-$M$61)/$M$61 -> 0.11962963 | W42: =(O42-$M$61)/$M$61 -> 0.11880089 | X42: =(P42-$M$61)/$M$61 -> 0.11467552 | Y42: =AVERAGE(T42:X42) -> 0.12216454
...

Sheet Resumen
A1: Muestra | B1: Tiempo [min] | C1: Lote 1 | H1: Lote 2 | M1: Lote 3 | R1: Lote 4
C2: Pellets/g | D2: %Ganancia | E2: Diametro [mm] | F2: e [mm] | G2: r [g/ml] | H2: Pellets/g | I2: %Ganancia | J2: Diametro [mm] | K2: e [mm] | L2: r [g/ml] | M2: Pellets/g | N2: %Ganancia | O2: Diametro [mm] | P2: e [mm] | Q2: r [g/ml] | R2: Pellets/g | S2: %Ganancia | T2: Diametro [mm] | U2: e [mm] | V2: r [g/ml]
A3: 0 | B3: 0 | C3: ='Lote 1'!H4 -> 1502 | D3: 0 | E3: ='Lote 1'!M4 -> 0.932 | F3: ='Lote 1'!R4 -> 0 | G3: ='Lote 1'!Z4 -> 0.90248333 | H3: ='Lote 2'!H4 -> 1515 | I3: 0 | J3: ='Lote 2'!M4 -> 0.88 | K3: ='Lote 2'!R4 -> 0 | L3: ='Lote 2'!Z4 -> 0.90328333 | M3: ='Lote 3'!H4 -> 1526 | N3: 0 | O3: ='Lote 3'!M4 -> 0.979 | P3: ='Lote 3'!R4 -> 0 | Q3: ='Lote 3'!Z4 -> 0.89911667 | R3: ='Lote 4'!H4 -> 1502 | S3: 0 | T3: ='Lote 4'!M4 -> 0.9984 | U3: ='Lote 4'!R4 -> 0 | V3: ='Lote 4'!AD4 -> 0.89765
A4: 1 | B4: 20 | C4: ='Lote 1'!H5 -> 1510 | D4: ='%Ganancia'!Y5 -> 0.00077990411 | E4: ='Lote 1'!M5 -> 0.92 | F4: ='Lote 1'!R5 -> 0 | G4: ='Lote 1'!Z5 -> 0.90993333 | H4: ='Lote 2'!H5 -> 1521 | I4: ='%Ganancia'!Y20 -> 0.0071251874 | J4: ='Lote 2'!M5 -> 0.99 | K4: ='Lote 2'!R5 -> 0.008 | L4: ='Lote 2'!Z5 -> 0.91190207 | M4: ='Lote 3'!H5 -> 1503 | N4: ='%Ganancia'!Y35 -> 0.0057391876 | O4: ='Lote 3'!M5 -> 0.936 | P4: ='Lote 3'!R5 -> 0.012 | Q4: ='Lote 3'!Z5 -> 0.91367701 | R4: ='Lote 4'!H5 -> 1497 | S4: ='%Ganancia'!Y50 -> 0.0095658496 | T4: ='Lote 4'!M5 -> 0.9349 | U4: ='Lote 4'!R5 -> 0.0143 | V4: ='Lote 4'!AD5 -> 0.91469295
A5: 2 | B5: 40 | C5: ='Lote 1'!H6 -> 1498 | D5: ='%Ganancia'!Y6 -> 0.0086516573 | E5: ='Lote 1'!M6 -> 0.95 | F5: ='Lote 1'!R6 -> 0 | G5: ='Lote 1'!Z6 -> 0.92180295 | H5: ='Lote 2'!H6 -> 1503 | I5: ='%Ganancia'!Y21 -> 0.0068586278 | J5: ='Lote 2'!M6 -> 0.886 | K5: ='Lote 2'!R6 -> 0.013 | L5: ='Lote 2'!Z6 -> 0.91801605 | M5: ='Lote 3'!H6 -> 1481 | N5: ='%Ganancia'!Y36 -> 0.020364029 | O5: ='Lote 3'!M6 -> 0.936 | P5: ='Lote 3'!R6 -> 0.014 | Q5: ='Lote 3'!Z6 -> 0.92009804 | R5: ='Lote 4'!H6 -> 1489 | S5: ='%Ganancia'!Y51 -> 0.014990236 | T5: ='Lote 4'!M6 -> 1.0032 | U5: ='Lote 4'!R6 -> 0.0159 | V5: ='Lote 4'!AD6 -> 0.92257919
A6: 3 | B6: 60 | C6: ='Lote 1'!H7 -> 1477 | D6: ='%Ganancia'!Y7 -> 0.023009634 | E6: ='Lote 1'!M7 -> 0.91 | F6: ='Lote 1'!R7 -> 0 | G6: ='Lote 1'!Z7 -> 0.92884077 | H6: ='Lote 2'!H7 -> 1493 | I6: ='%Ganancia'!Y22 -> 0.012016237 | J6: ='Lote 2'!M7 -> 0.893 | K6: ='Lote 2'!R7 -> 0.016 | L6: ='Lote 2'!Z7 -> 0.92113769 | M6: ='Lote 3'!H7 -> 1458 | N6: ='%Ganancia'!Y37 -> 0.036743298 | O6: ='Lote 3'!M7 -> 0.832 | P6: ='Lote 3'!R7 -> 0.018 | Q6: ='Lote 3'!Z7 -> 0.92278873 | R6: ='Lote 4'!H7 -> 1462 | S6: ='%Ganancia'!Y52 -> 0.033749885 | T6: ='Lote 4'!M7 -> 0.9651 | U6: ='Lote 4'!R7 -> 0.019 | V6: ='Lote 4'!AD7 -> 0.92540401
A7: 4 | B7: 80 | C7: ='Lote 1'!H8 -> 1457 | D7: ='%Ganancia'!Y8 -> 0.037508009 | E7: ='Lote 1'!M8 -> 0.95 | F7: ='Lote 1'!R8 -> 0 | G7: ='Lote 1'!Z8 -> 0.93654385 | H7: ='Lote 2'!H8 -> 1469 | I7: ='%Ganancia'!Y23 -> 0.028857827 | J7: ='Lote 2'!M8 -> 0.919 | K7: ='Lote 2'!R8 -> 0.032 | L7: ='Lote 2'!Z8 -> 0.92810817 | M7: ='Lote 3'!H8 -> 1445 | N7: ='%Ganancia'!Y38 -> 0.046057262 | O7: ='Lote 3'!M8 -> 0.904 | P7: ='Lote 3'!R8 -> 0.019 | Q7: ='Lote 3'!Z8 -> 0.92755872 | R7: ='Lote 4'!H8 -> 1451 | S7: ='%Ganancia'!Y53 -> 0.041349164 | T7: ='Lote 4'!M8 -> 0.946 | U7: ='Lote 4'!R8 -> 0.0222 | V7: ='Lote 4'!AD8 -> 0.93347931
A8: 5 | B8: 100 | C8: ='Lote 1'!H9 -> 1443 | D8: ='%Ganancia'!Y9 -> 0.047515205 | E8: ='Lote 1'!M9 -> 0.93 | F8: ='Lote 1'!R9 -> 0.01 | G8: ='Lote 1'!Z9 -> 0.9403927 | H8: ='Lote 2'!H9 -> 1438 | I8: ='%Ganancia'!Y24 -> 0.050755579 | J8: ='Lote 2'!M9 -> 0.924 | K8: ='Lote 2'!R9 -> 0.037 | L8: ='Lote 2'!Z9 -> 0.93067766 | M8: ='Lote 3'!H9 -> 1398 | N8: ='%Ganancia'!Y39 -> 0.081094398 | O8: ='Lote 3'!M9 -> 0.91 | P8: ='Lote 3'!R9 -> 0.02 | Q8: ='Lote 3'!Z9 -> 0.92939291 | R8: ='Lote 4'!H9 -> 1421 | S8: ='%Ganancia'!Y54 -> 0.063592106 | T8: ='Lote 4'!M9 -> 0.9194 | U8: ='Lote 4'!R9 -> 0.0302 | V8: ='Lote 4'!AD9 -> 0.93832256
A9: 6 | B9: 120 | C9: ='Lote 1'!H10 -> 1404 | D9: ='%Ganancia'!Y10 -> 0.07661527 | E9: ='Lote 1'!M10 -> 0.98 | F9: ='Lote 1'!R10 -> 0.01 | G9: ='Lote 1'!Z10 -> 0.94467787 | H9: ='Lote 2'!H10 -> 1408 | I9: ='%Ganancia'!Y25 -> 0.073272646 | J9: ='Lote 2'!M10 -> 0.959 | K9: ='Lote 2'!R10 -> 0.038 | L9: ='Lote 2'!Z10 -> 0.93698018 | M9: ='Lote 3'!H10 -> 1383 | N9: ='%Ganancia'!Y40 -> 0.092510049 | O9: ='Lote 3'!M10 -> 0.922 | P9: ='Lote 3'!R10 -> 0.023 | Q9: ='Lote 3'!Z10 -> 0.93422215 | R9: ='Lote 4'!H10 -> 1395 | S9: ='%Ganancia'!Y55 -> 0.083521437 | T9: ='Lote 4'!M10 -> 0.91 | U9: ='Lote 4'!R10 -> 0.0349 | V9: ='Lote 4'!AD10 -> 0.94375242
A10: 7 | B10: 140 | C10: ='Lote 1'!H11 -> 1390 | D10: ='%Ganancia'!Y11 -> 0.087140315 | E10: ='Lote 1'!M11 -> 0.95 | F10: ='Lote 1'!R11 -> 0.02 | G10: ='Lote 1'!Z11 -> 0.94786145 | H10: ='Lote 2'!H11 -> 1386 | I10: ='%Ganancia'!Y26 -> 0.090567555 | J10: ='Lote 2'!M11 -> 0.924 | K10: ='Lote 2'!R11 -> 0.043 | L10: ='Lote 2'!Z11 -> 0.94297565 | M10: ='Lote 3'!H11 -> 1366 | N10: ='%Ganancia'!Y41 -> 0.1065964 | O10: ='Lote 3'!M11 -> 0.905 | P10: ='Lote 3'!R11 -> 0.024 | Q10: ='Lote 3'!Z11 -> 0.93862045 | R10: ='Lote 4'!H11 -> 1382 | S10: ='%Ganancia'!Y56 -> 0.093295932 | T10: ='Lote 4'!M11 -> 0.8811 | U10: ='Lote 4'!R11 -> 0.0365 | V10: ='Lote 4'!AD11 -> 0.94624919
A11: 8 | B11: 160 | C11: ='Lote 1'!H12 -> 1378 | D11: ='%Ganancia'!Y12 -> 0.096245282 | E11: ='Lote 1'!M12 -> 0.97 | F11: ='Lote 1'!R12 -> 0.02 | G11: ='Lote 1'!Z12 -> 0.95281189 | H11: ='Lote 2'!H12 -> 1364 | I11: ='%Ganancia'!Y27 -> 0.10801445 | J11: ='Lote 2'!M12 -> 0.978 | K11: ='Lote 2'!R12 -> 0.0444 | L11: ='Lote 2'!Z12 -> 0.94872603 | M11: ='Lote 3'!H12 -> 1347 | N11: ='%Ganancia'!Y42 -> 0.12216454 | O11: ='Lote 3'!M12 -> 0.97 | P11: ='Lote 3'!R12 -> 0.027 | Q11: ='Lote 3'!Z12 -> 0.94290562 | R11: ='Lote 4'!H12 -> 1356 | S11: ='%Ganancia'!Y57 -> 0.11463575 | T11: ='Lote 4'!M12 -> 0.954 | U11: ='Lote 4'!R12 -> 0.0413 | V11: ='Lote 4'!AD12 -> 0.95252586
A12: 9 | B12: 180 | C12: ='Lote 1'!H13 -> 1375 | D12: ='%Ganancia'!Y13 -> 0.09867831 | E12: ='Lote 1'!M13 -> 0.95 | F12: ='Lote 1'!R13 -> 0.02 | G12: ='Lote 1'!Z13 -> 0.95721558 | H12: ='Lote 2'!H13 -> 1351 | I12: ='%Ganancia'!Y28 -> 0.11850414 | J12: ='Lote 2'!M13 -> 0.9106 | K12: ='Lote 2'!R13 -> 0.046 | L12: ='Lote 2'!Z13 -> 0.95165913 | M12: ='Lote 3'!H13 -> 1324 | N12: ='%Ganancia'!Y43 -> 0.14139642 | O12: ='Lote 3'!M13 -> 0.925 | P12: ='Lote 3'!R13 -> 0.025 | Q12: ='Lote 3'!Z13 -> 0.947312 | R12: ='Lote 4'!H13 -> 1334 | S12: ='%Ganancia'!Y58 -> 0.13291338 | T12: ='Lote 4'!M13 -> 0.9366 | U12: ='Lote 4'!R13 -> 0.0448 | V12: ='Lote 4'!AD13 -> 0.95890918
A13: Final | B13: 200 | C13: ='Lote 1'!H14 -> 1345 | D13: ='%Ganancia'!Y14 -> 0.12364486 | E13: ='Lote 1'!M14 -> 0.95 | F13: ='Lote 1'!R14 -> 0.02 | G13: ='Lote 1'!Z14 -> 0.96088666 | H13: ='Lote 2'!H14 -> 1348 | I13: ='%Ganancia'!Y29 -> 0.12133157 | J13: ='Lote 2'!M14 -> 1.0148 | K13: ='Lote 2'!R14 -> 0.0556 | L13: ='Lote 2'!Z14 -> 0.95838181 | M13: ='Lote 3'!H14 -> 1330 | N13: ='%Ganancia'!Y44 -> 0.13633195 | O13: ='Lote 3'!M14 -> 0.966 | P13: ='Lote 3'!R14 -> 0.031 | Q13: ='Lote 3'!Z14 -> 0.95997091 | R13: ='Lote 4'!H14 -> 1331 | S13: ='%Ganancia'!Y59 -> 0.13568973 | T13: ='Lote 4'!M14 -> 0.9204 | U13: ='Lote 4'!R14 -> 0.0508 | V13: ='Lote 4'!AD14 -> 0.96191823
K15: r_s [g/mm3] | M15: 0.000499
M17: 1 | N17: 2 | O17: 3 | P17: 4
K18: Do [mm] | M18: =E3 -> 0.932 | N18: =J3 -> 0.88 | O18: =O3 -> 0.979 | P18: =T3 -> 0.9984
K19: e [mm] | M19: =F13 -> 0.02 | N19: =K13 -> 0.0556 | O19: =P13 -> 0.031 | P19: =U13 -> 0.0508
K21: mc_teo [g] | M21: =((PI()/6)*((3*(M18^2)*M19)+(3*M18*(M19^2))+(M19^3)))*$M$15 -> 1.3911326e-05 | N21: =((PI()/6)*((3*(N18^2)*N19)+(3*N18*(N19^2))+(N19^3)))*$M$15 -> 3.5926202e-05 | O21: =((PI()/6)*((3*(O18^2)*O19)+(3*O18*(O19^2))+(O19^3)))*$M$15 -> 2.4034044e-05 | P21: =((PI()/6)*((3*(P18^2)*P19)+(3*P18*(P19^2))+(P19^3)))*$M$15 -> 4.1744905e-05
K22: mc_exp [g] | M22: ='%Ganancia'!Q14-'%Ganancia'!M61 -> 8.1802754e-05 | N22: ='%Ganancia'!Q29-'%Ganancia'!M61 -> 8.0272296e-05 | O22: ='%Ganancia'!Q44-'%Ganancia'!M61 -> 9.0196458e-05 | P22: ='%Ganancia'!Q59-'%Ganancia'!M61 -> 8.9771571e-05
K23: %ERROR | M23: =ABS(M21-M22)/M22 -> 0.82994061 | N23: =ABS(N21-N22)/N22 -> 0.55244581 | O23: =ABS(O21-O22)/O22 -> 0.73353672 | P23: =ABS(P21-P22)/P22 -> 0.53498747

Sheet Parámetros proceso
B1: Lote 1 | F1: Lote 2 | J1: Lote 3 | N1: Lote 4
A2: Tiempo [min] | B2: P atomiz [bar ] | C2: P. aire comp bar | D2: T. producto [°C ] | E2: Velocidad Aire [m/s ] | F2: P atomiz [bar ] | G2: P. aire comp bar | H2: T. producto [°C ] | I2: Velocidad Aire [m/s ] | J2: P atomiz [bar ] | K2: P. aire comp bar | L2: T. producto [°C ] | M2: Velocidad Aire [m/s ] | N2: P atomiz [bar ] | O2: P. aire comp bar | P2: T. producto [°C ] | Q2: Velocidad Aire [m/s ]
A3: 1 | B3: 3.5 | C3: 5.7 | D3: 16.9 | E3: 3.78 | F3: 3.5 | G3: 5.7 | H3: 48.9 | I3: 2.92 | J3: 3.6 | K3: 6.3 | L3: 18 | M3: 0.26 | N3: 3.5 | O3: 5.9 | P3: 50.7 | Q3: 3.04
A4: 2 | B4: 3.5 | C4: 6.3 | D4: 17 | E4: 3.26 | F4: 3.5 | G4: 6.2 | H4: 49.1 | I4: 2.89 | J4: 3.5 | K4: 6.2 | L4: 18 | M4: 2.45 | N4: 3.5 | O4: 6 | P4: 51.3 | Q4: 5.27
A5: 3 | B5: 3.5 | C5: 6.2 | D5: 26.1 | E5: 2.24 | F5: 3.5 | G5: 6.2 | H5: 49.1 | I5: 2.93 | J5: 3.5 | K5: 6.2 | L5: 18 | M5: 2.39 | N5: 3.5 | O5: 6.2 | P5: 48.3 | Q5: 2.38
A6: 4 | B6: 3.5 | C6: 5.9 | D6: 32.6 | E6: 3.5 | F6: 3.5 | G6: 6 | H6: 49.3 | I6: 3 | J6: 3.5 | K6: 6 | L6: 18 | M6: 3.51 | N6: 3.5 | O6: 6.3 | P6: 42.3 | Q6: 2.5
A7: 5 | B7: 3.5 | C7: 5.9 | D7: 34.7 | E7: 4.01 | F7: 3.5 | G7: 5.7 | H7: 49.5 | I7: 2.98 | J7: 3.5 | K7: 5.9 | L7: 18 | M7: 3.83 | N7: 3.5 | O7: 6.3 | P7: 48.4 | Q7: 2.84
A8: 6 | B8: 3.5 | C8: 6.2 | D8: 35.4 | E8: 3.88 | F8: 3.4 | G8: 6.2 | H8: 49.5 | I8: 2.99 | J8: 3.5 | K8: 6.3 | L8: 18 | M8: 4.26 | N8: 3.5 | O8: 6.2 | P8: 53.3 | Q8: 3.57
A9: 7 | B9: 3.5 | C9: 6 | D9: 35.9 | E9: 3.63 | F9: 3.4 | G9: 6.2 | H9: 49.5 | I9: 3.07 | J9: 3.5 | K9: 6.3 | L9: 18 | M9: 4.42 | N9: 3.5 | O9: 6.1 | P9: 47 | Q9: 2.36
A10: 8 | B10: 3.5 | C10: 5.6 | D10: 36.6 | E10: 3.6 | F10: 3.5 | G10: 6 | H10: 49.7 | I10: 2.97 | J10: 3.5 | K10: 6 | L10: 19.8 | M10: 0.23 | N10: 3.5 | O10: 5.8 | P10: 50.9 | Q10: 4
A11: 9 | B11: 3.5 | C11: 6.2 | D11: 37.6 | E11: 3.63 | F11: 3.4 | G11: 6.3 | H11: 50 | I11: 2.81 | J11: 3.5 | K11: 5.8 | L11: 36.1 | M11: 3 | N11: 3.5 | O11: 6.2 | P11: 48.9 | Q11: 2.15
A12: 10 | B12: 3.5 | C12: 6.1 | D12: 38.8 | E12: 3.69 | F12: 3.4 | G12: 6.2 | H12: 50.2 | I12: 2.81 | J12: 3.5 | K12: 6.3 | L12: 45.1 | M12: 3.57 | N12: 3.5 | O12: 6.2 | P12: 47.6 | Q12: 1.73
A13: 11 | B13: 3.5 | C13: 5.7 | D13: 40.5 | E13: 4.06 | F13: 3.4 | G13: 6.1 | H13: 50.6 | I13: 2.84 | J13: 3.5 | K13: 6.2 | L13: 46.9 | M13: 3.61 | N13: 3.5 | O13: 6.1 | P13: 50.3 | Q13: 3.06
A14: 12 | B14: 3.5 | C14: 6.3 | D14: 42.3 | E14: 4.2 | F14: 3.5 | G14: 5.9 | H14: 51 | I14: 2.84 | J14: 3.5 | K14: 6 | L14: 46.7 | M14: 3.26 | N14: 3.5 | O14: 5.8 | P14: 51.9 | Q14: 2.16
... A233: 231 | B233: 3.4 | C233: 6.2 | D233: 52 | E233: 2.73 | F233: 3.4 | G233: 5.9 | H233: 54.4 | I233: 2.58 | J233: 3.4 | K233: 6 | L233: 51.1 | M233: 2.38 | N233: 3.4 | O233: 5.7 | P233: 51.5 | Q233: 2.75
A234: 232 | B234: 3.4 | C234: 6.1 | D234: 51.9 | E234: 2.72 | F234: 3.4 | G234: 6.2 | H234: 54.5 | I234: 2.9 | N234: 3.4 | O234: 6.3 | P234: 51.2 | Q234: 2.66
A235: 233 | B235: 3.4 | C235: 5.8 | D235: 51.8 | E235: 2.78 | F235: 3.4 | G235: 6.2 | H235: 54.6 | I235: 2.75 | N235: 3.4 | O235: 6.2 | P235: 50.8 | Q235: 2.7
A236: 234 | B236: 3.4 | C236: 6.3 | D236: 51.1 | E236: 2.78 | F236: 3.4 | G236: 6 | H236: 55.1 | I236: 2.83 | N236: 3.4 | O236: 6 | P236: 50.2 | Q236: 2.69
A237: 235 | B237: 3.4 | C237: 6.2 | D237: 51.3 | E237: 2.79 | F237: 3.4 | G237: 5.7 | H237: 54.9 | I237: 2.89 | N237: 3.4 | O237: 5.8 | P237: 49.5 | Q237: 2.61
A238: 236 | B238: 3.4 | C238: 4.4 | D238: 51.7 | E238: 2.81 | F238: 3.4 | G238: 6.2 | H238: 55.4 | I238: 2.9 | N238: 3.4 | O238: 6.3 | P238: 48.8 | Q238: 2.56
A239: 237 | B239: 3.4 | C239: 6.3 | D239: 51.9 | E239: 2.83 | F239: 3.4 | G239: 6.2 | H239: 54.9 | I239: 2.92 | N239: 3.4 | O239: 6.2 | P239: 48.1 | Q239: 2.58
A240: 238 | B240: 3.4 | C240: 6.2 | D240: 52.2 | E240: 2.86 | F240: 3.4 | G240: 6 | H240: 54.1 | I240: 2.93 | N240: 3.4 | O240: 6.1 | P240: 47.5 | Q240: 2.52
A241: 239 | B241: 3.4 | C241: 6.1 | D241: 52.4 | E241: 2.89 | F241: 3.4 | G241: 5.7 | H241: 53.6 | I241: 2.95 | N241: 3.4 | O241: 5.8 | P241: 47.1 | Q241: 2.47
A242: 240 | B242: 3.4 | C242: 5.9 | D242: 52.5 | E242: 2.86 | F242: 3.4 | G242: 6.3 | H242: 53.2 | I242: 2.92 | N242: 3.4 | O242: 6.3 | P242: 46.8 | Q242: 2.47
A243: 241 | B243: 3.4 | C243: 6.2 | D243: 52.6 | E243: 2.93 | F243: 3.4 | G243: 6.2 | H243: 53 | I243: 2.89 | N243: 3.4 | O243: 6.2 | P243: 46.7 | Q243: 2.5
